Workbook

Sheet README
B1: MH Robotics — Seed + TIPS IR Financial Model (Draft v5, 2026-10)
B3: 목적: Seed · TIPS IR 덱의 모든 사업 수치를 하나의 수식 모델로 관리. 단위는 별도 표기가 없으면 만원 (KRW 10,000). 억원 = 만원 / 10,000.
B4: 주의: 실적 · 계약 · 고객 · Partner 데이터 없음. 모든 수치는 FACT / DERIVED / ASSUMPTION / TARGET Tag로 구분.
B6: Color code
B7: 파란 글자 = 입력값 (Inputs, Inputs_Yearly, Budget_24M 팀 · 지출 표에서만 수정) · 검은 글자 = 수식 · 녹색 글자 = 다른 Sheet 참조 · 노란 바탕 = 핵심 가정 (WTP · BOM · Volume)
B8: Tag
B9: FACT = 공식 통계 · 공개자료 확인값 · DERIVED = FACT 또는 가정으로 계산한 값 · ASSUMPTION = 현재 사업가설 · TARGET = 24개월 · 이후 목표
B10: Sheets
B11: Inputs: 단일값 가정 (시나리오별 Conservative / Base / Upside 열)
B12: Inputs_Yearly: 연도별 가정 (Volume, BOM, Interface 표준부품 사용률, 인원 · 지출 등). Y1~Y2 지출 = Budget_24M 팀 · 지출 계획과 같은 값
B13: FM_Conservative / FM_Base / FM_Upside: 5개년 Bottom-up 손익 (INSTALL · OPERATE · EXPAND 매출층, 채널 3종)
B14: Scenario_Summary: 3개 시나리오 요약 (억원)
... B23: 재현: python3 MH/source/model.py → python3 MH/source/xlsx_model.py (LibreOffice 재계산 후 check_xlsx.py로 model.py와 교차검증)

Sheet Scenario_Summary
A1: Scenario Summary (억원 · 세대 · 대)
A2: 각 셀은 FM Sheet 참조. 억원 = 만원 / 10,000. Upside는 가격 인상 없이 Partner·표준화·설치원가·Installed Base로 차이.
A4: Conservative | B4: 단위 | C4: Y1 | D4: Y2 | E4: Y3 | F4: Y4 | G4: Y5
A5: 매출 | B5: 억원 | C5: =FM_Conservative!$C$42/10000 -> 0 | D5: =FM_Conservative!$D$42/10000 -> 0.14508 | E5: =FM_Conservative!$E$42/10000 -> 3.609345 | F5: =FM_Conservative!$F$42/10000 -> 15.328645 | G5: =FM_Conservative!$G$42/10000 -> 33.985163
A6: 매출총이익 | B6: 억원 | C6: =FM_Conservative!$C$60/10000 -> 0 | D6: =FM_Conservative!$D$60/10000 -> -0.34295685 | E6: =FM_Conservative!$E$60/10000 -> 0.1148028 | F6: =FM_Conservative!$F$60/10000 -> 0.94692397 | G6: =FM_Conservative!$G$60/10000 -> 4.4150543
A7: 매출총이익률 | B7: % | C7: =FM_Conservative!$C$61 -> 0 | D7: =FM_Conservative!$D$61 -> -2.3639154 | E7: =FM_Conservative!$E$61 -> 0.031807101 | F7: =FM_Conservative!$F$61 -> 0.061774798 | G7: =FM_Conservative!$G$61 -> 0.12991123
A8: Contribution | B8: 억원 | C8: =FM_Conservative!$C$66/10000 -> 0 | D8: =FM_Conservative!$D$66/10000 -> -0.39695685 | E8: =FM_Conservative!$E$66/10000 -> -0.4164972 | F8: =FM_Conservative!$F$66/10000 -> -1.098076 | G8: =FM_Conservative!$G$66/10000 -> -0.02324566
A9: Opex | B9: 억원 | C9: =FM_Conservative!$C$69/10000 -> 9.216775 | D9: =FM_Conservative!$D$69/10000 -> 13.8166 | E9: =FM_Conservative!$E$69/10000 -> 30.5 | F9: =FM_Conservative!$F$69/10000 -> 43.9 | G9: =FM_Conservative!$G$69/10000 -> 56.7
A10: 영업이익 (근사) | B10: 억원 | C10: =FM_Conservative!$C$70/10000 -> -9.216775 | D10: =FM_Conservative!$D$70/10000 -> -14.213557 | E10: =FM_Conservative!$E$70/10000 -> -30.916497 | F10: =FM_Conservative!$F$70/10000 -> -44.998076 | G10: =FM_Conservative!$G$70/10000 -> -56.723246
A11: 누적 현금흐름 | B11: 억원 | C11: =FM_Conservative!$C$72/10000 -> -9.216775 | D11: =FM_Conservative!$D$72/10000 -> -23.560445 | E11: =FM_Conservative!$E$72/10000 -> -55.274209 | F11: =FM_Conservative!$F$72/10000 -> -100.09549 | G11: =FM_Conservative!$G$72/10000 -> -156.64195
A12: 설치 세대 (Remodeling + Retrofit + New-build) | B12: 세대 | C12: =FM_Conservative!$C$9 -> 0 | D12: =FM_Conservative!$D$9 -> 3 | E12: =FM_Conservative!$E$9 -> 30 | F12: =FM_Conservative!$F$9 -> 105 | G12: =FM_Conservative!$G$9 -> 230
A13: Robot 설치 | B13: 대 | C13: =FM_Conservative!$C$14 -> 0 | D13: =FM_Conservative!$D$14 -> 3 | E13: =FM_Conservative!$E$14 -> 22.5 | F13: =FM_Conservative!$F$14 -> 81.625 | G13: =FM_Conservative!$G$14 -> 184.04375
A14: Installed Robot (기말) | B14: 대 | C14: =FM_Conservative!$C$28 -> 0 | D14: =FM_Conservative!$D$28 -> 3 | E14: =FM_Conservative!$E$28 -> 25.5 | F14: =FM_Conservative!$F$28 -> 107.125 | G14: =FM_Conservative!$G$28 -> 291.16875
A15: 신축 Backlog | B15: 세대 | C15: =FM_Conservative!$C$29 -> 0 | D15: =FM_Conservative!$D$29 -> 0 | E15: =FM_Conservative!$E$29 -> 0 | F15: =FM_Conservative!$F$29 -> 48 | G15: =FM_Conservative!$G$29 -> 144
A16: OPERATE + EXPAND 비중 | B16: % | C16: =FM_Conservative!$C$78 -> 0 | D16: =FM_Conservative!$D$78 -> 0.14205955 | E16: =FM_Conservative!$E$78 -> 0.05474539 | F16: =FM_Conservative!$F$78 -> 0.039029195 | G16: =FM_Conservative!$G$78 -> 0.041439204
A18: Base | B18: 단위 | C18: Y1 | D18: Y2 | E18: Y3 | F18: Y4 | G18: Y5
A19: 매출 | B19: 억원 | C19: =FM_Base!$C$42/10000 -> 0 | D19: =FM_Base!$D$42/10000 -> 0.260511 | E19: =FM_Base!$E$42/10000 -> 7.4234195 | F19: =FM_Base!$F$42/10000 -> 35.918587 | G19: =FM_Base!$G$42/10000 -> 91.490638
A20: 매출총이익 | B20: 억원 | C20: =FM_Base!$C$60/10000 -> 0 | D20: =FM_Base!$D$60/10000 -> -0.21031785 | E20: =FM_Base!$E$60/10000 -> 1.7258479 | F20: =FM_Base!$F$60/10000 -> 10.248569 | G20: =FM_Base!$G$60/10000 -> 32.044477
A21: 매출총이익률 | B21: % | C21: =FM_Base!$C$61 -> 0 | D21: =FM_Base!$D$61 -> -0.8073281 | E21: =FM_Base!$E$61 -> 0.23248692 | F21: =FM_Base!$F$61 -> 0.28532772 | G21: =FM_Base!$G$61 -> 0.3502487
A22: Contribution | B22: 억원 | C22: =FM_Base!$C$66/10000 -> 0 | D22: =FM_Base!$D$66/10000 -> -0.25531785 | E22: =FM_Base!$E$66/10000 -> 0.71894793 | F22: =FM_Base!$F$66/10000 -> 6.4267186 | G22: =FM_Base!$G$66/10000 -> 23.069177
A23: Opex | B23: 억원 | C23: =FM_Base!$C$69/10000 -> 9.216775 | D23: =FM_Base!$D$69/10000 -> 13.8166 | E23: =FM_Base!$E$69/10000 -> 30.5 | F23: =FM_Base!$F$69/10000 -> 43.9 | G23: =FM_Base!$G$69/10000 -> 56.7
A24: 영업이익 (근사) | B24: 억원 | C24: =FM_Base!$C$70/10000 -> -9.216775 | D24: =FM_Base!$D$70/10000 -> -14.071918 | E24: =FM_Base!$E$70/10000 -> -29.781052 | F24: =FM_Base!$F$70/10000 -> -37.473281 | G24: =FM_Base!$G$70/10000 -> -33.630823
A25: 누적 현금흐름 | B25: 억원 | C25: =FM_Base!$C$72/10000 -> -9.216775 | D25: =FM_Base!$D$72/10000 -> -23.413865 | E25: =FM_Base!$E$72/10000 -> -54.548278 | F25: =FM_Base!$F$72/10000 -> -91.742539 | G25: =FM_Base!$G$72/10000 -> -125.09434
A26: 설치 세대 (Remodeling + Retrofit + New-build) | B26: 세대 | C26: =FM_Base!$C$9 -> 0 | D26: =FM_Base!$D$9 -> 3 | E26: =FM_Base!$E$9 -> 50 | F26: =FM_Base!$F$9 -> 200 | G26: =FM_Base!$G$9 -> 560
A27: Robot 설치 | B27: 대 | C27: =FM_Base!$C$14 -> 0 | D27: =FM_Base!$D$14 -> 3 | E27: =FM_Base!$E$14 -> 42.5 | F27: =FM_Base!$F$14 -> 173.75 | G27: =FM_Base!$G$14 -> 443.375
A28: Installed Robot (기말) | B28: 대 | C28: =FM_Base!$C$28 -> 0 | D28: =FM_Base!$D$28 -> 3 | E28: =FM_Base!$E$28 -> 45.5 | F28: =FM_Base!$F$28 -> 219.25 | G28: =FM_Base!$G$28 -> 662.625
A29: 신축 Backlog | B29: 세대 | C29: =FM_Base!$C$29 -> 0 | D29: =FM_Base!$D$29 -> 0 | E29: =FM_Base!$E$29 -> 80 | F29: =FM_Base!$F$29 -> 240 | G29: =FM_Base!$G$29 -> 400
A30: OPERATE + EXPAND 비중 | B30: % | C30: =FM_Base!$C$78 -> 0 | D30: =FM_Base!$D$78 -> 0.094280088 | E30: =FM_Base!$E$78 -> 0.053973711 | F30: =FM_Base!$F$78 -> 0.039046553 | G30: =FM_Base!$G$78 -> 0.041225868
A32: Upside | B32: 단위 | C32: Y1 | D32: Y2 | E32: Y3 | F32: Y4 | G32: Y5
A33: 매출 | B33: 억원 | C33: =FM_Upside!$C$42/10000 -> 0 | D33: =FM_Upside!$D$42/10000 -> 0.307701 | E33: =FM_Upside!$E$42/10000 -> 9.6346287 | F33: =FM_Upside!$F$42/10000 -> 55.237647 | G33: =FM_Upside!$G$42/10000 -> 154.77567
A34: 매출총이익 | B34: 억원 | C34: =FM_Upside!$C$60/10000 -> 0 | D34: =FM_Upside!$D$60/10000 -> -0.14501076 | E34: =FM_Upside!$E$60/10000 -> 2.7281883 | F34: =FM_Upside!$F$60/10000 -> 18.549148 | G34: =FM_Upside!$G$60/10000 -> 63.360874
A35: 매출총이익률 | B35: % | C35: =FM_Upside!$C$61 -> 0 | D35: =FM_Upside!$D$61 -> -0.47127166 | E35: =FM_Upside!$E$61 -> 0.28316486 | F35: =FM_Upside!$F$61 -> 0.33580626 | G35: =FM_Upside!$G$61 -> 0.4093723
A36: Contribution | B36: 억원 | C36: =FM_Upside!$C$66/10000 -> 0 | D36: =FM_Upside!$D$66/10000 -> -0.18701076 | E36: =FM_Upside!$E$66/10000 -> 1.3563733 | F36: =FM_Upside!$F$66/10000 -> 13.100638 | G36: =FM_Upside!$G$66/10000 -> 50.043774
A37: Opex | B37: 억원 | C37: =FM_Upside!$C$69/10000 -> 9.216775 | D37: =FM_Upside!$D$69/10000 -> 13.8166 | E37: =FM_Upside!$E$69/10000 -> 30.5 | F37: =FM_Upside!$F$69/10000 -> 43.9 | G37: =FM_Upside!$G$69/10000 -> 56.7
A38: 영업이익 (근사) | B38: 억원 | C38: =FM_Upside!$C$70/10000 -> -9.216775 | D38: =FM_Upside!$D$70/10000 -> -14.003611 | E38: =FM_Upside!$E$70/10000 -> -29.143627 | F38: =FM_Upside!$F$70/10000 -> -30.799362 | G38: =FM_Upside!$G$70/10000 -> -6.6562262
A39: 누적 현금흐름 | B39: 억원 | C39: =FM_Upside!$C$72/10000 -> -9.216775 | D39: =FM_Upside!$D$72/10000 -> -23.340617 | E39: =FM_Upside!$E$72/10000 -> -54.130179 | F39: =FM_Upside!$F$72/10000 -> -84.597251 | G39: =FM_Upside!$G$72/10000 -> -90.921187
A40: 설치 세대 (Remodeling + Retrofit + New-build) | B40: 세대 | C40: =FM_Upside!$C$9 -> 0 | D40: =FM_Upside!$D$9 -> 3 | E40: =FM_Upside!$E$9 -> 65 | F40: =FM_Upside!$F$9 -> 310 | G40: =FM_Upside!$G$9 -> 982
A41: Robot 설치 | B41: 대 | C41: =FM_Upside!$C$14 -> 0 | D41: =FM_Upside!$D$14 -> 3 | E41: =FM_Upside!$E$14 -> 55.25 | F41: =FM_Upside!$F$14 -> 269.17 | G41: =FM_Upside!$G$14 -> 753.1696
A42: Installed Robot (기말) | B42: 대 | C42: =FM_Upside!$C$28 -> 0 | D42: =FM_Upside!$D$28 -> 3 | E42: =FM_Upside!$E$28 -> 58.25 | F42: =FM_Upside!$F$28 -> 327.42 | G42: =FM_Upside!$G$28 -> 1080.5896
A43: 신축 Backlog | B43: 세대 | C43: =FM_Upside!$C$29 -> 0 | D43: =FM_Upside!$D$29 -> 0 | E43: =FM_Upside!$E$29 -> 192 | F43: =FM_Upside!$F$29 -> 480 | G43: =FM_Upside!$G$29 -> 672
...

Sheet Inputs
A1: Inputs — 단일값 가정 (만원 기준)
A3: Key | B3: 항목 | C3: 단위 | D3: Conservative | E3: Base | F3: Upside | G3: Tag | H3: Source / Note
A4: MARKET
A5: m_housing_total | B5: 총주택 (2025.11.1 기준) | C5: 천호 | D5: 20181 | E5: 20181 | F5: 20181 | G5: FACT | H5: 국가데이터처, 2025 인구주택총조사 등록센서스 결과 (2026.7.28 발표)
A6: m_apt_share | B6: 아파트 비중 (총주택 대비) | C6: % | D6: 0.658 | E6: 0.658 | F6: 0.658 | G6: FACT | H6: 국가데이터처, 2025 인구주택총조사
A7: m_house_20y_share | B7: 준공 20년 이상 주택 비중 | C7: % | D7: 0.56 | E7: 0.56 | F7: 0.56 | G7: FACT | H7: 국가데이터처, 2025 인구주택총조사
A8: m_house_30y_share | B8: 준공 30년 이상 주택 비중 | C8: % | D8: 0.306 | E8: 0.306 | F8: 0.306 | G8: FACT | H8: 국가데이터처, 2025 인구주택총조사
A9: m_apt_2023 | B9: 아파트 수 (2023) | C9: 천호 | D9: 12630 | E9: 12630 | F9: 12630 | G9: FACT | H9: 통계청, 2023 주택총조사 (보도 인용)
A10: m_apt_20y_2023 | B10: 준공 20년 이상 아파트 (2023) | C10: 천호 | D10: 6390 | E10: 6390 | F10: 6390 | G10: FACT | H10: 통계청, 2023 주택총조사 (보도 인용)
A11: m_txn_2025 | B11: 주택 매매거래 (2025, 전체 주택) | C11: 천호 | D11: 726 | E11: 726 | F11: 726 | G11: FACT | H11: KB주택시장리뷰 2026.2 (한국부동산원 자료)
A12: m_completion_2025 | B12: 주택 준공 (2025 연간, 전체 주택) | C12: 천호 | D12: 342.4 | E12: 342.4 | F12: 342.4 | G12: FACT | H12: 국토교통부, 2025년 12월 주택통계
A13: m_movein_2025 | B13: 아파트 입주 (2025) | C13: 천호 | D13: 236.3 | E13: 236.3 | F13: 236.3 | G13: FACT | H13: 부동산114 REPS
A14: m_movein_2026e | B14: 아파트 입주 예정 (2026) | C14: 천호 | D14: 183.1 | E14: 183.1 | F14: 183.1 | G14: FACT | H14: 부동산114 REPS (예정 물량)
A15: a_replace_cycle | B15: Kitchen 교체주기 (노후 아파트) | C15: 년 | D15: 22 | E15: 22 | F15: 22 | G15: ASSUMPTION | H15: 교차검증용 가정. 견적 · 인터뷰로 검증
A16: a_txn_apt_share | B16: 매매거래 중 아파트 비중 | C16: % | D16: 0.7 | E16: 0.7 | F16: 0.7 | G16: ASSUMPTION | H16: 부동산원 월별 아파트 거래 비중 확인 필요
... A27: a_premium_project | B27: Premium 단지 비중 (신축) | C27: % | D27: 0.15 | E27: 0.15 | F27: 0.15 | G27: ASSUMPTION | H27: 브랜드 · 분양가 기준 정의 필요
A28: VALUE
A29: f_helper_rate | B29: 가사서비스 시간당 요금 (플랫폼 4시간 59,900~64,900원) | C29: 만원/h | D29: 1.5 | E29: 1.5 | F29: 1.5 | G29: FACT | H29: 가사서비스 플랫폼 공개 요금 (2025, 보도 · 앱 정보)
A30: a_cleanup_min | B30: 식사 후 정리 시간 (식기 이동 · 식세기 · 수납, 일) | C30: 분/일 | D30: 40 | E30: 40 | F30: 40 | G30: ASSUMPTION | H30: Time-diary(n=30)로 검증
A31: a_auto_share | B31: CLEAN 자동화 가능 비중 | C31: % | D31: 0.6 | E31: 0.6 | F31: 0.6 | G31: ASSUMPTION | H31: 식기 이동 · 식세기 적재/인출 · 수납만. 행주 · 싱크 세척 제외
A32: fx | B32: 환율 (Benchmark 환산용) | C32: 원/USD | D32: 1400 | E32: 1400 | F32: 1400 | G32: ASSUMPTION | H32: 부품 Benchmark 환산 전용
A33: PRICE
A34: p_rr | B34: Interface · Integration — Remodeling (Robot Home · Rail · 식세기 Interface · Storage Dock) | C34: 만원/세대 | D34: 400 | E34: 450 | F34: 450 | G34: ASSUMPTION | H34: 주방 공사비 위 증분. 시스템에어컨 유상옵션(500~1,000만원) 대비 하단
A35: p_rr_new | B35: Interface Option — New-build (설계 반영, MH 공급가) | C35: 만원/세대 | D35: 200 | E35: 220 | F35: 220 | G35: ASSUMPTION | H35: 건설사 · 가구사 마진 별도. 분양 고객가 약 300만원 가정
A36: p_rt_if | B36: Interface Kit — Retrofit (Compact Mount · Dock · Vision Reference · Drop Zone) | C36: 만원/세대 | D36: 150 | E36: 150 | F36: 150 | G36: ASSUMPTION | H36: 기존 주방 유지. 최소 시공
A37: p_robot | B37: Robot System ASP (Arm · Adaptive Hand · Vision · Safety · Controller) | C37: 만원/대 | D37: 1290 | E37: 1490 | F37: 1490 | G37: ASSUMPTION | H37: Upside는 가격 인상 없음. WTP 검증 대상 1순위
A38: p_comm | B38: Installation · Calibration · Safety Check (Remodeling · New-build) | C38: 만원/대 | D38: 80 | E38: 80 | F38: 80 | G38: ASSUMPTION
A39: p_comm_rt | B39: Installation · Calibration (Retrofit, 현장 Calibration 비중 큼) | C39: 만원/대 | D39: 120 | E39: 120 | F39: 120 | G39: ASSUMPTION
A40: p_rent | B40: Robot Rental 월 요금 (Care Basic · Grip Kit 포함, 60개월) | C40: 만원/월 | D40: 29 | E40: 33 | F40: 33 | G40: ASSUMPTION | H40: 원가 Build-up (감가 · 금융 · Care · Grip · Reserve) + 마진
A41: rent_months | B41: Rental 계약기간 | C41: 개월 | D41: 60 | E41: 60 | F41: 60 | G41: ASSUMPTION
A42: p_care | B42: Care Basic 연 요금 (구매 고객) | C42: 만원/년 | D42: 42 | E42: 48 | F42: 48 | G42: ASSUMPTION | H42: 정기 안전점검 · Calibration · 원격진단 · SW Update · A/S 공임
A43: p_care_plus | B43: Care Plus 연 요금 (Kit 정기교체 포함) | C43: 만원/년 | D43: 72 | E43: 72 | F43: 72 | G43: ASSUMPTION | H43: 옵션 상품. 재무 Base에는 미반영
A44: p_grip | B44: Grip Kit (Finger Pad · Food-contact Tip · Suction Seal) | C44: 만원/Kit | D44: 4.5 | E44: 4.5 | F44: 4.5 | G44: ASSUMPTION | H44: 분기 교체 가정
A45: n_grip | B45: Grip Kit 교체 횟수 | C45: 회/년 | D45: 4 | E45: 4 | F45: 4 | G45: ASSUMPTION | H45: Pad 마모율 · 교체주기 검증 대상 (KPI: Pad 수명)
A46: p_clean | B46: Cleaning Kit (Brush · Wiper · Cleaning Pad) | C46: 만원/Kit | D46: 2.5 | E46: 2.5 | F46: 2.5 | G46: ASSUMPTION
A47: n_clean | B47: Cleaning Kit 교체 횟수 | C47: 회/년 | D47: 4 | E47: 4 | F47: 4 | G47: ASSUMPTION
A48: p_protect | B48: Protection Kit (Sensor Cover · Sleeve · Seal) | C48: 만원/Kit | D48: 4 | E48: 4 | F48: 4 | G48: ASSUMPTION
A49: n_protect | B49: Protection Kit 교체 횟수 | C49: 회/년 | D49: 2 | E49: 2 | F49: 2 | G49: ASSUMPTION
A50: cons_attach | B50: Consumables 구매율 | C50: % | D50: 0.55 | E50: 0.7 | F50: 0.7 | G50: ASSUMPTION
A51: care_attach | B51: Care 가입률 (구매 고객) | C51: % | D51: 0.55 | E51: 0.7 | F51: 0.7 | G51: ASSUMPTION
...

Sheet Inputs_Yearly
A1: Inputs_Yearly — 연도별 가정
A3: Key | B3: 항목 | C3: 단위 | D3: Scenario | E3: Y1 | F3: Y2 | G3: Y3 | H3: Y4 | I3: Y5 | J3: Tag | K3: Source / Note
A4: realization | B4: 가격 실현율 (Y2 Pilot 할인) | C4: % | D4: Conservative | E4: 1 | F4: 0.3 | G4: 1 | H4: 1 | I4: 1 | J4: ASSUMPTION | K4: Pilot은 할인 유료
A5: realization | B5: 가격 실현율 (Y2 Pilot 할인) | C5: % | D5: Base | E5: 1 | F5: 0.5 | G5: 1 | H5: 1 | I5: 1 | J5: ASSUMPTION | K5: Pilot은 할인 유료
A6: realization | B6: 가격 실현율 (Y2 Pilot 할인) | C6: % | D6: Upside | E6: 1 | F6: 0.6 | G6: 1 | H6: 1 | I6: 1 | J6: ASSUMPTION | K6: Pilot은 할인 유료
A8: smr | B8: Interface 표준부품 사용률 | C8: % | D8: Conservative | E8: 0.4 | F8: 0.45 | G8: 0.55 | H8: 0.62 | I8: 0.65 | J8: TARGET | K8: M24 65% 이상 목표 (M18 60% 미만이면 Interface 설계 재검토)
A9: smr | B9: Interface 표준부품 사용률 | C9: % | D9: Base | E9: 0.4 | F9: 0.5 | G9: 0.65 | H9: 0.75 | I9: 0.8 | J9: TARGET | K9: M24 65% 이상 목표 (M18 60% 미만이면 Interface 설계 재검토)
A10: smr | B10: Interface 표준부품 사용률 | C10: % | D10: Upside | E10: 0.4 | F10: 0.55 | G10: 0.7 | H10: 0.8 | I10: 0.85 | J10: TARGET | K10: M24 65% 이상 목표 (M18 60% 미만이면 Interface 설계 재검토)
A12: bom | B12: Robot System BOM (Adaptive Hand 포함) | C12: 만원/대 | D12: Conservative | E12: 1680 | F12: 1580 | G12: 1330 | H12: 1210 | I12: 1100 | J12: ASSUMPTION | K12: BOM 구성 Benchmark 기반 (부록). 수량 · 국산화 · 자체 Hand 원가 하락 가정
A13: bom | B13: Robot System BOM (Adaptive Hand 포함) | C13: 만원/대 | D13: Base | E13: 1680 | F13: 1520 | G13: 1180 | H13: 1030 | I13: 915 | J13: ASSUMPTION | K13: BOM 구성 Benchmark 기반 (부록). 수량 · 국산화 · 자체 Hand 원가 하락 가정
A14: bom | B14: Robot System BOM (Adaptive Hand 포함) | C14: 만원/대 | D14: Upside | E14: 1680 | F14: 1460 | G14: 1100 | H14: 950 | I14: 820 | J14: ASSUMPTION | K14: BOM 구성 Benchmark 기반 (부록). 수량 · 국산화 · 자체 Hand 원가 하락 가정
A16: comm_cost | B16: Installation · Calibration 원가 — Remodeling · New-build (MH 인력) | C16: 만원/대 | D16: Conservative | E16: 120 | F16: 100 | G16: 75 | H16: 62 | I16: 55 | J16: ASSUMPTION | K16: Calibration 시간 KPI와 연동
A17: comm_cost | B17: Installation · Calibration 원가 — Remodeling · New-build (MH 인력) | C17: 만원/대 | D17: Base | E17: 120 | F17: 90 | G17: 60 | H17: 45 | I17: 38 | J17: ASSUMPTION | K17: Calibration 시간 KPI와 연동
A18: comm_cost | B18: Installation · Calibration 원가 — Remodeling · New-build (MH 인력) | C18: 만원/대 | D18: Upside | E18: 120 | F18: 85 | G18: 52 | H18: 38 | I18: 30 | J18: ASSUMPTION | K18: Calibration 시간 KPI와 연동
... A46: attach | B46: Robot Attach Rate (Remodeling, 설치 시점) | C46: % | D46: Upside | E46: 1 | F46: 1 | G46: 0.85 | H46: 0.85 | I46: 0.85 | J46: ASSUMPTION | K46: 나머지는 Interface 선설치 (Robot 후설치)
A48: rental_share | B48: Rental 선택 비중 | C48: % | D48: Conservative | E48: 0 | F48: 0.3 | G48: 0.3 | H48: 0.35 | I48: 0.35 | J48: ASSUMPTION
A49: rental_share | B49: Rental 선택 비중 | C49: % | D49: Base | E49: 0 | F49: 0.3 | G49: 0.3 | H49: 0.4 | I49: 0.4 | J49: ASSUMPTION
A50: rental_share | B50: Rental 선택 비중 | C50: % | D50: Upside | E50: 0 | F50: 0.3 | G50: 0.3 | H50: 0.45 | I50: 0.45 | J50: ASSUMPTION
A52: partner_rental | B52: Rental 자산 보유 주체 (0 = MH Pilot, 1 = Rental Partner) | C52: flag | D52: Conservative | E52: 0 | F52: 0 | G52: 0 | H52: 1 | I52: 1 | J52: ASSUMPTION
A53: partner_rental | B53: Rental 자산 보유 주체 (0 = MH Pilot, 1 = Rental Partner) | C53: flag | D53: Base | E53: 0 | F53: 0 | G53: 0 | H53: 1 | I53: 1 | J53: ASSUMPTION
A54: partner_rental | B54: Rental 자산 보유 주체 (0 = MH Pilot, 1 = Rental Partner) | C54: flag | D54: Upside | E54: 0 | F54: 0 | G54: 0 | H54: 1 | I54: 1 | J54: ASSUMPTION
A56: projects | B56: 신축 Interface Option 계약 Project | C56: 개 | D56: Conservative | E56: 0 | F56: 0 | G56: 0 | H56: 1 | I56: 2 | J56: TARGET | K56: 계약 2년 후 입주 · 설치
A57: projects | B57: 신축 Interface Option 계약 Project | C57: 개 | D57: Base | E57: 0 | F57: 0 | G57: 1 | H57: 2 | I57: 3 | J57: TARGET | K57: 계약 2년 후 입주 · 설치
A58: projects | B58: 신축 Interface Option 계약 Project | C58: 개 | D58: Upside | E58: 0 | F58: 0 | G58: 2 | H58: 3 | I58: 4 | J58: TARGET | K58: 계약 2년 후 입주 · 설치
A60: fte | B60: 평균 인원 (FTE) | C60: 명 | D60: Conservative | E60: 7.0416667 | F60: 12.75 | G60: 20 | H60: 32 | I60: 42 | J60: ASSUMPTION | K60: Y1~Y2 = 팀 계획 (Budget_24M, Founder 2 + 신규 채용) · Y3부터 Series A 전제
A61: fte | B61: 평균 인원 (FTE) | C61: 명 | D61: Base | E61: 7.0416667 | F61: 12.75 | G61: 20 | H61: 32 | I61: 42 | J61: ASSUMPTION | K61: Y1~Y2 = 팀 계획 (Budget_24M, Founder 2 + 신규 채용) · Y3부터 Series A 전제
A62: fte | B62: 평균 인원 (FTE) | C62: 명 | D62: Upside | E62: 7.0416667 | F62: 12.75 | G62: 20 | H62: 32 | I62: 42 | J62: ASSUMPTION | K62: Y1~Y2 = 팀 계획 (Budget_24M, Founder 2 + 신규 채용) · Y3부터 Series A 전제
A64: loaded | B64: 인당 연 인건비 (4대보험 · 퇴직급여 포함, 평균) | C64: 만원/년 | D64: Conservative | E64: 7927.8107 | F64: 7611.7647 | G64: 8500 | H64: 8500 | I64: 8500 | J64: ASSUMPTION | K64: Y1~Y2 = 팀 계획 가중평균 · Y3~ 평균 연봉 약 7,100만원 × 1.2
A65: loaded | B65: 인당 연 인건비 (4대보험 · 퇴직급여 포함, 평균) | C65: 만원/년 | D65: Base | E65: 7927.8107 | F65: 7611.7647 | G65: 8500 | H65: 8500 | I65: 8500 | J65: ASSUMPTION | K65: Y1~Y2 = 팀 계획 가중평균 · Y3~ 평균 연봉 약 7,100만원 × 1.2
A66: loaded | B66: 인당 연 인건비 (4대보험 · 퇴직급여 포함, 평균) | C66: 만원/년 | D66: Upside | E66: 7927.8107 | F66: 7611.7647 | G66: 8500 | H66: 8500 | I66: 8500 | J66: ASSUMPTION | K66: Y1~Y2 = 팀 계획 가중평균 · Y3~ 평균 연봉 약 7,100만원 × 1.2
A68: robot_hw | B68: Robot Hardware (R&D 로봇 셀) | C68: 만원 | D68: Conservative | E68: 4800 | F68: 1600 | G68: 12000 | H68: 14000 | I68: 16000 | J68: ASSUMPTION
A69: robot_hw | B69: Robot Hardware (R&D 로봇 셀) | C69: 만원 | D69: Base | E69: 4800 | F69: 1600 | G69: 12000 | H69: 14000 | I69: 16000 | J69: ASSUMPTION
A70: robot_hw | B70: Robot Hardware (R&D 로봇 셀) | C70: 만원 | D70: Upside | E70: 4800 | F70: 1600 | G70: 12000 | H70: 14000 | I70: 16000 | J70: ASSUMPTION
A72: hand_proto | B72: Hand Prototype (비교군 · 자체 Hand v1~v3) | C72: 만원 | D72: Conservative | E72: 6000 | F72: 4000 | G72: 10000 | H72: 12000 | I72: 14000 | J72: ASSUMPTION
A73: hand_proto | B73: Hand Prototype (비교군 · 자체 Hand v1~v3) | C73: 만원 | D73: Base | E73: 6000 | F73: 4000 | G73: 10000 | H73: 12000 | I73: 14000 | J73: ASSUMPTION
A74: hand_proto | B74: Hand Prototype (비교군 · 자체 Hand v1~v3) | C74: 만원 | D74: Upside | E74: 6000 | F74: 4000 | G74: 10000 | H74: 12000 | I74: 14000 | J74: ASSUMPTION
A76: mockup | B76: Kitchen Mock-up (실물 크기 3종) | C76: 만원 | D76: Conservative | E76: 5000 | F76: 2500 | G76: 8000 | H76: 9000 | I76: 10000 | J76: ASSUMPTION
A77: mockup | B77: Kitchen Mock-up (실물 크기 3종) | C77: 만원 | D77: Base | E77: 5000 | F77: 2500 | G77: 8000 | H77: 9000 | I77: 10000 | J77: ASSUMPTION
A78: mockup | B78: Kitchen Mock-up (실물 크기 3종) | C78: 만원 | D78: Upside | E78: 5000 | F78: 2500 | G78: 8000 | H78: 9000 | I78: 10000 | J78: ASSUMPTION
A80: swdata | B80: Software · Data (GPU · Cloud · Annotation) | C80: 만원 | D80: Conservative | E80: 2500 | F80: 3000 | G80: 10000 | H80: 15000 | I80: 20000 | J80: ASSUMPTION
...

Sheet FM_Conservative
A1: 5-Year Bottom-up Model — Conservative (만원)
A2: 모든 입력은 Inputs / Inputs_Yearly의 Conservative 열·행을 참조 (녹색). 영업이익은 이자·세금 제외 근사.
A3: 항목 | B3: 단위 | C3: Y1 | D3: Y2 | E3: Y3 | F3: Y4 | G3: Y5 | H3: 5Y 합계
A4: VOLUME
A5: Remodeling — MH 직접 판매 | B5: 세대 | C5: =Inputs_Yearly!$E$32 -> 0 | D5: =Inputs_Yearly!$F$32 -> 3 | E5: =Inputs_Yearly!$G$32 -> 20 | F5: =Inputs_Yearly!$H$32 -> 35 | G5: =Inputs_Yearly!$I$32 -> 40 | H5: =SUM(C5:G5) -> 98
A6: Remodeling — Partner 경유 | B6: 세대 | C6: =Inputs_Yearly!$E$36 -> 0 | D6: =Inputs_Yearly!$F$36 -> 0 | E6: =Inputs_Yearly!$G$36 -> 10 | F6: =Inputs_Yearly!$H$36 -> 60 | G6: =Inputs_Yearly!$I$36 -> 150 | H6: =SUM(C6:G6) -> 220
A7: Existing Kitchen Retrofit | B7: 세대 | C7: =Inputs_Yearly!$E$40 -> 0 | D7: =Inputs_Yearly!$F$40 -> 0 | E7: =Inputs_Yearly!$G$40 -> 0 | F7: =Inputs_Yearly!$H$40 -> 10 | G7: =Inputs_Yearly!$I$40 -> 40 | H7: =SUM(C7:G7) -> 50
A8: New-build Interface Option 입주 (계약 2년 후) | B8: 세대 | C8: =0 -> 0 | D8: =0 -> 0 | E8: =Inputs_Yearly!$E$56*Inputs!$D$80*Inputs!$D$81 -> 0 | F8: =Inputs_Yearly!$F$56*Inputs!$D$80*Inputs!$D$81 -> 0 | G8: =Inputs_Yearly!$G$56*Inputs!$D$80*Inputs!$D$81 -> 0 | H8: =SUM(C8:G8) -> 0
A9: 설치 세대 합계 | B9: 세대 | C9: =C5+C6+C8+C7 -> 0 | D9: =D5+D6+D8+D7 -> 3 | E9: =E5+E6+E8+E7 -> 30 | F9: =F5+F6+F8+F7 -> 105 | G9: =G5+G6+G8+G7 -> 230 | H9: =SUM(C9:G9) -> 368
A10: Robot Attach Rate (Remodeling) | B10: % | C10: =Inputs_Yearly!$E$44 -> 1 | D10: =Inputs_Yearly!$F$44 -> 1 | E10: =Inputs_Yearly!$G$44 -> 0.75 | F10: =Inputs_Yearly!$H$44 -> 0.75 | G10: =Inputs_Yearly!$I$44 -> 0.75
A11: Interface 선설치 세대 Robot 후설치 | B11: 대 | C11: =0*Inputs!$D$79 -> 0 | D11: =C21*Inputs!$D$79 -> 0 | E11: =D21*Inputs!$D$79 -> 0 | F11: =E21*Inputs!$D$79 -> 0.375 | G11: =F21*Inputs!$D$79 -> 1.54375 | H11: =SUM(C11:G11) -> 1.91875
A12: Robot 설치 — Remodeling | B12: 대 | C12: =(C5+C6)*C10 -> 0 | D12: =(D5+D6)*D10 -> 3 | E12: =(E5+E6)*E10 -> 22.5 | F12: =(F5+F6)*F10 -> 71.25 | G12: =(G5+G6)*G10 -> 142.5 | H12: =SUM(C12:G12) -> 239.25
A13: Robot 설치 — New-build 입주 | B13: 대 | C13: =C8*Inputs!$D$82 -> 0 | D13: =D8*Inputs!$D$82 -> 0 | E13: =E8*Inputs!$D$82 -> 0 | F13: =F8*Inputs!$D$82 -> 0 | G13: =G8*Inputs!$D$82 -> 0 | H13: =SUM(C13:G13) -> 0
A14: Robot 설치 합계 (Retrofit 포함) | B14: 대 | C14: =C12+C13+C11+C7 -> 0 | D14: =D12+D13+D11+D7 -> 3 | E14: =E12+E13+E11+E7 -> 22.5 | F14: =F12+F13+F11+F7 -> 81.625 | G14: =G12+G13+G11+G7 -> 184.04375 | H14: =SUM(C14:G14) -> 291.16875
A15: Rental 비중 | B15: % | C15: =Inputs_Yearly!$E$48 -> 0 | D15: =Inputs_Yearly!$F$48 -> 0.3 | E15: =Inputs_Yearly!$G$48 -> 0.3 | F15: =Inputs_Yearly!$H$48 -> 0.35 | G15: =Inputs_Yearly!$I$48 -> 0.35
A16: Rental Partner 보유 Flag | B16: flag | C16: =Inputs_Yearly!$E$52 -> 0 | D16: =Inputs_Yearly!$F$52 -> 0 | E16: =Inputs_Yearly!$G$52 -> 0 | F16: =Inputs_Yearly!$H$52 -> 1 | G16: =Inputs_Yearly!$I$52 -> 1
A17: Rental 설치 | B17: 대 | C17: =C14*C15 -> 0 | D17: =D14*D15 -> 0.9 | E17: =E14*E15 -> 6.75 | F17: =F14*F15 -> 28.56875 | G17: =G14*G15 -> 64.415312 | H17: =SUM(C17:G17) -> 100.63406
A18: 구매 설치 | B18: 대 | C18: =C14-C17 -> 0 | D18: =D14-D17 -> 2.1 | E18: =E14-E17 -> 15.75 | F18: =F14-F17 -> 53.05625 | G18: =G14-G17 -> 119.62844 | H18: =SUM(C18:G18) -> 190.53469
A19: Rental — MH 보유 (Pilot) | B19: 대 | C19: =C17*(1-C16) -> 0 | D19: =D17*(1-D16) -> 0.9 | E19: =E17*(1-E16) -> 6.75 | F19: =F17*(1-F16) -> 0 | G19: =G17*(1-G16) -> 0 | H19: =SUM(C19:G19) -> 7.65
A20: Rental — Partner 보유 | B20: 대 | C20: =C17*C16 -> 0 | D20: =D17*D16 -> 0 | E20: =E17*E16 -> 0 | F20: =F17*F16 -> 28.56875 | G20: =G17*G16 -> 64.415312 | H20: =SUM(C20:G20) -> 92.984062
A21: Interface 선설치 (Robot 미설치) 누적 | B21: 세대 | C21: =0+(C5+C6)*(1-C10)+C8*(1-Inputs!$D$82)-C11 -> 0 | D21: =C21+(D5+D6)*(1-D10)+D8*(1-Inputs!$D$82)-D11 -> 0 | E21: =D21+(E5+E6)*(1-E10)+E8*(1-Inputs!$D$82)-E11 -> 7.5 | F21: =E21+(F5+F6)*(1-F10)+F8*(1-Inputs!$D$82)-F11 -> 30.875 | G21: =F21+(G5+G6)*(1-G10)+G8*(1-Inputs!$D$82)-G11 -> 76.83125
A22: 구매 Robot 누적 (기말) | B22: 대 | C22: =0+C18 -> 0 | D22: =C22+D18 -> 2.1 | E22: =D22+E18 -> 17.85 | F22: =E22+F18 -> 70.90625 | G22: =F22+G18 -> 190.53469
A23: 구매 Robot 평균 가동 | B23: 대 | C23: =0+C18/2 -> 0 | D23: =C22+D18/2 -> 1.05 | E23: =D22+E18/2 -> 9.975 | F23: =E22+F18/2 -> 44.378125 | G23: =F22+G18/2 -> 130.72047
A24: MH Rental 누적 (기말) | B24: 대 | C24: =0+C19 -> 0 | D24: =C24+D19 -> 0.9 | E24: =D24+E19 -> 7.65 | F24: =E24+F19 -> 7.65 | G24: =F24+G19 -> 7.65
A25: MH Rental 평균 가동 | B25: 대 | C25: =0+C19/2 -> 0 | D25: =C24+D19/2 -> 0.45 | E25: =D24+E19/2 -> 4.275 | F25: =E24+F19/2 -> 7.65 | G25: =F24+G19/2 -> 7.65
A26: Partner Rental 누적 (기말) | B26: 대 | C26: =0+C20 -> 0 | D26: =C26+D20 -> 0 | E26: =D26+E20 -> 0 | F26: =E26+F20 -> 28.56875 | G26: =F26+G20 -> 92.984062
A27: Partner Rental 평균 가동 | B27: 대 | C27: =0+C20/2 -> 0 | D27: =C26+D20/2 -> 0 | E27: =D26+E20/2 -> 0 | F27: =E26+F20/2 -> 14.284375 | G27: =F26+G20/2 -> 60.776406
A28: Installed Robot (기말) | B28: 대 | C28: =C22+C24+C26 -> 0 | D28: =D22+D24+D26 -> 3 | E28: =E22+E24+E26 -> 25.5 | F28: =F22+F24+F26 -> 107.125 | G28: =G22+G24+G26 -> 291.16875
A29: 신축 계약 Backlog (미설치 세대) | B29: 세대 | C29: =Inputs_Yearly!$E$56*Inputs!$D$80*Inputs!$D$81 -> 0 | D29: =(Inputs_Yearly!$F$56+Inputs_Yearly!$E$56)*Inputs!$D$80*Inputs!$D$81 -> 0 | E29: =(Inputs_Yearly!$G$56+Inputs_Yearly!$F$56)*Inputs!$D$80*Inputs!$D$81 -> 0 | F29: =(Inputs_Yearly!$H$56+Inputs_Yearly!$G$56)*Inputs!$D$80*Inputs!$D$81 -> 48 | G29: =(Inputs_Yearly!$I$56+Inputs_Yearly!$H$56)*Inputs!$D$80*Inputs!$D$81 -> 144
A30: REVENUE (만원) — INSTALL / OPERATE / EXPAND
A31: 가격 실현율 | B31: % | C31: =Inputs_Yearly!$E$4 -> 1 | D31: =Inputs_Yearly!$F$4 -> 0.3 | E31: =Inputs_Yearly!$G$4 -> 1 | F31: =Inputs_Yearly!$H$4 -> 1 | G31: =Inputs_Yearly!$I$4 -> 1
A32: Consumables 연 List (구매 고객) | B32: 만원/대 | C32: =Inputs!$D$44*Inputs!$D$45+Inputs!$D$46*Inputs!$D$47+Inputs!$D$48*Inputs!$D$49 -> 36 | D32: =Inputs!$D$44*Inputs!$D$45+Inputs!$D$46*Inputs!$D$47+Inputs!$D$48*Inputs!$D$49 -> 36 | E32: =Inputs!$D$44*Inputs!$D$45+Inputs!$D$46*Inputs!$D$47+Inputs!$D$48*Inputs!$D$49 -> 36 | F32: =Inputs!$D$44*Inputs!$D$45+Inputs!$D$46*Inputs!$D$47+Inputs!$D$48*Inputs!$D$49 -> 36 | G32: =Inputs!$D$44*Inputs!$D$45+Inputs!$D$46*Inputs!$D$47+Inputs!$D$48*Inputs!$D$49 -> 36
A33: Consumables 연 List (Rental, Grip 제외) | B33: 만원/대 | C33: =Inputs!$D$46*Inputs!$D$47+Inputs!$D$48*Inputs!$D$49 -> 18 | D33: =Inputs!$D$46*Inputs!$D$47+Inputs!$D$48*Inputs!$D$49 -> 18 | E33: =Inputs!$D$46*Inputs!$D$47+Inputs!$D$48*Inputs!$D$49 -> 18 | F33: =Inputs!$D$46*Inputs!$D$47+Inputs!$D$48*Inputs!$D$49 -> 18 | G33: =Inputs!$D$46*Inputs!$D$47+Inputs!$D$48*Inputs!$D$49 -> 18
A34: Grip Kit 연 List | B34: 만원/대 | C34: =Inputs!$D$44*Inputs!$D$45 -> 18 | D34: =Inputs!$D$44*Inputs!$D$45 -> 18 | E34: =Inputs!$D$44*Inputs!$D$45 -> 18 | F34: =Inputs!$D$44*Inputs!$D$45 -> 18 | G34: =Inputs!$D$44*Inputs!$D$45 -> 18
A35: INSTALL. Interface · Integration | B35: 만원 | C35: =(C5+C6)*Inputs!$D$34*C31+C8*Inputs!$D$35+C7*Inputs!$D$36*C31 -> 0 | D35: =(D5+D6)*Inputs!$D$34*D31+D8*Inputs!$D$35+D7*Inputs!$D$36*D31 -> 360 | E35: =(E5+E6)*Inputs!$D$34*E31+E8*Inputs!$D$35+E7*Inputs!$D$36*E31 -> 12000 | F35: =(F5+F6)*Inputs!$D$34*F31+F8*Inputs!$D$35+F7*Inputs!$D$36*F31 -> 39500 | G35: =(G5+G6)*Inputs!$D$34*G31+G8*Inputs!$D$35+G7*Inputs!$D$36*G31 -> 82000 | H35: =SUM(C35:G35) -> 133860
A36: INSTALL. Installation · Calibration | B36: 만원 | C36: =(C14-C7)*Inputs!$D$38*C31+C7*Inputs!$D$39*C31 -> 0 | D36: =(D14-D7)*Inputs!$D$38*D31+D7*Inputs!$D$39*D31 -> 72 | E36: =(E14-E7)*Inputs!$D$38*E31+E7*Inputs!$D$39*E31 -> 1800 | F36: =(F14-F7)*Inputs!$D$38*F31+F7*Inputs!$D$39*F31 -> 6930 | G36: =(G14-G7)*Inputs!$D$38*G31+G7*Inputs!$D$39*G31 -> 16323.5 | H36: =SUM(C36:G36) -> 25125.5
A37: INSTALL. Robot System (구매 + Rental Partner 공급) | B37: 만원 | C37: =C18*Inputs!$D$37*C31+C20*Inputs!$D$37*Inputs!$D$56 -> 0 | D37: =D18*Inputs!$D$37*D31+D20*Inputs!$D$37*Inputs!$D$56 -> 812.7 | E37: =E18*Inputs!$D$37*E31+E20*Inputs!$D$37*Inputs!$D$56 -> 20317.5 | F37: =F18*Inputs!$D$37*F31+F20*Inputs!$D$37*Inputs!$D$56 -> 100873.81 | G37: =G18*Inputs!$D$37*G31+G20*Inputs!$D$37*Inputs!$D$56 -> 227444.95 | H37: =SUM(C37:G37) -> 349448.95
A38: OPERATE. Rental (MH 보유) | B38: 만원 | C38: =C25*Inputs!$D$40*12 -> 0 | D38: =D25*Inputs!$D$40*12 -> 156.6 | E38: =E25*Inputs!$D$40*12 -> 1487.7 | F38: =F25*Inputs!$D$40*12 -> 2662.2 | G38: =G25*Inputs!$D$40*12 -> 2662.2 | H38: =SUM(C38:G38) -> 6968.7
A39: OPERATE. Care (구매 고객 + Partner 서비스료) | B39: 만원 | C39: =C23*Inputs!$D$51*Inputs!$D$42+C27*Inputs!$D$57*12 -> 0 | D39: =D23*Inputs!$D$51*Inputs!$D$42+D27*Inputs!$D$57*12 -> 24.255 | E39: =E23*Inputs!$D$51*Inputs!$D$42+E27*Inputs!$D$57*12 -> 230.4225 | F39: =F23*Inputs!$D$51*Inputs!$D$42+F27*Inputs!$D$57*12 -> 2053.6097 | G39: =G23*Inputs!$D$51*Inputs!$D$42+G27*Inputs!$D$57*12 -> 7395.5441 | H39: =SUM(C39:G39) -> 9703.8313
A40: OPERATE. Consumables | B40: 만원 | C40: =C23*Inputs!$D$50*C32+(C25+C27)*Inputs!$D$50*C33 -> 0 | D40: =D23*Inputs!$D$50*D32+(D25+D27)*Inputs!$D$50*D33 -> 25.245 | E40: =E23*Inputs!$D$50*E32+(E25+E27)*Inputs!$D$50*E33 -> 239.8275 | F40: =F23*Inputs!$D$50*F32+(F25+F27)*Inputs!$D$50*F33 -> 1095.8372 | G40: =G23*Inputs!$D$50*G32+(G25+G27)*Inputs!$D$50*G33 -> 3265.6867 | H40: =SUM(C40:G40) -> 4626.5964
...

Sheet FM_Base
A1: 5-Year Bottom-up Model — Base (만원)
A2: 모든 입력은 Inputs / Inputs_Yearly의 Base 열·행을 참조 (녹색). 영업이익은 이자·세금 제외 근사.
A3: 항목 | B3: 단위 | C3: Y1 | D3: Y2 | E3: Y3 | F3: Y4 | G3: Y5 | H3: 5Y 합계
A4: VOLUME
A5: Remodeling — MH 직접 판매 | B5: 세대 | C5: =Inputs_Yearly!$E$33 -> 0 | D5: =Inputs_Yearly!$F$33 -> 3 | E5: =Inputs_Yearly!$G$33 -> 30 | F5: =Inputs_Yearly!$H$33 -> 50 | G5: =Inputs_Yearly!$I$33 -> 60 | H5: =SUM(C5:G5) -> 143
A6: Remodeling — Partner 경유 | B6: 세대 | C6: =Inputs_Yearly!$E$37 -> 0 | D6: =Inputs_Yearly!$F$37 -> 0 | E6: =Inputs_Yearly!$G$37 -> 20 | F6: =Inputs_Yearly!$H$37 -> 130 | G6: =Inputs_Yearly!$I$37 -> 340 | H6: =SUM(C6:G6) -> 490
A7: Existing Kitchen Retrofit | B7: 세대 | C7: =Inputs_Yearly!$E$41 -> 0 | D7: =Inputs_Yearly!$F$41 -> 0 | E7: =Inputs_Yearly!$G$41 -> 0 | F7: =Inputs_Yearly!$H$41 -> 20 | G7: =Inputs_Yearly!$I$41 -> 80 | H7: =SUM(C7:G7) -> 100
A8: New-build Interface Option 입주 (계약 2년 후) | B8: 세대 | C8: =0 -> 0 | D8: =0 -> 0 | E8: =Inputs_Yearly!$E$57*Inputs!$E$80*Inputs!$E$81 -> 0 | F8: =Inputs_Yearly!$F$57*Inputs!$E$80*Inputs!$E$81 -> 0 | G8: =Inputs_Yearly!$G$57*Inputs!$E$80*Inputs!$E$81 -> 80 | H8: =SUM(C8:G8) -> 80
A9: 설치 세대 합계 | B9: 세대 | C9: =C5+C6+C8+C7 -> 0 | D9: =D5+D6+D8+D7 -> 3 | E9: =E5+E6+E8+E7 -> 50 | F9: =F5+F6+F8+F7 -> 200 | G9: =G5+G6+G8+G7 -> 560 | H9: =SUM(C9:G9) -> 813
A10: Robot Attach Rate (Remodeling) | B10: % | C10: =Inputs_Yearly!$E$45 -> 1 | D10: =Inputs_Yearly!$F$45 -> 1 | E10: =Inputs_Yearly!$G$45 -> 0.85 | F10: =Inputs_Yearly!$H$45 -> 0.85 | G10: =Inputs_Yearly!$I$45 -> 0.85
A11: Interface 선설치 세대 Robot 후설치 | B11: 대 | C11: =0*Inputs!$E$79 -> 0 | D11: =C21*Inputs!$E$79 -> 0 | E11: =D21*Inputs!$E$79 -> 0 | F11: =E21*Inputs!$E$79 -> 0.75 | G11: =F21*Inputs!$E$79 -> 3.375 | H11: =SUM(C11:G11) -> 4.125
A12: Robot 설치 — Remodeling | B12: 대 | C12: =(C5+C6)*C10 -> 0 | D12: =(D5+D6)*D10 -> 3 | E12: =(E5+E6)*E10 -> 42.5 | F12: =(F5+F6)*F10 -> 153 | G12: =(G5+G6)*G10 -> 340 | H12: =SUM(C12:G12) -> 538.5
A13: Robot 설치 — New-build 입주 | B13: 대 | C13: =C8*Inputs!$E$82 -> 0 | D13: =D8*Inputs!$E$82 -> 0 | E13: =E8*Inputs!$E$82 -> 0 | F13: =F8*Inputs!$E$82 -> 0 | G13: =G8*Inputs!$E$82 -> 20 | H13: =SUM(C13:G13) -> 20
A14: Robot 설치 합계 (Retrofit 포함) | B14: 대 | C14: =C12+C13+C11+C7 -> 0 | D14: =D12+D13+D11+D7 -> 3 | E14: =E12+E13+E11+E7 -> 42.5 | F14: =F12+F13+F11+F7 -> 173.75 | G14: =G12+G13+G11+G7 -> 443.375 | H14: =SUM(C14:G14) -> 662.625
A15: Rental 비중 | B15: % | C15: =Inputs_Yearly!$E$49 -> 0 | D15: =Inputs_Yearly!$F$49 -> 0.3 | E15: =Inputs_Yearly!$G$49 -> 0.3 | F15: =Inputs_Yearly!$H$49 -> 0.4 | G15: =Inputs_Yearly!$I$49 -> 0.4
A16: Rental Partner 보유 Flag | B16: flag | C16: =Inputs_Yearly!$E$53 -> 0 | D16: =Inputs_Yearly!$F$53 -> 0 | E16: =Inputs_Yearly!$G$53 -> 0 | F16: =Inputs_Yearly!$H$53 -> 1 | G16: =Inputs_Yearly!$I$53 -> 1
A17: Rental 설치 | B17: 대 | C17: =C14*C15 -> 0 | D17: =D14*D15 -> 0.9 | E17: =E14*E15 -> 12.75 | F17: =F14*F15 -> 69.5 | G17: =G14*G15 -> 177.35 | H17: =SUM(C17:G17) -> 260.5
A18: 구매 설치 | B18: 대 | C18: =C14-C17 -> 0 | D18: =D14-D17 -> 2.1 | E18: =E14-E17 -> 29.75 | F18: =F14-F17 -> 104.25 | G18: =G14-G17 -> 266.025 | H18: =SUM(C18:G18) -> 402.125
A19: Rental — MH 보유 (Pilot) | B19: 대 | C19: =C17*(1-C16) -> 0 | D19: =D17*(1-D16) -> 0.9 | E19: =E17*(1-E16) -> 12.75 | F19: =F17*(1-F16) -> 0 | G19: =G17*(1-G16) -> 0 | H19: =SUM(C19:G19) -> 13.65
A20: Rental — Partner 보유 | B20: 대 | C20: =C17*C16 -> 0 | D20: =D17*D16 -> 0 | E20: =E17*E16 -> 0 | F20: =F17*F16 -> 69.5 | G20: =G17*G16 -> 177.35 | H20: =SUM(C20:G20) -> 246.85
A21: Interface 선설치 (Robot 미설치) 누적 | B21: 세대 | C21: =0+(C5+C6)*(1-C10)+C8*(1-Inputs!$E$82)-C11 -> 0 | D21: =C21+(D5+D6)*(1-D10)+D8*(1-Inputs!$E$82)-D11 -> 0 | E21: =D21+(E5+E6)*(1-E10)+E8*(1-Inputs!$E$82)-E11 -> 7.5 | F21: =E21+(F5+F6)*(1-F10)+F8*(1-Inputs!$E$82)-F11 -> 33.75 | G21: =F21+(G5+G6)*(1-G10)+G8*(1-Inputs!$E$82)-G11 -> 150.375
A22: 구매 Robot 누적 (기말) | B22: 대 | C22: =0+C18 -> 0 | D22: =C22+D18 -> 2.1 | E22: =D22+E18 -> 31.85 | F22: =E22+F18 -> 136.1 | G22: =F22+G18 -> 402.125
A23: 구매 Robot 평균 가동 | B23: 대 | C23: =0+C18/2 -> 0 | D23: =C22+D18/2 -> 1.05 | E23: =D22+E18/2 -> 16.975 | F23: =E22+F18/2 -> 83.975 | G23: =F22+G18/2 -> 269.1125
A24: MH Rental 누적 (기말) | B24: 대 | C24: =0+C19 -> 0 | D24: =C24+D19 -> 0.9 | E24: =D24+E19 -> 13.65 | F24: =E24+F19 -> 13.65 | G24: =F24+G19 -> 13.65
A25: MH Rental 평균 가동 | B25: 대 | C25: =0+C19/2 -> 0 | D25: =C24+D19/2 -> 0.45 | E25: =D24+E19/2 -> 7.275 | F25: =E24+F19/2 -> 13.65 | G25: =F24+G19/2 -> 13.65
A26: Partner Rental 누적 (기말) | B26: 대 | C26: =0+C20 -> 0 | D26: =C26+D20 -> 0 | E26: =D26+E20 -> 0 | F26: =E26+F20 -> 69.5 | G26: =F26+G20 -> 246.85
A27: Partner Rental 평균 가동 | B27: 대 | C27: =0+C20/2 -> 0 | D27: =C26+D20/2 -> 0 | E27: =D26+E20/2 -> 0 | F27: =E26+F20/2 -> 34.75 | G27: =F26+G20/2 -> 158.175
A28: Installed Robot (기말) | B28: 대 | C28: =C22+C24+C26 -> 0 | D28: =D22+D24+D26 -> 3 | E28: =E22+E24+E26 -> 45.5 | F28: =F22+F24+F26 -> 219.25 | G28: =G22+G24+G26 -> 662.625
A29: 신축 계약 Backlog (미설치 세대) | B29: 세대 | C29: =Inputs_Yearly!$E$57*Inputs!$E$80*Inputs!$E$81 -> 0 | D29: =(Inputs_Yearly!$F$57+Inputs_Yearly!$E$57)*Inputs!$E$80*Inputs!$E$81 -> 0 | E29: =(Inputs_Yearly!$G$57+Inputs_Yearly!$F$57)*Inputs!$E$80*Inputs!$E$81 -> 80 | F29: =(Inputs_Yearly!$H$57+Inputs_Yearly!$G$57)*Inputs!$E$80*Inputs!$E$81 -> 240 | G29: =(Inputs_Yearly!$I$57+Inputs_Yearly!$H$57)*Inputs!$E$80*Inputs!$E$81 -> 400
A30: REVENUE (만원) — INSTALL / OPERATE / EXPAND
A31: 가격 실현율 | B31: % | C31: =Inputs_Yearly!$E$5 -> 1 | D31: =Inputs_Yearly!$F$5 -> 0.5 | E31: =Inputs_Yearly!$G$5 -> 1 | F31: =Inputs_Yearly!$H$5 -> 1 | G31: =Inputs_Yearly!$I$5 -> 1
A32: Consumables 연 List (구매 고객) | B32: 만원/대 | C32: =Inputs!$E$44*Inputs!$E$45+Inputs!$E$46*Inputs!$E$47+Inputs!$E$48*Inputs!$E$49 -> 36 | D32: =Inputs!$E$44*Inputs!$E$45+Inputs!$E$46*Inputs!$E$47+Inputs!$E$48*Inputs!$E$49 -> 36 | E32: =Inputs!$E$44*Inputs!$E$45+Inputs!$E$46*Inputs!$E$47+Inputs!$E$48*Inputs!$E$49 -> 36 | F32: =Inputs!$E$44*Inputs!$E$45+Inputs!$E$46*Inputs!$E$47+Inputs!$E$48*Inputs!$E$49 -> 36 | G32: =Inputs!$E$44*Inputs!$E$45+Inputs!$E$46*Inputs!$E$47+Inputs!$E$48*Inputs!$E$49 -> 36
A33: Consumables 연 List (Rental, Grip 제외) | B33: 만원/대 | C33: =Inputs!$E$46*Inputs!$E$47+Inputs!$E$48*Inputs!$E$49 -> 18 | D33: =Inputs!$E$46*Inputs!$E$47+Inputs!$E$48*Inputs!$E$49 -> 18 | E33: =Inputs!$E$46*Inputs!$E$47+Inputs!$E$48*Inputs!$E$49 -> 18 | F33: =Inputs!$E$46*Inputs!$E$47+Inputs!$E$48*Inputs!$E$49 -> 18 | G33: =Inputs!$E$46*Inputs!$E$47+Inputs!$E$48*Inputs!$E$49 -> 18
A34: Grip Kit 연 List | B34: 만원/대 | C34: =Inputs!$E$44*Inputs!$E$45 -> 18 | D34: =Inputs!$E$44*Inputs!$E$45 -> 18 | E34: =Inputs!$E$44*Inputs!$E$45 -> 18 | F34: =Inputs!$E$44*Inputs!$E$45 -> 18 | G34: =Inputs!$E$44*Inputs!$E$45 -> 18
A35: INSTALL. Interface · Integration | B35: 만원 | C35: =(C5+C6)*Inputs!$E$34*C31+C8*Inputs!$E$35+C7*Inputs!$E$36*C31 -> 0 | D35: =(D5+D6)*Inputs!$E$34*D31+D8*Inputs!$E$35+D7*Inputs!$E$36*D31 -> 675 | E35: =(E5+E6)*Inputs!$E$34*E31+E8*Inputs!$E$35+E7*Inputs!$E$36*E31 -> 22500 | F35: =(F5+F6)*Inputs!$E$34*F31+F8*Inputs!$E$35+F7*Inputs!$E$36*F31 -> 84000 | G35: =(G5+G6)*Inputs!$E$34*G31+G8*Inputs!$E$35+G7*Inputs!$E$36*G31 -> 209600 | H35: =SUM(C35:G35) -> 316775
A36: INSTALL. Installation · Calibration | B36: 만원 | C36: =(C14-C7)*Inputs!$E$38*C31+C7*Inputs!$E$39*C31 -> 0 | D36: =(D14-D7)*Inputs!$E$38*D31+D7*Inputs!$E$39*D31 -> 120 | E36: =(E14-E7)*Inputs!$E$38*E31+E7*Inputs!$E$39*E31 -> 3400 | F36: =(F14-F7)*Inputs!$E$38*F31+F7*Inputs!$E$39*F31 -> 14700 | G36: =(G14-G7)*Inputs!$E$38*G31+G7*Inputs!$E$39*G31 -> 38670 | H36: =SUM(C36:G36) -> 56890
A37: INSTALL. Robot System (구매 + Rental Partner 공급) | B37: 만원 | C37: =C18*Inputs!$E$37*C31+C20*Inputs!$E$37*Inputs!$E$56 -> 0 | D37: =D18*Inputs!$E$37*D31+D20*Inputs!$E$37*Inputs!$E$56 -> 1564.5 | E37: =E18*Inputs!$E$37*E31+E20*Inputs!$E$37*Inputs!$E$56 -> 44327.5 | F37: =F18*Inputs!$E$37*F31+F20*Inputs!$E$37*Inputs!$E$56 -> 246460.9 | G37: =G18*Inputs!$E$37*G31+G20*Inputs!$E$37*Inputs!$E$56 -> 628918.57 | H37: =SUM(C37:G37) -> 921271.47
A38: OPERATE. Rental (MH 보유) | B38: 만원 | C38: =C25*Inputs!$E$40*12 -> 0 | D38: =D25*Inputs!$E$40*12 -> 178.2 | E38: =E25*Inputs!$E$40*12 -> 2880.9 | F38: =F25*Inputs!$E$40*12 -> 5405.4 | G38: =G25*Inputs!$E$40*12 -> 5405.4 | H38: =SUM(C38:G38) -> 13869.9
A39: OPERATE. Care (구매 고객 + Partner 서비스료) | B39: 만원 | C39: =C23*Inputs!$E$51*Inputs!$E$42+C27*Inputs!$E$57*12 -> 0 | D39: =D23*Inputs!$E$51*Inputs!$E$42+D27*Inputs!$E$57*12 -> 35.28 | E39: =E23*Inputs!$E$51*Inputs!$E$42+E27*Inputs!$E$57*12 -> 570.36 | F39: =F23*Inputs!$E$51*Inputs!$E$42+F27*Inputs!$E$57*12 -> 5323.56 | G39: =G23*Inputs!$E$51*Inputs!$E$42+G27*Inputs!$E$57*12 -> 20430.78 | H39: =SUM(C39:G39) -> 26359.98
A40: OPERATE. Consumables | B40: 만원 | C40: =C23*Inputs!$E$50*C32+(C25+C27)*Inputs!$E$50*C33 -> 0 | D40: =D23*Inputs!$E$50*D32+(D25+D27)*Inputs!$E$50*D33 -> 32.13 | E40: =E23*Inputs!$E$50*E32+(E25+E27)*Inputs!$E$50*E33 -> 519.435 | F40: =F23*Inputs!$E$50*F32+(F25+F27)*Inputs!$E$50*F33 -> 2726.01 | G40: =G23*Inputs!$E$50*G32+(G25+G27)*Inputs!$E$50*G33 -> 8946.63 | H40: =SUM(C40:G40) -> 12224.205
...

Sheet FM_Upside
A1: 5-Year Bottom-up Model — Upside (만원)
A2: 모든 입력은 Inputs / Inputs_Yearly의 Upside 열·행을 참조 (녹색). 영업이익은 이자·세금 제외 근사.
A3: 항목 | B3: 단위 | C3: Y1 | D3: Y2 | E3: Y3 | F3: Y4 | G3: Y5 | H3: 5Y 합계
A4: VOLUME
A5: Remodeling — MH 직접 판매 | B5: 세대 | C5: =Inputs_Yearly!$E$34 -> 0 | D5: =Inputs_Yearly!$F$34 -> 3 | E5: =Inputs_Yearly!$G$34 -> 35 | F5: =Inputs_Yearly!$H$34 -> 60 | G5: =Inputs_Yearly!$I$34 -> 70 | H5: =SUM(C5:G5) -> 168
A6: Remodeling — Partner 경유 | B6: 세대 | C6: =Inputs_Yearly!$E$38 -> 0 | D6: =Inputs_Yearly!$F$38 -> 0 | E6: =Inputs_Yearly!$G$38 -> 30 | F6: =Inputs_Yearly!$H$38 -> 220 | G6: =Inputs_Yearly!$I$38 -> 600 | H6: =SUM(C6:G6) -> 850
A7: Existing Kitchen Retrofit | B7: 세대 | C7: =Inputs_Yearly!$E$42 -> 0 | D7: =Inputs_Yearly!$F$42 -> 0 | E7: =Inputs_Yearly!$G$42 -> 0 | F7: =Inputs_Yearly!$H$42 -> 30 | G7: =Inputs_Yearly!$I$42 -> 120 | H7: =SUM(C7:G7) -> 150
A8: New-build Interface Option 입주 (계약 2년 후) | B8: 세대 | C8: =0 -> 0 | D8: =0 -> 0 | E8: =Inputs_Yearly!$E$58*Inputs!$F$80*Inputs!$F$81 -> 0 | F8: =Inputs_Yearly!$F$58*Inputs!$F$80*Inputs!$F$81 -> 0 | G8: =Inputs_Yearly!$G$58*Inputs!$F$80*Inputs!$F$81 -> 192 | H8: =SUM(C8:G8) -> 192
A9: 설치 세대 합계 | B9: 세대 | C9: =C5+C6+C8+C7 -> 0 | D9: =D5+D6+D8+D7 -> 3 | E9: =E5+E6+E8+E7 -> 65 | F9: =F5+F6+F8+F7 -> 310 | G9: =G5+G6+G8+G7 -> 982 | H9: =SUM(C9:G9) -> 1360
A10: Robot Attach Rate (Remodeling) | B10: % | C10: =Inputs_Yearly!$E$46 -> 1 | D10: =Inputs_Yearly!$F$46 -> 1 | E10: =Inputs_Yearly!$G$46 -> 0.85 | F10: =Inputs_Yearly!$H$46 -> 0.85 | G10: =Inputs_Yearly!$I$46 -> 0.85
A11: Interface 선설치 세대 Robot 후설치 | B11: 대 | C11: =0*Inputs!$F$79 -> 0 | D11: =C21*Inputs!$F$79 -> 0 | E11: =D21*Inputs!$F$79 -> 0 | F11: =E21*Inputs!$F$79 -> 1.17 | G11: =F21*Inputs!$F$79 -> 6.0696 | H11: =SUM(C11:G11) -> 7.2396
A12: Robot 설치 — Remodeling | B12: 대 | C12: =(C5+C6)*C10 -> 0 | D12: =(D5+D6)*D10 -> 3 | E12: =(E5+E6)*E10 -> 55.25 | F12: =(F5+F6)*F10 -> 238 | G12: =(G5+G6)*G10 -> 569.5 | H12: =SUM(C12:G12) -> 865.75
A13: Robot 설치 — New-build 입주 | B13: 대 | C13: =C8*Inputs!$F$82 -> 0 | D13: =D8*Inputs!$F$82 -> 0 | E13: =E8*Inputs!$F$82 -> 0 | F13: =F8*Inputs!$F$82 -> 0 | G13: =G8*Inputs!$F$82 -> 57.6 | H13: =SUM(C13:G13) -> 57.6
A14: Robot 설치 합계 (Retrofit 포함) | B14: 대 | C14: =C12+C13+C11+C7 -> 0 | D14: =D12+D13+D11+D7 -> 3 | E14: =E12+E13+E11+E7 -> 55.25 | F14: =F12+F13+F11+F7 -> 269.17 | G14: =G12+G13+G11+G7 -> 753.1696 | H14: =SUM(C14:G14) -> 1080.5896
A15: Rental 비중 | B15: % | C15: =Inputs_Yearly!$E$50 -> 0 | D15: =Inputs_Yearly!$F$50 -> 0.3 | E15: =Inputs_Yearly!$G$50 -> 0.3 | F15: =Inputs_Yearly!$H$50 -> 0.45 | G15: =Inputs_Yearly!$I$50 -> 0.45
A16: Rental Partner 보유 Flag | B16: flag | C16: =Inputs_Yearly!$E$54 -> 0 | D16: =Inputs_Yearly!$F$54 -> 0 | E16: =Inputs_Yearly!$G$54 -> 0 | F16: =Inputs_Yearly!$H$54 -> 1 | G16: =Inputs_Yearly!$I$54 -> 1
A17: Rental 설치 | B17: 대 | C17: =C14*C15 -> 0 | D17: =D14*D15 -> 0.9 | E17: =E14*E15 -> 16.575 | F17: =F14*F15 -> 121.1265 | G17: =G14*G15 -> 338.92632 | H17: =SUM(C17:G17) -> 477.52782
A18: 구매 설치 | B18: 대 | C18: =C14-C17 -> 0 | D18: =D14-D17 -> 2.1 | E18: =E14-E17 -> 38.675 | F18: =F14-F17 -> 148.0435 | G18: =G14-G17 -> 414.24328 | H18: =SUM(C18:G18) -> 603.06178
A19: Rental — MH 보유 (Pilot) | B19: 대 | C19: =C17*(1-C16) -> 0 | D19: =D17*(1-D16) -> 0.9 | E19: =E17*(1-E16) -> 16.575 | F19: =F17*(1-F16) -> 0 | G19: =G17*(1-G16) -> 0 | H19: =SUM(C19:G19) -> 17.475
A20: Rental — Partner 보유 | B20: 대 | C20: =C17*C16 -> 0 | D20: =D17*D16 -> 0 | E20: =E17*E16 -> 0 | F20: =F17*F16 -> 121.1265 | G20: =G17*G16 -> 338.92632 | H20: =SUM(C20:G20) -> 460.05282
A21: Interface 선설치 (Robot 미설치) 누적 | B21: 세대 | C21: =0+(C5+C6)*(1-C10)+C8*(1-Inputs!$F$82)-C11 -> 0 | D21: =C21+(D5+D6)*(1-D10)+D8*(1-Inputs!$F$82)-D11 -> 0 | E21: =D21+(E5+E6)*(1-E10)+E8*(1-Inputs!$F$82)-E11 -> 9.75 | F21: =E21+(F5+F6)*(1-F10)+F8*(1-Inputs!$F$82)-F11 -> 50.58 | G21: =F21+(G5+G6)*(1-G10)+G8*(1-Inputs!$F$82)-G11 -> 279.4104
A22: 구매 Robot 누적 (기말) | B22: 대 | C22: =0+C18 -> 0 | D22: =C22+D18 -> 2.1 | E22: =D22+E18 -> 40.775 | F22: =E22+F18 -> 188.8185 | G22: =F22+G18 -> 603.06178
A23: 구매 Robot 평균 가동 | B23: 대 | C23: =0+C18/2 -> 0 | D23: =C22+D18/2 -> 1.05 | E23: =D22+E18/2 -> 21.4375 | F23: =E22+F18/2 -> 114.79675 | G23: =F22+G18/2 -> 395.94014
A24: MH Rental 누적 (기말) | B24: 대 | C24: =0+C19 -> 0 | D24: =C24+D19 -> 0.9 | E24: =D24+E19 -> 17.475 | F24: =E24+F19 -> 17.475 | G24: =F24+G19 -> 17.475
A25: MH Rental 평균 가동 | B25: 대 | C25: =0+C19/2 -> 0 | D25: =C24+D19/2 -> 0.45 | E25: =D24+E19/2 -> 9.1875 | F25: =E24+F19/2 -> 17.475 | G25: =F24+G19/2 -> 17.475
A26: Partner Rental 누적 (기말) | B26: 대 | C26: =0+C20 -> 0 | D26: =C26+D20 -> 0 | E26: =D26+E20 -> 0 | F26: =E26+F20 -> 121.1265 | G26: =F26+G20 -> 460.05282
A27: Partner Rental 평균 가동 | B27: 대 | C27: =0+C20/2 -> 0 | D27: =C26+D20/2 -> 0 | E27: =D26+E20/2 -> 0 | F27: =E26+F20/2 -> 60.56325 | G27: =F26+G20/2 -> 290.58966
A28: Installed Robot (기말) | B28: 대 | C28: =C22+C24+C26 -> 0 | D28: =D22+D24+D26 -> 3 | E28: =E22+E24+E26 -> 58.25 | F28: =F22+F24+F26 -> 327.42 | G28: =G22+G24+G26 -> 1080.5896
A29: 신축 계약 Backlog (미설치 세대) | B29: 세대 | C29: =Inputs_Yearly!$E$58*Inputs!$F$80*Inputs!$F$81 -> 0 | D29: =(Inputs_Yearly!$F$58+Inputs_Yearly!$E$58)*Inputs!$F$80*Inputs!$F$81 -> 0 | E29: =(Inputs_Yearly!$G$58+Inputs_Yearly!$F$58)*Inputs!$F$80*Inputs!$F$81 -> 192 | F29: =(Inputs_Yearly!$H$58+Inputs_Yearly!$G$58)*Inputs!$F$80*Inputs!$F$81 -> 480 | G29: =(Inputs_Yearly!$I$58+Inputs_Yearly!$H$58)*Inputs!$F$80*Inputs!$F$81 -> 672
A30: REVENUE (만원) — INSTALL / OPERATE / EXPAND
A31: 가격 실현율 | B31: % | C31: =Inputs_Yearly!$E$6 -> 1 | D31: =Inputs_Yearly!$F$6 -> 0.6 | E31: =Inputs_Yearly!$G$6 -> 1 | F31: =Inputs_Yearly!$H$6 -> 1 | G31: =Inputs_Yearly!$I$6 -> 1
A32: Consumables 연 List (구매 고객) | B32: 만원/대 | C32: =Inputs!$F$44*Inputs!$F$45+Inputs!$F$46*Inputs!$F$47+Inputs!$F$48*Inputs!$F$49 -> 36 | D32: =Inputs!$F$44*Inputs!$F$45+Inputs!$F$46*Inputs!$F$47+Inputs!$F$48*Inputs!$F$49 -> 36 | E32: =Inputs!$F$44*Inputs!$F$45+Inputs!$F$46*Inputs!$F$47+Inputs!$F$48*Inputs!$F$49 -> 36 | F32: =Inputs!$F$44*Inputs!$F$45+Inputs!$F$46*Inputs!$F$47+Inputs!$F$48*Inputs!$F$49 -> 36 | G32: =Inputs!$F$44*Inputs!$F$45+Inputs!$F$46*Inputs!$F$47+Inputs!$F$48*Inputs!$F$49 -> 36
A33: Consumables 연 List (Rental, Grip 제외) | B33: 만원/대 | C33: =Inputs!$F$46*Inputs!$F$47+Inputs!$F$48*Inputs!$F$49 -> 18 | D33: =Inputs!$F$46*Inputs!$F$47+Inputs!$F$48*Inputs!$F$49 -> 18 | E33: =Inputs!$F$46*Inputs!$F$47+Inputs!$F$48*Inputs!$F$49 -> 18 | F33: =Inputs!$F$46*Inputs!$F$47+Inputs!$F$48*Inputs!$F$49 -> 18 | G33: =Inputs!$F$46*Inputs!$F$47+Inputs!$F$48*Inputs!$F$49 -> 18
A34: Grip Kit 연 List | B34: 만원/대 | C34: =Inputs!$F$44*Inputs!$F$45 -> 18 | D34: =Inputs!$F$44*Inputs!$F$45 -> 18 | E34: =Inputs!$F$44*Inputs!$F$45 -> 18 | F34: =Inputs!$F$44*Inputs!$F$45 -> 18 | G34: =Inputs!$F$44*Inputs!$F$45 -> 18
A35: INSTALL. Interface · Integration | B35: 만원 | C35: =(C5+C6)*Inputs!$F$34*C31+C8*Inputs!$F$35+C7*Inputs!$F$36*C31 -> 0 | D35: =(D5+D6)*Inputs!$F$34*D31+D8*Inputs!$F$35+D7*Inputs!$F$36*D31 -> 810 | E35: =(E5+E6)*Inputs!$F$34*E31+E8*Inputs!$F$35+E7*Inputs!$F$36*E31 -> 29250 | F35: =(F5+F6)*Inputs!$F$34*F31+F8*Inputs!$F$35+F7*Inputs!$F$36*F31 -> 130500 | G35: =(G5+G6)*Inputs!$F$34*G31+G8*Inputs!$F$35+G7*Inputs!$F$36*G31 -> 361740 | H35: =SUM(C35:G35) -> 522300
A36: INSTALL. Installation · Calibration | B36: 만원 | C36: =(C14-C7)*Inputs!$F$38*C31+C7*Inputs!$F$39*C31 -> 0 | D36: =(D14-D7)*Inputs!$F$38*D31+D7*Inputs!$F$39*D31 -> 144 | E36: =(E14-E7)*Inputs!$F$38*E31+E7*Inputs!$F$39*E31 -> 4420 | F36: =(F14-F7)*Inputs!$F$38*F31+F7*Inputs!$F$39*F31 -> 22733.6 | G36: =(G14-G7)*Inputs!$F$38*G31+G7*Inputs!$F$39*G31 -> 65053.568 | H36: =SUM(C36:G36) -> 92351.168
A37: INSTALL. Robot System (구매 + Rental Partner 공급) | B37: 만원 | C37: =C18*Inputs!$F$37*C31+C20*Inputs!$F$37*Inputs!$F$56 -> 0 | D37: =D18*Inputs!$F$37*D31+D20*Inputs!$F$37*Inputs!$F$56 -> 1877.4 | E37: =E18*Inputs!$F$37*E31+E20*Inputs!$F$37*Inputs!$F$56 -> 57625.75 | F37: =F18*Inputs!$F$37*F31+F20*Inputs!$F$37*Inputs!$F$56 -> 379405.88 | G37: =G18*Inputs!$F$37*G31+G20*Inputs!$F$37*Inputs!$F$56 -> 1061622.7 | H37: =SUM(C37:G37) -> 1500531.7
A38: OPERATE. Rental (MH 보유) | B38: 만원 | C38: =C25*Inputs!$F$40*12 -> 0 | D38: =D25*Inputs!$F$40*12 -> 178.2 | E38: =E25*Inputs!$F$40*12 -> 3638.25 | F38: =F25*Inputs!$F$40*12 -> 6920.1 | G38: =G25*Inputs!$F$40*12 -> 6920.1 | H38: =SUM(C38:G38) -> 17656.65
A39: OPERATE. Care (구매 고객 + Partner 서비스료) | B39: 만원 | C39: =C23*Inputs!$F$51*Inputs!$F$42+C27*Inputs!$F$57*12 -> 0 | D39: =D23*Inputs!$F$51*Inputs!$F$42+D27*Inputs!$F$57*12 -> 35.28 | E39: =E23*Inputs!$F$51*Inputs!$F$42+E27*Inputs!$F$57*12 -> 720.3 | F39: =F23*Inputs!$F$51*Inputs!$F$42+F27*Inputs!$F$57*12 -> 8217.7248 | G39: =G23*Inputs!$F$51*Inputs!$F$42+G27*Inputs!$F$57*12 -> 34226.044 | H39: =SUM(C39:G39) -> 43199.349
A40: OPERATE. Consumables | B40: 만원 | C40: =C23*Inputs!$F$50*C32+(C25+C27)*Inputs!$F$50*C33 -> 0 | D40: =D23*Inputs!$F$50*D32+(D25+D27)*Inputs!$F$50*D33 -> 32.13 | E40: =E23*Inputs!$F$50*E32+(E25+E27)*Inputs!$F$50*E33 -> 655.9875 | F40: =F23*Inputs!$F$50*F32+(F25+F27)*Inputs!$F$50*F33 -> 3876.16 | G40: =G23*Inputs!$F$50*G32+(G25+G27)*Inputs!$F$50*G33 -> 13859.306 | H40: =SUM(C40:G40) -> 18423.584
...

Sheet Household
A1: Household Economics — 대표 1세대, 5년, Base (만원)
A2: 기대값 기준 (Skill · Tool은 구매율 반영). 구매 모델은 Care 가입 세대 기준. Y3 / Y5 = 해당 연도의 원가 수준을 5년간 적용. Remodeling = 직접판매 (획득비용), Retrofit = Partner 경유 (수수료), New-build = Project 수주비용 ÷ Option 세대.
A4: 항목 | B4: Remodeling 구매 · Y3 | C4: Remodeling 구매 · Y5 | D4: Remodeling Rental · Y3 | E4: Remodeling Rental · Y5 | F4: Retrofit 구매 · Y3 | G4: New-build 구매 · Y3 | H4: 산식
A5: REVENUE
A6: INSTALL · Interface · Integration | B6: =Inputs!$E$34 -> 450 | C6: =Inputs!$E$34 -> 450 | D6: =Inputs!$E$34 -> 450 | E6: =Inputs!$E$34 -> 450 | F6: =Inputs!$E$36 -> 150 | G6: =Inputs!$E$35 -> 220
A7: INSTALL · Installation · Calibration | B7: =Inputs!$E$38 -> 80 | C7: =Inputs!$E$38 -> 80 | D7: =Inputs!$E$38 -> 80 | E7: =Inputs!$E$38 -> 80 | F7: =Inputs!$E$39 -> 120 | G7: =Inputs!$E$38 -> 80
A8: INSTALL · Robot System (구매) | B8: =Inputs!$E$37 -> 1490 | C8: =Inputs!$E$37 -> 1490 | D8: =0 -> 0 | E8: =0 -> 0 | F8: =Inputs!$E$37 -> 1490 | G8: =Inputs!$E$37 -> 1490
A9: OPERATE · Rental (60개월) | B9: =0 -> 0 | C9: =0 -> 0 | D9: =Inputs!$E$40*Inputs!$E$41 -> 1980 | E9: =Inputs!$E$40*Inputs!$E$41 -> 1980 | F9: =0 -> 0 | G9: =0 -> 0
A10: OPERATE · Care Basic (5년) | B10: =5*Inputs!$E$42 -> 240 | C10: =5*Inputs!$E$42 -> 240 | D10: =0 -> 0 | E10: =0 -> 0 | F10: =5*Inputs!$E$42 -> 240 | G10: =5*Inputs!$E$42 -> 240
A11: OPERATE · Consumables (5년, 구매율 반영) | B11: =5*Inputs!$E$50*(Inputs!$E$44*Inputs!$E$45+Inputs!$E$46*Inputs!$E$47+Inputs!$E$48*Inputs!$E$49) -> 126 | C11: =5*Inputs!$E$50*(Inputs!$E$44*Inputs!$E$45+Inputs!$E$46*Inputs!$E$47+Inputs!$E$48*Inputs!$E$49) -> 126 | D11: =5*Inputs!$E$50*(Inputs!$E$46*Inputs!$E$47+Inputs!$E$48*Inputs!$E$49) -> 63 | E11: =5*Inputs!$E$50*(Inputs!$E$46*Inputs!$E$47+Inputs!$E$48*Inputs!$E$49) -> 63 | F11: =5*Inputs!$E$50*(Inputs!$E$44*Inputs!$E$45+Inputs!$E$46*Inputs!$E$47+Inputs!$E$48*Inputs!$E$49) -> 126 | G11: =5*Inputs!$E$50*(Inputs!$E$44*Inputs!$E$45+Inputs!$E$46*Inputs!$E$47+Inputs!$E$48*Inputs!$E$49) -> 126
A12: EXPAND · ASSIST Skill (기대값) | B12: =Inputs!$E$53*Inputs!$E$52 -> 12 | C12: =Inputs!$E$53*Inputs!$E$52 -> 12 | D12: =Inputs!$E$53*Inputs!$E$52 -> 12 | E12: =Inputs!$E$53*Inputs!$E$52 -> 12 | F12: =Inputs!$E$53*Inputs!$E$52 -> 12 | G12: =Inputs!$E$53*Inputs!$E$52 -> 12
A13: EXPAND · Tool / End-effector (기대값) | B13: =Inputs!$E$55*Inputs!$E$54 -> 20 | C13: =Inputs!$E$55*Inputs!$E$54 -> 20 | D13: =Inputs!$E$55*Inputs!$E$54 -> 20 | E13: =Inputs!$E$55*Inputs!$E$54 -> 20 | F13: =Inputs!$E$55*Inputs!$E$54 -> 20 | G13: =Inputs!$E$55*Inputs!$E$54 -> 20
A14: 5년 매출 | B14: =B6+B7+B8+B9+B10+B11+B12+B13 -> 2418 | C14: =C6+C7+C8+C9+C10+C11+C12+C13 -> 2418 | D14: =D6+D7+D8+D9+D10+D11+D12+D13 -> 2605 | E14: =E6+E7+E8+E9+E10+E11+E12+E13 -> 2605 | F14: =F6+F7+F8+F9+F10+F11+F12+F13 -> 2158 | G14: =G6+G7+G8+G9+G10+G11+G12+G13 -> 2188
A15: COST
A16: Interface 원가 | B16: =Inputs!$E$59*(Inputs_Yearly!$G$9+Inputs!$E$60*(1-Inputs_Yearly!$G$9))+Inputs!$E$61*(1-Inputs_Yearly!$G$9) -> 277 | C16: =Inputs!$E$59*(Inputs_Yearly!$I$9+Inputs!$E$60*(1-Inputs_Yearly!$I$9))+Inputs!$E$61*(1-Inputs_Yearly!$I$9) -> 244 | D16: =Inputs!$E$59*(Inputs_Yearly!$G$9+Inputs!$E$60*(1-Inputs_Yearly!$G$9))+Inputs!$E$61*(1-Inputs_Yearly!$G$9) -> 277 | E16: =Inputs!$E$59*(Inputs_Yearly!$I$9+Inputs!$E$60*(1-Inputs_Yearly!$I$9))+Inputs!$E$61*(1-Inputs_Yearly!$I$9) -> 244 | F16: =Inputs!$E$63 -> 70 | G16: =Inputs!$E$62 -> 130
A17: Installation · Calibration 원가 | B17: =Inputs_Yearly!$G$17 -> 60 | C17: =Inputs_Yearly!$I$17 -> 38 | D17: =Inputs_Yearly!$G$17 -> 60 | E17: =Inputs_Yearly!$I$17 -> 38 | F17: =Inputs_Yearly!$G$21 -> 95 | G17: =Inputs_Yearly!$G$17 -> 60
A18: 물류 | B18: =Inputs!$E$64 -> 25 | C18: =Inputs!$E$64 -> 25 | D18: =Inputs!$E$64 -> 25 | E18: =Inputs!$E$64 -> 25 | F18: =Inputs!$E$64 -> 25 | G18: =Inputs!$E$64 -> 25
A19: Robot BOM (Rental은 잔존가치 차감) | B19: =Inputs_Yearly!$G$13 -> 1180 | C19: =Inputs_Yearly!$I$13 -> 915 | D19: =Inputs_Yearly!$G$13*(1-Inputs!$E$75) -> 1003 | E19: =Inputs_Yearly!$I$13*(1-Inputs!$E$75) -> 777.75 | F19: =Inputs_Yearly!$G$13 -> 1180 | G19: =Inputs_Yearly!$G$13 -> 1180
A20: Rental 금융비용 (5년) | B20: =0 -> 0 | C20: =0 -> 0 | D20: =Inputs_Yearly!$G$13*(1+Inputs!$E$75)/2*Inputs!$E$76*5 -> 271.4 | E20: =Inputs_Yearly!$I$13*(1+Inputs!$E$75)/2*Inputs!$E$76*5 -> 210.45 | F20: =0 -> 0 | G20: =0 -> 0
A21: Warranty Reserve | B21: =Inputs!$E$65*Inputs!$E$37 -> 59.6 | C21: =Inputs!$E$65*Inputs!$E$37 -> 59.6 | D21: =Inputs!$E$65*Inputs_Yearly!$G$13 -> 47.2 | E21: =Inputs!$E$65*Inputs_Yearly!$I$13 -> 36.6 | F21: =Inputs!$E$65*Inputs!$E$37 -> 59.6 | G21: =Inputs!$E$65*Inputs!$E$37 -> 59.6
A22: Care Service 원가 (5년) | B22: =5*(Inputs_Yearly!$G$25*Inputs_Yearly!$G$29+Inputs!$E$66*Inputs!$E$67+Inputs!$E$68) -> 184 | C22: =5*(Inputs_Yearly!$I$25*Inputs_Yearly!$I$29+Inputs!$E$66*Inputs!$E$67+Inputs!$E$68) -> 134 | D22: =5*(Inputs_Yearly!$G$25*Inputs_Yearly!$G$29+Inputs!$E$66*Inputs!$E$67+Inputs!$E$68) -> 184 | E22: =5*(Inputs_Yearly!$I$25*Inputs_Yearly!$I$29+Inputs!$E$66*Inputs!$E$67+Inputs!$E$68) -> 134 | F22: =5*(Inputs_Yearly!$G$25*Inputs_Yearly!$G$29+Inputs!$E$66*Inputs!$E$67+Inputs!$E$68) -> 184 | G22: =5*(Inputs_Yearly!$G$25*Inputs_Yearly!$G$29+Inputs!$E$66*Inputs!$E$67+Inputs!$E$68) -> 184
A23: Consumables 원가 | B23: =B11*Inputs!$E$69 -> 44.1 | C23: =C11*Inputs!$E$69 -> 44.1 | D23: =(D11+5*Inputs!$E$44*Inputs!$E$45)*Inputs!$E$69 -> 53.55 | E23: =(E11+5*Inputs!$E$44*Inputs!$E$45)*Inputs!$E$69 -> 53.55 | F23: =F11*Inputs!$E$69 -> 44.1 | G23: =G11*Inputs!$E$69 -> 44.1
A24: Skill · Tool 원가 | B24: =Inputs!$E$53*Inputs!$E$52*Inputs!$E$70+Inputs!$E$55*Inputs!$E$54*Inputs!$E$71 -> 10.2 | C24: =Inputs!$E$53*Inputs!$E$52*Inputs!$E$70+Inputs!$E$55*Inputs!$E$54*Inputs!$E$71 -> 10.2 | D24: =Inputs!$E$53*Inputs!$E$52*Inputs!$E$70+Inputs!$E$55*Inputs!$E$54*Inputs!$E$71 -> 10.2 | E24: =Inputs!$E$53*Inputs!$E$52*Inputs!$E$70+Inputs!$E$55*Inputs!$E$54*Inputs!$E$71 -> 10.2 | F24: =Inputs!$E$53*Inputs!$E$52*Inputs!$E$70+Inputs!$E$55*Inputs!$E$54*Inputs!$E$71 -> 10.2 | G24: =Inputs!$E$53*Inputs!$E$52*Inputs!$E$70+Inputs!$E$55*Inputs!$E$54*Inputs!$E$71 -> 10.2
A25: 채널비용 (획득비용 · Partner 수수료 · 수주비용) | B25: =Inputs!$E$73 -> 150 | C25: =Inputs!$E$73 -> 150 | D25: =Inputs!$E$73 -> 150 | E25: =Inputs!$E$73 -> 150 | F25: =Inputs!$E$72*(Inputs!$E$36+Inputs!$E$37+Inputs!$E$39) -> 176 | G25: =Inputs!$E$74/(Inputs!$E$80*Inputs!$E$81) -> 25
A26: 5년 비용 | B26: =B16+B17+B18+B19+B20+B21+B22+B23+B24+B25 -> 1989.9 | C26: =C16+C17+C18+C19+C20+C21+C22+C23+C24+C25 -> 1619.9 | D26: =D16+D17+D18+D19+D20+D21+D22+D23+D24+D25 -> 2081.35 | E26: =E16+E17+E18+E19+E20+E21+E22+E23+E24+E25 -> 1679.55 | F26: =F16+F17+F18+F19+F20+F21+F22+F23+F24+F25 -> 1843.9 | G26: =G16+G17+G18+G19+G20+G21+G22+G23+G24+G25 -> 1717.9
A27: RESULT
A28: Year 0 매출 (INSTALL) | B28: =B6+B7+B8 -> 2020 | C28: =C6+C7+C8 -> 2020 | D28: =D6+D7+D8 -> 530 | E28: =E6+E7+E8 -> 530 | F28: =F6+F7+F8 -> 1760 | G28: =G6+G7+G8 -> 1790
A29: OPERATE 매출 (5년) | B29: =B9+B10+B11 -> 366 | C29: =C9+C10+C11 -> 366 | D29: =D9+D10+D11 -> 2043 | E29: =E9+E10+E11 -> 2043 | F29: =F9+F10+F11 -> 366 | G29: =G9+G10+G11 -> 366
A30: EXPAND 매출 (5년) | B30: =B12+B13 -> 32 | C30: =C12+C13 -> 32 | D30: =D12+D13 -> 32 | E30: =E12+E13 -> 32 | F30: =F12+F13 -> 32 | G30: =G12+G13 -> 32
A31: 5년 매출총이익 (채널비용 전) | B31: =B14-(B26-B25) -> 578.1 | C31: =C14-(C26-C25) -> 948.1 | D31: =D14-(D26-D25) -> 673.65 | E31: =E14-(E26-E25) -> 1075.45 | F31: =F14-(F26-F25) -> 490.1 | G31: =G14-(G26-G25) -> 495.1
A32: 5년 Lifetime Contribution | B32: =B14-B26 -> 428.1 | C32: =C14-C26 -> 798.1 | D32: =D14-D26 -> 523.65 | E32: =E14-E26 -> 925.45 | F32: =F14-F26 -> 314.1 | G32: =G14-G26 -> 470.1
A33: Contribution Margin | B33: =IF(B14=0,0,B32/B14) -> 0.17704715 | C33: =IF(C14=0,0,C32/C14) -> 0.33006617 | D33: =IF(D14=0,0,D32/D14) -> 0.20101727 | E33: =IF(E14=0,0,E32/E14) -> 0.35525912 | F33: =IF(F14=0,0,F32/F14) -> 0.14555144 | G33: =IF(G14=0,0,G32/G14) -> 0.21485375
A34: 5년 서비스 원가 (Care · Consumables · Warranty) | B34: =B22+B23+B21 -> 287.7 | C34: =C22+C23+C21 -> 237.7 | D34: =D22+D23+D21 -> 284.75 | E34: =E22+E23+E21 -> 224.15 | F34: =F22+F23+F21 -> 287.7 | G34: =G22+G23+G21 -> 287.7

Sheet Unit_Economics
A1: Unit Economics — Base (만원)
A3: Rental 월 원가 Build-up (Robot 1대, MH 보유 가정) | B3: Y3 원가 | C3: Y5 원가 | D3: 산식
A4: Robot BOM | B4: =Inputs_Yearly!$G$13 -> 1180 | C4: =Inputs_Yearly!$I$13 -> 915
A5: 감가 (잔존가치 차감, 60개월) | B5: =B4*(1-Inputs!$E$75)/Inputs!$E$41 -> 16.716667 | C5: =C4*(1-Inputs!$E$75)/Inputs!$E$41 -> 12.9625
A6: 금융비용 (평균잔액 × 금리 / 12) | B6: =B4*(1+Inputs!$E$75)/2*Inputs!$E$76/12 -> 4.5233333 | C6: =C4*(1+Inputs!$E$75)/2*Inputs!$E$76/12 -> 3.5075
A7: Care 원가 / 12 | B7: =(Inputs_Yearly!$G$25*Inputs_Yearly!$G$29+Inputs!$E$66*Inputs!$E$67+Inputs!$E$68)/12 -> 3.0666667 | C7: =(Inputs_Yearly!$I$25*Inputs_Yearly!$I$29+Inputs!$E$66*Inputs!$E$67+Inputs!$E$68)/12 -> 2.2333333
A8: Grip Kit 원가 / 12 | B8: =Inputs!$E$44*Inputs!$E$45*Inputs!$E$69/12 -> 0.525 | C8: =Inputs!$E$44*Inputs!$E$45*Inputs!$E$69/12 -> 0.525
A9: Failure Reserve | B9: =Inputs!$E$65*B4/Inputs!$E$41 -> 0.78666667 | C9: =Inputs!$E$65*C4/Inputs!$E$41 -> 0.61
A10: 월 원가 합계 | B10: =B5+B6+B7+B8+B9 -> 25.618333 | C10: =C5+C6+C7+C8+C9 -> 19.838333
A11: 월 Rental 요금 (가정) | B11: =Inputs!$E$40 -> 33 | C11: =Inputs!$E$40 -> 33
A12: 월 Contribution | B12: =B11-B10 -> 7.3816667 | C12: =C11-C10 -> 13.161667
A13: Contribution Margin | B13: =B12/B11 -> 0.22368687 | C13: =C12/C11 -> 0.39883838
A14: 마진 20% 확보 요금 | B14: =B10/0.8 -> 32.022917 | C14: =C10/0.8 -> 24.797917
A15: Payback (BOM ÷ (요금 − Care − Grip), 개월) | B15: =B4/(B11-B7-B8) -> 40.124681 | C15: =C4/(C11-C7-C8) -> 30.256269 | D15: 금융비용 제외 현금 회수
A16: Payback 허들 충족 최대 BOM | B16: =Inputs!$E$77*(B11-B7-B8) -> 1058.7 | C16: =Inputs!$E$77*(C11-C7-C8) -> 1088.7 | D16: Rental Partner 요구 Payback 기준
A18: Care Basic (Robot 1대·년) | B18: Y3 원가 | C18: Y5 원가 | D18: 산식
A19: Care 연 요금 | B19: =Inputs!$E$42 -> 48 | C19: =Inputs!$E$42 -> 48
A20: 정기 방문 원가 | B20: =Inputs_Yearly!$G$25*Inputs_Yearly!$G$29 -> 22 | C20: =Inputs_Yearly!$I$25*Inputs_Yearly!$I$29 -> 12
A21: 고장 방문 원가 | B21: =Inputs!$E$66*Inputs!$E$67 -> 10.8 | C21: =Inputs!$E$66*Inputs!$E$67 -> 10.8
A22: Cloud·Software | B22: =Inputs!$E$68 -> 4 | C22: =Inputs!$E$68 -> 4
A23: Care 원가 합계 | B23: =SUM(B20:B22) -> 36.8 | C23: =SUM(C20:C22) -> 26.8
A24: Care Contribution | B24: =B19-B23 -> 11.2 | C24: =C19-C23 -> 21.2
A25: Care Margin | B25: =B24/B19 -> 0.23333333 | C25: =C24/C19 -> 0.44166667
A27: Consumables (Robot 1대·년, 구매 고객) | B27: 연 매출 | C27: 원가 | D27: Contribution
A28: Grip Kit (List × 구매율) | B28: =Inputs!$E$44*Inputs!$E$45*Inputs!$E$50 -> 12.6 | C28: =B28*Inputs!$E$69 -> 4.41 | D28: =B28-C28 -> 8.19
A29: Cleaning Kit (List × 구매율) | B29: =Inputs!$E$46*Inputs!$E$47*Inputs!$E$50 -> 7 | C29: =B29*Inputs!$E$69 -> 2.45 | D29: =B29-C29 -> 4.55
A30: Protection Kit (List × 구매율) | B30: =Inputs!$E$48*Inputs!$E$49*Inputs!$E$50 -> 5.6 | C30: =B30*Inputs!$E$69 -> 1.96 | D30: =B30-C30 -> 3.64
A31: 합계 | B31: =SUM(B28:B30) -> 25.2 | C31: =SUM(C28:C30) -> 8.82 | D31: =SUM(D28:D30) -> 16.38
A33: Rental Partner 경제성 (Base, Y4~) | B33: 값 | D33: 산식
A34: Robot 매입가 (ASP × 공급가율) | B34: =Inputs!$E$37*Inputs!$E$56 -> 1311.2
A35: 월 순유입 (요금 − MH 서비스료) | B35: =Inputs!$E$40-Inputs!$E$57 -> 27
A36: 잔존가치 (매입가 × 잔존율) | B36: =B34*Inputs!$E$75 -> 196.68
A37: 월 IRR | B37: =RATE(Inputs!$E$41,B35,-B34,B36) -> 0.010276112 | D37: RATE(기간, 월 유입, −매입가, 잔존가치)
A38: 연 IRR (연체·해지 미반영) | B38: =(1+B37)^12-1 -> 0.13052719
