Workbook

Sheet README
B1: ARKI Robotics — TIPS IR Financial Model (Draft v4, 2026-10)
B3: 목적: TIPS IR 덱의 모든 사업 수치를 하나의 수식 모델로 관리. 단위는 별도 표기가 없으면 만원 (KRW 10,000). 억원 = 만원 / 10,000.
B4: 주의: 실적·계약·고객·Partner 데이터 없음. 모든 수치는 FACT / DERIVED / ASSUMPTION / TARGET Tag로 구분.
B6: Color code
B7: 파란 글자 = 입력값 (Inputs, Inputs_Yearly에서만 수정) · 검은 글자 = 수식 · 녹색 글자 = 다른 Sheet 참조 · 노란 바탕 = 핵심 가정 (WTP·BOM·Volume)
B8: Tag
B9: FACT = 공식 통계·공개자료 확인값 · DERIVED = FACT 기반 계산값 · ASSUMPTION = 현재 사업가설 · TARGET = TIPS 과제 · 이후 목표
B10: Sheets
B11: Inputs: 단일값 가정 (시나리오별 Conservative / Base / Upside 열)
B12: Inputs_Yearly: 연도별 가정 (Volume, BOM, Standard Module 사용률, 인원 등)
B13: FM_Conservative / FM_Base / FM_Upside: 5개년 Bottom-up 손익 (각 Sheet가 해당 시나리오 열을 참조)
B14: Scenario_Summary: 3개 시나리오 요약 (억원)
... B23: 재현: python3 ARKI/source/model.py → python3 ARKI/source/xlsx_model.py (LibreOffice 재계산 후 model.py와 교차검증)

Sheet Scenario_Summary
A1: Scenario Summary (억원 · 세대 · 대)
A2: 각 셀은 FM Sheet 참조. 억원 = 만원 / 10,000. Upside는 가격 인상 없이 Partner·표준화·설치원가·Installed Base로 차이.
A4: Conservative | B4: 단위 | C4: Y1 | D4: Y2 | E4: Y3 | F4: Y4 | G4: Y5
A5: 매출 | B5: 억원 | C5: =FM_Conservative!$C$41/10000 -> 0 | D5: =FM_Conservative!$D$41/10000 -> 0.14508 | E5: =FM_Conservative!$E$41/10000 -> 3.609345 | F5: =FM_Conservative!$F$41/10000 -> 13.79455 | G5: =FM_Conservative!$G$41/10000 -> 27.786233
A6: 매출총이익 | B6: 억원 | C6: =FM_Conservative!$C$59/10000 -> 0 | D6: =FM_Conservative!$D$59/10000 -> -0.32554485 | E6: =FM_Conservative!$E$59/10000 -> 0.16499805 | F6: =FM_Conservative!$F$59/10000 -> 1.1136167 | G6: =FM_Conservative!$G$59/10000 -> 3.9891288
A7: 매출총이익률 | B7: % | C7: =FM_Conservative!$C$60 -> 0 | D7: =FM_Conservative!$D$60 -> -2.2438989 | E7: =FM_Conservative!$E$60 -> 0.045714125 | F7: =FM_Conservative!$F$60 -> 0.080728743 | G7: =FM_Conservative!$G$60 -> 0.14356494
A8: Contribution | B8: 억원 | C8: =FM_Conservative!$C$65/10000 -> 0 | D8: =FM_Conservative!$D$65/10000 -> -0.37954485 | E8: =FM_Conservative!$E$65/10000 -> -0.36630195 | F8: =FM_Conservative!$F$65/10000 -> -0.74418328 | G8: =FM_Conservative!$G$65/10000 -> 0.29962884
A9: Opex | B9: 억원 | C9: =FM_Conservative!$C$68/10000 -> 6.69 | D9: =FM_Conservative!$D$68/10000 -> 8.7 | E9: =FM_Conservative!$E$68/10000 -> 30.5 | F9: =FM_Conservative!$F$68/10000 -> 43.9 | G9: =FM_Conservative!$G$68/10000 -> 56.7
A10: 영업이익 (근사) | B10: 억원 | C10: =FM_Conservative!$C$69/10000 -> -6.69 | D10: =FM_Conservative!$D$69/10000 -> -9.0795448 | E10: =FM_Conservative!$E$69/10000 -> -30.866302 | F10: =FM_Conservative!$F$69/10000 -> -44.644183 | G10: =FM_Conservative!$G$69/10000 -> -56.400371
A11: 누적 현금흐름 | B11: 억원 | C11: =FM_Conservative!$C$71/10000 -> -6.69 | D11: =FM_Conservative!$D$71/10000 -> -15.89307 | E11: =FM_Conservative!$E$71/10000 -> -47.539334 | F11: =FM_Conservative!$F$71/10000 -> -92.011393 | G11: =FM_Conservative!$G$71/10000 -> -148.23964
A12: Kitchen 설치 | B12: 세대 | C12: =FM_Conservative!$C$8 -> 0 | D12: =FM_Conservative!$D$8 -> 3 | E12: =FM_Conservative!$E$8 -> 30 | F12: =FM_Conservative!$F$8 -> 95 | G12: =FM_Conservative!$G$8 -> 190
A13: Robot 설치 | B13: 대 | C13: =FM_Conservative!$C$13 -> 0 | D13: =FM_Conservative!$D$13 -> 3 | E13: =FM_Conservative!$E$13 -> 22.5 | F13: =FM_Conservative!$F$13 -> 71.625 | G13: =FM_Conservative!$G$13 -> 144.04375
A14: Installed Robot (기말) | B14: 대 | C14: =FM_Conservative!$C$27 -> 0 | D14: =FM_Conservative!$D$27 -> 3 | E14: =FM_Conservative!$E$27 -> 25.5 | F14: =FM_Conservative!$F$27 -> 97.125 | G14: =FM_Conservative!$G$27 -> 241.16875
A15: 신축 Backlog | B15: 세대 | C15: =FM_Conservative!$C$28 -> 0 | D15: =FM_Conservative!$D$28 -> 0 | E15: =FM_Conservative!$E$28 -> 0 | F15: =FM_Conservative!$F$28 -> 48 | G15: =FM_Conservative!$G$28 -> 144
A16: Robot + Recurring + Upgrade 비중 | B16: % | C16: =FM_Conservative!$C$75 -> 0 | D16: =FM_Conservative!$D$75 -> 0.70223325 | E16: =FM_Conservative!$E$75 -> 0.61765916 | F16: =FM_Conservative!$F$75 -> 0.68299076 | G16: =FM_Conservative!$G$75 -> 0.68501128
A18: Base | B18: 단위 | C18: Y1 | D18: Y2 | E18: Y3 | F18: Y4 | G18: Y5
A19: 매출 | B19: 억원 | C19: =FM_Base!$C$41/10000 -> 0 | D19: =FM_Base!$D$41/10000 -> 0.260511 | E19: =FM_Base!$E$41/10000 -> 7.4234195 | F19: =FM_Base!$F$41/10000 -> 32.472507 | G19: =FM_Base!$G$41/10000 -> 77.544078
A20: 매출총이익 | B20: 억원 | C20: =FM_Base!$C$59/10000 -> 0 | D20: =FM_Base!$D$59/10000 -> -0.19508235 | E20: =FM_Base!$E$59/10000 -> 1.8194202 | F20: =FM_Base!$F$59/10000 -> 9.8175725 | G20: =FM_Base!$G$59/10000 -> 27.872179
A21: 매출총이익률 | B21: % | C21: =FM_Base!$C$60 -> 0 | D21: =FM_Base!$D$60 -> -0.74884496 | E21: =FM_Base!$E$60 -> 0.24509192 | F21: =FM_Base!$F$60 -> 0.30233491 | G21: =FM_Base!$G$60 -> 0.35943659
A22: Contribution | B22: 억원 | C22: =FM_Base!$C$65/10000 -> 0 | D22: =FM_Base!$D$65/10000 -> -0.24008235 | E22: =FM_Base!$E$65/10000 -> 0.81252018 | F22: =FM_Base!$F$65/10000 -> 6.3477225 | G22: =FM_Base!$G$65/10000 -> 20.304879
A23: Opex | B23: 억원 | C23: =FM_Base!$C$68/10000 -> 6.69 | D23: =FM_Base!$D$68/10000 -> 8.7 | E23: =FM_Base!$E$68/10000 -> 30.5 | F23: =FM_Base!$F$68/10000 -> 43.9 | G23: =FM_Base!$G$68/10000 -> 56.7
A24: 영업이익 (근사) | B24: 억원 | C24: =FM_Base!$C$69/10000 -> -6.69 | D24: =FM_Base!$D$69/10000 -> -8.9400824 | E24: =FM_Base!$E$69/10000 -> -29.68748 | F24: =FM_Base!$F$69/10000 -> -37.552278 | G24: =FM_Base!$G$69/10000 -> -36.395121
A25: 누적 현금흐름 | B25: 억원 | C25: =FM_Base!$C$71/10000 -> -6.69 | D25: =FM_Base!$D$71/10000 -> -15.74949 | E25: =FM_Base!$E$71/10000 -> -46.756403 | F25: =FM_Base!$F$71/10000 -> -84.037233 | G25: =FM_Base!$G$71/10000 -> -120.16091
A26: Kitchen 설치 | B26: 세대 | C26: =FM_Base!$C$8 -> 0 | D26: =FM_Base!$D$8 -> 3 | E26: =FM_Base!$E$8 -> 50 | F26: =FM_Base!$F$8 -> 180 | G26: =FM_Base!$G$8 -> 480
A27: Robot 설치 | B27: 대 | C27: =FM_Base!$C$13 -> 0 | D27: =FM_Base!$D$13 -> 3 | E27: =FM_Base!$E$13 -> 42.5 | F27: =FM_Base!$F$13 -> 153.75 | G27: =FM_Base!$G$13 -> 363.375
A28: Installed Robot (기말) | B28: 대 | C28: =FM_Base!$C$27 -> 0 | D28: =FM_Base!$D$27 -> 3 | E28: =FM_Base!$E$27 -> 45.5 | F28: =FM_Base!$F$27 -> 199.25 | G28: =FM_Base!$G$27 -> 562.625
A29: 신축 Backlog | B29: 세대 | C29: =FM_Base!$C$28 -> 0 | D29: =FM_Base!$D$28 -> 0 | E29: =FM_Base!$E$28 -> 80 | F29: =FM_Base!$F$28 -> 240 | G29: =FM_Base!$G$28 -> 400
A30: Robot + Recurring + Upgrade 비중 | B30: % | C30: =FM_Base!$C$75 -> 0 | D30: =FM_Base!$D$75 -> 0.69483054 | E30: =FM_Base!$E$75 -> 0.65110418 | F30: =FM_Base!$F$75 -> 0.71268002 | G30: =FM_Base!$G$75 -> 0.70768883
A32: Upside | B32: 단위 | C32: Y1 | D32: Y2 | E32: Y3 | F32: Y4 | G32: Y5
A33: 매출 | B33: 억원 | C33: =FM_Upside!$C$41/10000 -> 0 | D33: =FM_Upside!$D$41/10000 -> 0.307701 | E33: =FM_Upside!$E$41/10000 -> 9.6346287 | F33: =FM_Upside!$F$41/10000 -> 50.093412 | G33: =FM_Upside!$G$41/10000 -> 133.9515
A34: 매출총이익 | B34: 억원 | C34: =FM_Upside!$C$59/10000 -> 0 | D34: =FM_Upside!$D$59/10000 -> -0.13195176 | E34: =FM_Upside!$E$59/10000 -> 2.809274 | F34: =FM_Upside!$F$59/10000 -> 17.648547 | G34: =FM_Upside!$G$59/10000 -> 56.239078
A35: 매출총이익률 | B35: % | C35: =FM_Upside!$C$60 -> 0 | D35: =FM_Upside!$D$60 -> -0.42883111 | E35: =FM_Upside!$E$60 -> 0.29158093 | F35: =FM_Upside!$F$60 -> 0.35231273 | G35: =FM_Upside!$G$60 -> 0.41984656
A36: Contribution | B36: 억원 | C36: =FM_Upside!$C$65/10000 -> 0 | D36: =FM_Upside!$D$65/10000 -> -0.17395176 | E36: =FM_Upside!$E$65/10000 -> 1.437459 | F36: =FM_Upside!$F$65/10000 -> 12.675237 | G36: =FM_Upside!$G$65/10000 -> 44.822778
A37: Opex | B37: 억원 | C37: =FM_Upside!$C$68/10000 -> 6.69 | D37: =FM_Upside!$D$68/10000 -> 8.7 | E37: =FM_Upside!$E$68/10000 -> 30.5 | F37: =FM_Upside!$F$68/10000 -> 43.9 | G37: =FM_Upside!$G$68/10000 -> 56.7
A38: 영업이익 (근사) | B38: 억원 | C38: =FM_Upside!$C$69/10000 -> -6.69 | D38: =FM_Upside!$D$69/10000 -> -8.8739518 | E38: =FM_Upside!$E$69/10000 -> -29.062541 | F38: =FM_Upside!$F$69/10000 -> -31.224763 | G38: =FM_Upside!$G$69/10000 -> -11.877222
A39: 누적 현금흐름 | B39: 억원 | C39: =FM_Upside!$C$71/10000 -> -6.69 | D39: =FM_Upside!$D$71/10000 -> -15.679242 | E39: =FM_Upside!$E$71/10000 -> -46.358304 | F39: =FM_Upside!$F$71/10000 -> -77.257331 | G39: =FM_Upside!$G$71/10000 -> -88.808816
A40: Kitchen 설치 | B40: 세대 | C40: =FM_Upside!$C$8 -> 0 | D40: =FM_Upside!$D$8 -> 3 | E40: =FM_Upside!$E$8 -> 65 | F40: =FM_Upside!$F$8 -> 280 | G40: =FM_Upside!$G$8 -> 862
A41: Robot 설치 | B41: 대 | C41: =FM_Upside!$C$13 -> 0 | D41: =FM_Upside!$D$13 -> 3 | E41: =FM_Upside!$E$13 -> 55.25 | F41: =FM_Upside!$F$13 -> 239.17 | G41: =FM_Upside!$G$13 -> 633.1696
A42: Installed Robot (기말) | B42: 대 | C42: =FM_Upside!$C$27 -> 0 | D42: =FM_Upside!$D$27 -> 3 | E42: =FM_Upside!$E$27 -> 58.25 | F42: =FM_Upside!$F$27 -> 297.42 | G42: =FM_Upside!$G$27 -> 930.5896
A43: 신축 Backlog | B43: 세대 | C43: =FM_Upside!$C$28 -> 0 | D43: =FM_Upside!$D$28 -> 0 | E43: =FM_Upside!$E$28 -> 192 | F43: =FM_Upside!$F$28 -> 480 | G43: =FM_Upside!$G$28 -> 672
...

Sheet Inputs
A1: Inputs — 단일값 가정 (만원 기준)
A3: Key | B3: 항목 | C3: 단위 | D3: Conservative | E3: Base | F3: Upside | G3: Tag | H3: Source / Note
A4: MARKET
A5: m_housing_total | B5: 총주택 (2025.11.1 기준) | C5: 천호 | D5: 20181 | E5: 20181 | F5: 20181 | G5: FACT | H5: 국가데이터처, 2025 인구주택총조사 등록센서스 결과 (2026.7.28 발표)
A6: m_apt_share | B6: 아파트 비중 (총주택 대비) | C6: % | D6: 0.658 | E6: 0.658 | F6: 0.658 | G6: FACT | H6: 국가데이터처, 2025 인구주택총조사
A7: m_house_20y_share | B7: 준공 20년 이상 주택 비중 | C7: % | D7: 0.56 | E7: 0.56 | F7: 0.56 | G7: FACT | H7: 국가데이터처, 2025 인구주택총조사
A8: m_house_30y_share | B8: 준공 30년 이상 주택 비중 | C8: % | D8: 0.306 | E8: 0.306 | F8: 0.306 | G8: FACT | H8: 국가데이터처, 2025 인구주택총조사
A9: m_apt_2023 | B9: 아파트 수 (2023) | C9: 천호 | D9: 12630 | E9: 12630 | F9: 12630 | G9: FACT | H9: 통계청, 2023 주택총조사 (보도 인용)
A10: m_apt_20y_2023 | B10: 준공 20년 이상 아파트 (2023) | C10: 천호 | D10: 6390 | E10: 6390 | F10: 6390 | G10: FACT | H10: 통계청, 2023 주택총조사 (보도 인용)
A11: m_txn_2025 | B11: 주택 매매거래 (2025, 전체 주택) | C11: 천호 | D11: 726 | E11: 726 | F11: 726 | G11: FACT | H11: KB주택시장리뷰 2026.2 (한국부동산원 자료)
A12: m_completion_2025 | B12: 주택 준공 (2025 연간, 전체 주택) | C12: 천호 | D12: 342.4 | E12: 342.4 | F12: 342.4 | G12: FACT | H12: 국토교통부, 2025년 12월 주택통계
A13: m_movein_2025 | B13: 아파트 입주 (2025) | C13: 천호 | D13: 236.3 | E13: 236.3 | F13: 236.3 | G13: FACT | H13: 부동산114 REPS
A14: m_movein_2026e | B14: 아파트 입주 예정 (2026) | C14: 천호 | D14: 183.1 | E14: 183.1 | F14: 183.1 | G14: FACT | H14: 부동산114 REPS (예정 물량)
A15: a_replace_cycle | B15: Kitchen 교체주기 (노후 아파트) | C15: 년 | D15: 22 | E15: 22 | F15: 22 | G15: ASSUMPTION | H15: 교차검증용 가정. Seed 기간 견적·인터뷰로 검증
A16: a_txn_apt_share | B16: 매매거래 중 아파트 비중 | C16: % | D16: 0.7 | E16: 0.7 | F16: 0.7 | G16: ASSUMPTION | H16: 부동산원 월별 아파트 거래 비중 확인 필요
... A23: a_premium_project | B23: Premium 단지 비중 (신축) | C23: % | D23: 0.15 | E23: 0.15 | F23: 0.15 | G23: ASSUMPTION | H23: 브랜드·분양가 기준 정의 필요
A24: VALUE
A25: f_helper_rate | B25: 가사서비스 시간당 요금 (플랫폼 4시간 59,900~64,900원) | C25: 만원/h | D25: 1.5 | E25: 1.5 | F25: 1.5 | G25: FACT | H25: 가사서비스 플랫폼 공개 요금 (2025, 보도·앱 정보)
A26: a_cleanup_min | B26: Clean-up 시간 (식사 후 정리, 일) | C26: 분/일 | D26: 40 | E26: 40 | F26: 40 | G26: ASSUMPTION | H26: Time-diary(n=30)로 검증
A27: a_auto_share | B27: V1 자동화 가능 비중 | C27: % | D27: 0.6 | E27: 0.6 | F27: 0.6 | G27: ASSUMPTION | H27: 식기 이동·식세기·수납만. 행주·싱크 세척 제외
A28: fx | B28: 환율 (Benchmark 환산용) | C28: 원/USD | D28: 1400 | E28: 1400 | F28: 1400 | G28: ASSUMPTION | H28: 부품 Benchmark 환산 전용
A29: PRICE
A30: p_rr | B30: Robot-ready Kitchen 증분가 (구축) | C30: 만원/세대 | D30: 400 | E30: 450 | F30: 450 | G30: ASSUMPTION | H30: 기존 Kitchen 공사비 위 증분. 시스템에어컨 유상옵션(500~1,000만원) 대비 하단
A31: p_rr_new | B31: Robot-ready Option 공급가 (신축, ARKI 매출) | C31: 만원/세대 | D31: 200 | E31: 220 | F31: 220 | G31: ASSUMPTION | H31: 건설사·가구사 마진 별도. 분양 고객가 약 300만원 가정
A32: p_robot | B32: Robot Module ASP (구매) | C32: 만원/대 | D32: 1290 | E32: 1490 | F32: 1490 | G32: ASSUMPTION | H32: Upside는 가격 인상 없음. WTP 검증 대상 1순위
A33: p_comm | B33: 설치·Calibration·Safety Check | C33: 만원/대 | D33: 80 | E33: 80 | F33: 80 | G33: ASSUMPTION
A34: p_rent | B34: Robot Rental 월 요금 (Care Basic·Grip Kit 포함, 60개월) | C34: 만원/월 | D34: 29 | E34: 33 | F34: 33 | G34: ASSUMPTION | H34: 원가 Build-up(감가·금융·Care·Grip·Reserve)+마진
A35: rent_months | B35: Rental 계약기간 | C35: 개월 | D35: 60 | E35: 60 | F35: 60 | G35: ASSUMPTION
A36: p_care | B36: Care Basic 연 요금 (구매 고객) | C36: 만원/년 | D36: 42 | E36: 48 | F36: 48 | G36: ASSUMPTION | H36: 정기점검·Calibration·원격진단·SW Update·A/S 공임
A37: p_care_plus | B37: Care Plus 연 요금 (Kit 정기교체 포함) | C37: 만원/년 | D37: 72 | E37: 72 | F37: 72 | G37: ASSUMPTION | H37: 옵션 상품. 재무 Base에는 미반영
A38: p_grip | B38: Grip Kit (Finger Pad·Food-contact Tip·Suction Cup) | C38: 만원/Kit | D38: 4.5 | E38: 4.5 | F38: 4.5 | G38: ASSUMPTION | H38: 분기 교체 가정
A39: n_grip | B39: Grip Kit 교체 횟수 | C39: 회/년 | D39: 4 | E39: 4 | F39: 4 | G39: ASSUMPTION | H39: Replacement Cycle 검증 대상
A40: p_clean | B40: Cleaning Kit (Brush·Wiper·Cleaning Pad) | C40: 만원/Kit | D40: 2.5 | E40: 2.5 | F40: 2.5 | G40: ASSUMPTION
A41: n_clean | B41: Cleaning Kit 교체 횟수 | C41: 회/년 | D41: 4 | E41: 4 | F41: 4 | G41: ASSUMPTION
A42: p_protect | B42: Protection Kit (Sensor Cover·Sleeve·Seal) | C42: 만원/Kit | D42: 4 | E42: 4 | F42: 4 | G42: ASSUMPTION
A43: n_protect | B43: Protection Kit 교체 횟수 | C43: 회/년 | D43: 2 | E43: 2 | F43: 2 | G43: ASSUMPTION
A44: cons_attach | B44: Consumables 구매율 | C44: % | D44: 0.55 | E44: 0.7 | F44: 0.7 | G44: ASSUMPTION
A45: care_attach | B45: Care 가입률 (구매 고객) | C45: % | D45: 0.55 | E45: 0.7 | F45: 0.7 | G45: ASSUMPTION
A46: p_sw | B46: Software Skill Pack (설치 다음 해) | C46: 만원 | D46: 60 | E46: 60 | F46: 60 | G46: ASSUMPTION | H46: V2 기능 (재료 투입 보조 등) 출시 전제
A47: sw_attach | B47: Software Skill 구매율 | C47: % | D47: 0.1 | E47: 0.2 | F47: 0.2 | G47: ASSUMPTION
...

Sheet Inputs_Yearly
A1: Inputs_Yearly — 연도별 가정
A3: Key | B3: 항목 | C3: 단위 | D3: Scenario | E3: Y1 | F3: Y2 | G3: Y3 | H3: Y4 | I3: Y5 | J3: Tag | K3: Source / Note
A4: realization | B4: 가격 실현율 (Y2 Pilot 할인) | C4: % | D4: Conservative | E4: 1 | F4: 0.3 | G4: 1 | H4: 1 | I4: 1 | J4: ASSUMPTION | K4: Pilot은 할인 유료
A5: realization | B5: 가격 실현율 (Y2 Pilot 할인) | C5: % | D5: Base | E5: 1 | F5: 0.5 | G5: 1 | H5: 1 | I5: 1 | J5: ASSUMPTION | K5: Pilot은 할인 유료
A6: realization | B6: 가격 실현율 (Y2 Pilot 할인) | C6: % | D6: Upside | E6: 1 | F6: 0.6 | G6: 1 | H6: 1 | I6: 1 | J6: ASSUMPTION | K6: Pilot은 할인 유료
A8: smr | B8: Standard Module 사용률 | C8: % | D8: Conservative | E8: 0.4 | F8: 0.45 | G8: 0.55 | H8: 0.62 | I8: 0.65 | J8: TARGET | K8: Seed 종료 시 65% 이상 (Kill Criteria: M18 60% 미만)
A9: smr | B9: Standard Module 사용률 | C9: % | D9: Base | E9: 0.4 | F9: 0.5 | G9: 0.65 | H9: 0.75 | I9: 0.8 | J9: TARGET | K9: Seed 종료 시 65% 이상 (Kill Criteria: M18 60% 미만)
A10: smr | B10: Standard Module 사용률 | C10: % | D10: Upside | E10: 0.4 | F10: 0.55 | G10: 0.7 | H10: 0.8 | I10: 0.85 | J10: TARGET | K10: Seed 종료 시 65% 이상 (Kill Criteria: M18 60% 미만)
A12: bom | B12: Robot Module BOM | C12: 만원/대 | D12: Conservative | E12: 1600 | F12: 1500 | G12: 1300 | H12: 1180 | I12: 1080 | J12: ASSUMPTION | K12: A4 부품 Benchmark 기반. 수량·국산화·전용 Arm으로 하락 가정
A13: bom | B13: Robot Module BOM | C13: 만원/대 | D13: Base | E13: 1600 | F13: 1450 | G13: 1150 | H13: 1000 | I13: 900 | J13: ASSUMPTION | K13: A4 부품 Benchmark 기반. 수량·국산화·전용 Arm으로 하락 가정
A14: bom | B14: Robot Module BOM | C14: 만원/대 | D14: Upside | E14: 1600 | F14: 1400 | G14: 1080 | H14: 920 | I14: 800 | J14: ASSUMPTION | K14: A4 부품 Benchmark 기반. 수량·국산화·전용 Arm으로 하락 가정
A16: comm_cost | B16: 설치·Calibration 원가 (ARKI 인력) | C16: 만원/대 | D16: Conservative | E16: 120 | F16: 100 | G16: 75 | H16: 62 | I16: 55 | J16: ASSUMPTION | K16: 설치시간 TARGET과 연동
A17: comm_cost | B17: 설치·Calibration 원가 (ARKI 인력) | C17: 만원/대 | D17: Base | E17: 120 | F17: 90 | G17: 60 | H17: 45 | I17: 38 | J17: ASSUMPTION | K17: 설치시간 TARGET과 연동
A18: comm_cost | B18: 설치·Calibration 원가 (ARKI 인력) | C18: 만원/대 | D18: Upside | E18: 120 | F18: 85 | G18: 52 | H18: 38 | I18: 30 | J18: ASSUMPTION | K18: 설치시간 TARGET과 연동
... A38: attach | B38: Robot Attach Rate (구축, 설치 시점) | C38: % | D38: Upside | E38: 1 | F38: 1 | G38: 0.85 | H38: 0.85 | I38: 0.85 | J38: ASSUMPTION | K38: 나머지는 Robot-ready Only
A40: rental_share | B40: Rental 선택 비중 | C40: % | D40: Conservative | E40: 0 | F40: 0.3 | G40: 0.3 | H40: 0.35 | I40: 0.35 | J40: ASSUMPTION
A41: rental_share | B41: Rental 선택 비중 | C41: % | D41: Base | E41: 0 | F41: 0.3 | G41: 0.3 | H41: 0.4 | I41: 0.4 | J41: ASSUMPTION
A42: rental_share | B42: Rental 선택 비중 | C42: % | D42: Upside | E42: 0 | F42: 0.3 | G42: 0.3 | H42: 0.45 | I42: 0.45 | J42: ASSUMPTION
A44: partner_rental | B44: Rental 자산 보유 주체 (0 = ARKI Pilot, 1 = Rental Partner) | C44: flag | D44: Conservative | E44: 0 | F44: 0 | G44: 0 | H44: 1 | I44: 1 | J44: ASSUMPTION
A45: partner_rental | B45: Rental 자산 보유 주체 (0 = ARKI Pilot, 1 = Rental Partner) | C45: flag | D45: Base | E45: 0 | F45: 0 | G45: 0 | H45: 1 | I45: 1 | J45: ASSUMPTION
A46: partner_rental | B46: Rental 자산 보유 주체 (0 = ARKI Pilot, 1 = Rental Partner) | C46: flag | D46: Upside | E46: 0 | F46: 0 | G46: 0 | H46: 1 | I46: 1 | J46: ASSUMPTION
A48: projects | B48: 신축 Robot-ready Option 계약 Project | C48: 개 | D48: Conservative | E48: 0 | F48: 0 | G48: 0 | H48: 1 | I48: 2 | J48: TARGET | K48: 계약 2년 후 입주·설치
A49: projects | B49: 신축 Robot-ready Option 계약 Project | C49: 개 | D49: Base | E49: 0 | F49: 0 | G49: 1 | H49: 2 | I49: 3 | J49: TARGET | K49: 계약 2년 후 입주·설치
A50: projects | B50: 신축 Robot-ready Option 계약 Project | C50: 개 | D50: Upside | E50: 0 | F50: 0 | G50: 2 | H50: 3 | I50: 4 | J50: TARGET | K50: 계약 2년 후 입주·설치
A52: fte | B52: 평균 인원 | C52: 명 | D52: Conservative | E52: 4.4 | F52: 7 | G52: 20 | H52: 32 | I52: 42 | J52: ASSUMPTION | K52: Y1~Y2 = TIPS 기간 (대표 + 신규 연구원 4명 → Y2 실증 엔지니어 · 사업개발 추가, TIPS_TEAM). Y3부터 후속 투자 전제
A53: fte | B53: 평균 인원 | C53: 명 | D53: Base | E53: 4.4 | F53: 7 | G53: 20 | H53: 32 | I53: 42 | J53: ASSUMPTION | K53: Y1~Y2 = TIPS 기간 (대표 + 신규 연구원 4명 → Y2 실증 엔지니어 · 사업개발 추가, TIPS_TEAM). Y3부터 후속 투자 전제
A54: fte | B54: 평균 인원 | C54: 명 | D54: Upside | E54: 4.4 | F54: 7 | G54: 20 | H54: 32 | I54: 42 | J54: ASSUMPTION | K54: Y1~Y2 = TIPS 기간 (대표 + 신규 연구원 4명 → Y2 실증 엔지니어 · 사업개발 추가, TIPS_TEAM). Y3부터 후속 투자 전제
A56: proto | B56: Robot·Kitchen Prototype (H/W) | C56: 만원 | D56: Conservative | E56: 12000 | F56: 4000 | G56: 30000 | H56: 35000 | I56: 40000 | J56: ASSUMPTION | K56: Y1 시제품 1차 2식 + 실물 크기 목업 주방 2식 · Y2 2차 개선 부품 (실증 3세대 하드웨어는 원가에 반영)
A57: proto | B57: Robot·Kitchen Prototype (H/W) | C57: 만원 | D57: Base | E57: 12000 | F57: 4000 | G57: 30000 | H57: 35000 | I57: 40000 | J57: ASSUMPTION | K57: Y1 시제품 1차 2식 + 실물 크기 목업 주방 2식 · Y2 2차 개선 부품 (실증 3세대 하드웨어는 원가에 반영)
A58: proto | B58: Robot·Kitchen Prototype (H/W) | C58: 만원 | D58: Upside | E58: 12000 | F58: 4000 | G58: 30000 | H58: 35000 | I58: 40000 | J58: ASSUMPTION | K58: Y1 시제품 1차 2식 + 실물 크기 목업 주방 2식 · Y2 2차 개선 부품 (실증 3세대 하드웨어는 원가에 반영)
A60: swdata | B60: Vision·Software·Data (GPU·Cloud·Annotation) | C60: 만원 | D60: Conservative | E60: 2000 | F60: 3000 | G60: 10000 | H60: 15000 | I60: 20000 | J60: ASSUMPTION
A61: swdata | B61: Vision·Software·Data (GPU·Cloud·Annotation) | C61: 만원 | D61: Base | E61: 2000 | F61: 3000 | G61: 10000 | H61: 15000 | I61: 20000 | J61: ASSUMPTION
A62: swdata | B62: Vision·Software·Data (GPU·Cloud·Annotation) | C62: 만원 | D62: Upside | E62: 2000 | F62: 3000 | G62: 10000 | H62: 15000 | I62: 20000 | J62: ASSUMPTION
A64: space | B64: Full-scale Mock-up·공간 | C64: 만원 | D64: Conservative | E64: 6000 | F64: 4000 | G64: 10000 | H64: 12000 | I64: 15000 | J64: ASSUMPTION | K64: Y1~Y2: 목업 공간 약 30평 임차 + 목업 시공
A65: space | B65: Full-scale Mock-up·공간 | C65: 만원 | D65: Base | E65: 6000 | F65: 4000 | G65: 10000 | H65: 12000 | I65: 15000 | J65: ASSUMPTION | K65: Y1~Y2: 목업 공간 약 30평 임차 + 목업 시공
A66: space | B66: Full-scale Mock-up·공간 | C66: 만원 | D66: Upside | E66: 6000 | F66: 4000 | G66: 10000 | H66: 12000 | I66: 15000 | J66: ASSUMPTION | K66: Y1~Y2: 목업 공간 약 30평 임차 + 목업 시공
A68: cert_ip | B68: Safety·Certification·IP | C68: 만원 | D68: Conservative | E68: 2500 | F68: 6000 | G68: 20000 | H68: 10000 | I68: 10000 | J68: ASSUMPTION | K68: Y1 선행기술조사 · 특허 출원 2건 / Y2 공인시험 · 안전 사전시험 · 특허 3건 / Y3 본인증
A69: cert_ip | B69: Safety·Certification·IP | C69: 만원 | D69: Base | E69: 2500 | F69: 6000 | G69: 20000 | H69: 10000 | I69: 10000 | J69: ASSUMPTION | K69: Y1 선행기술조사 · 특허 출원 2건 / Y2 공인시험 · 안전 사전시험 · 특허 3건 / Y3 본인증
A70: cert_ip | B70: Safety·Certification·IP | C70: 만원 | D70: Upside | E70: 2500 | F70: 6000 | G70: 20000 | H70: 10000 | I70: 10000 | J70: ASSUMPTION | K70: Y1 선행기술조사 · 특허 출원 2건 / Y2 공인시험 · 안전 사전시험 · 특허 3건 / Y3 본인증
A72: research | B72: Pilot·Customer Validation | C72: 만원 | D72: Conservative | E72: 2000 | F72: 3500 | G72: 5000 | H72: 5000 | I72: 5000 | J72: ASSUMPTION | K72: Y1 인터뷰 50명 · 정리 시간 기록 30세대 / Y2 지불의사 조사 n≥300 · 실증 가정 지원
...

Sheet FM_Conservative
A1: 5-Year Bottom-up Model — Conservative (만원)
A2: 모든 입력은 Inputs / Inputs_Yearly의 Conservative 열·행을 참조 (녹색). 영업이익은 이자·세금 제외 근사.
A3: 항목 | B3: 단위 | C3: Y1 | D3: Y2 | E3: Y3 | F3: Y4 | G3: Y5 | H3: 5Y 합계
A4: VOLUME
A5: 구축 직접판매 Kitchen | B5: 세대 | C5: =Inputs_Yearly!$E$28 -> 0 | D5: =Inputs_Yearly!$F$28 -> 3 | E5: =Inputs_Yearly!$G$28 -> 20 | F5: =Inputs_Yearly!$H$28 -> 35 | G5: =Inputs_Yearly!$I$28 -> 40 | H5: =SUM(C5:G5) -> 98
A6: 구축 Partner 경유 Kitchen | B6: 세대 | C6: =Inputs_Yearly!$E$32 -> 0 | D6: =Inputs_Yearly!$F$32 -> 0 | E6: =Inputs_Yearly!$G$32 -> 10 | F6: =Inputs_Yearly!$H$32 -> 60 | G6: =Inputs_Yearly!$I$32 -> 150 | H6: =SUM(C6:G6) -> 220
A7: 신축 Robot-ready 설치 (계약 2년 후) | B7: 세대 | C7: =0 -> 0 | D7: =0 -> 0 | E7: =Inputs_Yearly!$E$48*Inputs!$D$73*Inputs!$D$74 -> 0 | F7: =Inputs_Yearly!$F$48*Inputs!$D$73*Inputs!$D$74 -> 0 | G7: =Inputs_Yearly!$G$48*Inputs!$D$73*Inputs!$D$74 -> 0 | H7: =SUM(C7:G7) -> 0
A8: Kitchen 설치 합계 | B8: 세대 | C8: =C5+C6+C7 -> 0 | D8: =D5+D6+D7 -> 3 | E8: =E5+E6+E7 -> 30 | F8: =F5+F6+F7 -> 95 | G8: =G5+G6+G7 -> 190 | H8: =SUM(C8:G8) -> 318
A9: Robot Attach Rate (구축) | B9: % | C9: =Inputs_Yearly!$E$36 -> 1 | D9: =Inputs_Yearly!$F$36 -> 1 | E9: =Inputs_Yearly!$G$36 -> 0.75 | F9: =Inputs_Yearly!$H$36 -> 0.75 | G9: =Inputs_Yearly!$I$36 -> 0.75
A10: Robot-ready Only 세대 후속 Attach | B10: 대 | C10: =0*Inputs!$D$72 -> 0 | D10: =C20*Inputs!$D$72 -> 0 | E10: =D20*Inputs!$D$72 -> 0 | F10: =E20*Inputs!$D$72 -> 0.375 | G10: =F20*Inputs!$D$72 -> 1.54375 | H10: =SUM(C10:G10) -> 1.91875
A11: Robot 설치 — 구축 | B11: 대 | C11: =(C5+C6)*C9 -> 0 | D11: =(D5+D6)*D9 -> 3 | E11: =(E5+E6)*E9 -> 22.5 | F11: =(F5+F6)*F9 -> 71.25 | G11: =(G5+G6)*G9 -> 142.5 | H11: =SUM(C11:G11) -> 239.25
A12: Robot 설치 — 신축 입주 | B12: 대 | C12: =C7*Inputs!$D$75 -> 0 | D12: =D7*Inputs!$D$75 -> 0 | E12: =E7*Inputs!$D$75 -> 0 | F12: =F7*Inputs!$D$75 -> 0 | G12: =G7*Inputs!$D$75 -> 0 | H12: =SUM(C12:G12) -> 0
A13: Robot 설치 합계 | B13: 대 | C13: =C11+C12+C10 -> 0 | D13: =D11+D12+D10 -> 3 | E13: =E11+E12+E10 -> 22.5 | F13: =F11+F12+F10 -> 71.625 | G13: =G11+G12+G10 -> 144.04375 | H13: =SUM(C13:G13) -> 241.16875
A14: Rental 비중 | B14: % | C14: =Inputs_Yearly!$E$40 -> 0 | D14: =Inputs_Yearly!$F$40 -> 0.3 | E14: =Inputs_Yearly!$G$40 -> 0.3 | F14: =Inputs_Yearly!$H$40 -> 0.35 | G14: =Inputs_Yearly!$I$40 -> 0.35
A15: Rental Partner 보유 Flag | B15: flag | C15: =Inputs_Yearly!$E$44 -> 0 | D15: =Inputs_Yearly!$F$44 -> 0 | E15: =Inputs_Yearly!$G$44 -> 0 | F15: =Inputs_Yearly!$H$44 -> 1 | G15: =Inputs_Yearly!$I$44 -> 1
A16: Rental 설치 | B16: 대 | C16: =C13*C14 -> 0 | D16: =D13*D14 -> 0.9 | E16: =E13*E14 -> 6.75 | F16: =F13*F14 -> 25.06875 | G16: =G13*G14 -> 50.415312 | H16: =SUM(C16:G16) -> 83.134062
A17: 구매 설치 | B17: 대 | C17: =C13-C16 -> 0 | D17: =D13-D16 -> 2.1 | E17: =E13-E16 -> 15.75 | F17: =F13-F16 -> 46.55625 | G17: =G13-G16 -> 93.628438 | H17: =SUM(C17:G17) -> 158.03469
A18: Rental — ARKI 보유 (Pilot) | B18: 대 | C18: =C16*(1-C15) -> 0 | D18: =D16*(1-D15) -> 0.9 | E18: =E16*(1-E15) -> 6.75 | F18: =F16*(1-F15) -> 0 | G18: =G16*(1-G15) -> 0 | H18: =SUM(C18:G18) -> 7.65
A19: Rental — Partner 보유 | B19: 대 | C19: =C16*C15 -> 0 | D19: =D16*D15 -> 0 | E19: =E16*E15 -> 0 | F19: =F16*F15 -> 25.06875 | G19: =G16*G15 -> 50.415312 | H19: =SUM(C19:G19) -> 75.484062
A20: Robot-ready Only 누적 (기말) | B20: 세대 | C20: =0+(C5+C6)*(1-C9)+C7*(1-Inputs!$D$75)-C10 -> 0 | D20: =C20+(D5+D6)*(1-D9)+D7*(1-Inputs!$D$75)-D10 -> 0 | E20: =D20+(E5+E6)*(1-E9)+E7*(1-Inputs!$D$75)-E10 -> 7.5 | F20: =E20+(F5+F6)*(1-F9)+F7*(1-Inputs!$D$75)-F10 -> 30.875 | G20: =F20+(G5+G6)*(1-G9)+G7*(1-Inputs!$D$75)-G10 -> 76.83125
A21: 구매 Robot 누적 (기말) | B21: 대 | C21: =0+C17 -> 0 | D21: =C21+D17 -> 2.1 | E21: =D21+E17 -> 17.85 | F21: =E21+F17 -> 64.40625 | G21: =F21+G17 -> 158.03469
A22: 구매 Robot 평균 가동 | B22: 대 | C22: =0+C17/2 -> 0 | D22: =C21+D17/2 -> 1.05 | E22: =D21+E17/2 -> 9.975 | F22: =E21+F17/2 -> 41.128125 | G22: =F21+G17/2 -> 111.22047
A23: ARKI Rental 누적 (기말) | B23: 대 | C23: =0+C18 -> 0 | D23: =C23+D18 -> 0.9 | E23: =D23+E18 -> 7.65 | F23: =E23+F18 -> 7.65 | G23: =F23+G18 -> 7.65
A24: ARKI Rental 평균 가동 | B24: 대 | C24: =0+C18/2 -> 0 | D24: =C23+D18/2 -> 0.45 | E24: =D23+E18/2 -> 4.275 | F24: =E23+F18/2 -> 7.65 | G24: =F23+G18/2 -> 7.65
A25: Partner Rental 누적 (기말) | B25: 대 | C25: =0+C19 -> 0 | D25: =C25+D19 -> 0 | E25: =D25+E19 -> 0 | F25: =E25+F19 -> 25.06875 | G25: =F25+G19 -> 75.484062
A26: Partner Rental 평균 가동 | B26: 대 | C26: =0+C19/2 -> 0 | D26: =C25+D19/2 -> 0 | E26: =D25+E19/2 -> 0 | F26: =E25+F19/2 -> 12.534375 | G26: =F25+G19/2 -> 50.276406
A27: Installed Robot (기말) | B27: 대 | C27: =C21+C23+C25 -> 0 | D27: =D21+D23+D25 -> 3 | E27: =E21+E23+E25 -> 25.5 | F27: =F21+F23+F25 -> 97.125 | G27: =G21+G23+G25 -> 241.16875
A28: 신축 계약 Backlog (미설치 세대) | B28: 세대 | C28: =Inputs_Yearly!$E$48*Inputs!$D$73*Inputs!$D$74 -> 0 | D28: =(Inputs_Yearly!$F$48+Inputs_Yearly!$E$48)*Inputs!$D$73*Inputs!$D$74 -> 0 | E28: =(Inputs_Yearly!$G$48+Inputs_Yearly!$F$48)*Inputs!$D$73*Inputs!$D$74 -> 0 | F28: =(Inputs_Yearly!$H$48+Inputs_Yearly!$G$48)*Inputs!$D$73*Inputs!$D$74 -> 48 | G28: =(Inputs_Yearly!$I$48+Inputs_Yearly!$H$48)*Inputs!$D$73*Inputs!$D$74 -> 144
A29: REVENUE (만원)
A30: 가격 실현율 | B30: % | C30: =Inputs_Yearly!$E$4 -> 1 | D30: =Inputs_Yearly!$F$4 -> 0.3 | E30: =Inputs_Yearly!$G$4 -> 1 | F30: =Inputs_Yearly!$H$4 -> 1 | G30: =Inputs_Yearly!$I$4 -> 1
A31: Consumables 연 List (구매 고객) | B31: 만원/대 | C31: =Inputs!$D$38*Inputs!$D$39+Inputs!$D$40*Inputs!$D$41+Inputs!$D$42*Inputs!$D$43 -> 36 | D31: =Inputs!$D$38*Inputs!$D$39+Inputs!$D$40*Inputs!$D$41+Inputs!$D$42*Inputs!$D$43 -> 36 | E31: =Inputs!$D$38*Inputs!$D$39+Inputs!$D$40*Inputs!$D$41+Inputs!$D$42*Inputs!$D$43 -> 36 | F31: =Inputs!$D$38*Inputs!$D$39+Inputs!$D$40*Inputs!$D$41+Inputs!$D$42*Inputs!$D$43 -> 36 | G31: =Inputs!$D$38*Inputs!$D$39+Inputs!$D$40*Inputs!$D$41+Inputs!$D$42*Inputs!$D$43 -> 36
A32: Consumables 연 List (Rental, Grip 제외) | B32: 만원/대 | C32: =Inputs!$D$40*Inputs!$D$41+Inputs!$D$42*Inputs!$D$43 -> 18 | D32: =Inputs!$D$40*Inputs!$D$41+Inputs!$D$42*Inputs!$D$43 -> 18 | E32: =Inputs!$D$40*Inputs!$D$41+Inputs!$D$42*Inputs!$D$43 -> 18 | F32: =Inputs!$D$40*Inputs!$D$41+Inputs!$D$42*Inputs!$D$43 -> 18 | G32: =Inputs!$D$40*Inputs!$D$41+Inputs!$D$42*Inputs!$D$43 -> 18
A33: Grip Kit 연 List | B33: 만원/대 | C33: =Inputs!$D$38*Inputs!$D$39 -> 18 | D33: =Inputs!$D$38*Inputs!$D$39 -> 18 | E33: =Inputs!$D$38*Inputs!$D$39 -> 18 | F33: =Inputs!$D$38*Inputs!$D$39 -> 18 | G33: =Inputs!$D$38*Inputs!$D$39 -> 18
A34: A. Kitchen Build (Robot-ready) | B34: 만원 | C34: =(C5+C6)*Inputs!$D$30*C30+C7*Inputs!$D$31 -> 0 | D34: =(D5+D6)*Inputs!$D$30*D30+D7*Inputs!$D$31 -> 360 | E34: =(E5+E6)*Inputs!$D$30*E30+E7*Inputs!$D$31 -> 12000 | F34: =(F5+F6)*Inputs!$D$30*F30+F7*Inputs!$D$31 -> 38000 | G34: =(G5+G6)*Inputs!$D$30*G30+G7*Inputs!$D$31 -> 76000 | H34: =SUM(C34:G34) -> 126360
A35: A. 설치·Calibration | B35: 만원 | C35: =C13*Inputs!$D$33*C30 -> 0 | D35: =D13*Inputs!$D$33*D30 -> 72 | E35: =E13*Inputs!$D$33*E30 -> 1800 | F35: =F13*Inputs!$D$33*F30 -> 5730 | G35: =G13*Inputs!$D$33*G30 -> 11523.5 | H35: =SUM(C35:G35) -> 19125.5
A36: A. Robot Hardware (구매 + Rental Partner 공급) | B36: 만원 | C36: =C17*Inputs!$D$32*C30+C19*Inputs!$D$32*Inputs!$D$50 -> 0 | D36: =D17*Inputs!$D$32*D30+D19*Inputs!$D$32*Inputs!$D$50 -> 812.7 | E36: =E17*Inputs!$D$32*E30+E19*Inputs!$D$32*Inputs!$D$50 -> 20317.5 | F36: =F17*Inputs!$D$32*F30+F19*Inputs!$D$32*Inputs!$D$50 -> 88515.607 | G36: =G17*Inputs!$D$32*G30+G19*Inputs!$D$32*Inputs!$D$50 -> 178012.15 | H36: =SUM(C36:G36) -> 287657.95
A37: B. Rental (ARKI 보유) | B37: 만원 | C37: =C24*Inputs!$D$34*12 -> 0 | D37: =D24*Inputs!$D$34*12 -> 156.6 | E37: =E24*Inputs!$D$34*12 -> 1487.7 | F37: =F24*Inputs!$D$34*12 -> 2662.2 | G37: =G24*Inputs!$D$34*12 -> 2662.2 | H37: =SUM(C37:G37) -> 6968.7
A38: B. Care (구매 고객 + Partner 서비스료) | B38: 만원 | C38: =C22*Inputs!$D$45*Inputs!$D$36+C26*Inputs!$D$51*12 -> 0 | D38: =D22*Inputs!$D$45*Inputs!$D$36+D26*Inputs!$D$51*12 -> 24.255 | E38: =E22*Inputs!$D$45*Inputs!$D$36+E26*Inputs!$D$51*12 -> 230.4225 | F38: =F22*Inputs!$D$45*Inputs!$D$36+F26*Inputs!$D$51*12 -> 1852.5347 | G38: =G22*Inputs!$D$45*Inputs!$D$36+G26*Inputs!$D$51*12 -> 6189.0941 | H38: =SUM(C38:G38) -> 8296.3063
A39: B. Consumables | B39: 만원 | C39: =C22*Inputs!$D$44*C31+(C24+C26)*Inputs!$D$44*C32 -> 0 | D39: =D22*Inputs!$D$44*D31+(D24+D26)*Inputs!$D$44*D32 -> 25.245 | E39: =E22*Inputs!$D$44*E31+(E24+E26)*Inputs!$D$44*E32 -> 239.8275 | F39: =F22*Inputs!$D$44*F31+(F24+F26)*Inputs!$D$44*F32 -> 1014.1622 | G39: =G22*Inputs!$D$44*G31+(G24+G26)*Inputs!$D$44*G32 -> 2775.6367 | H39: =SUM(C39:G39) -> 4054.8714
A40: C. Upgrade (Software Skill + Tool) | B40: 만원 | C40: =0*Inputs!$D$47*Inputs!$D$46+0*Inputs!$D$49*Inputs!$D$48 -> 0 | D40: =C13*Inputs!$D$47*Inputs!$D$46+0*Inputs!$D$49*Inputs!$D$48 -> 0 | E40: =D13*Inputs!$D$47*Inputs!$D$46+C13*Inputs!$D$49*Inputs!$D$48 -> 18 | F40: =E13*Inputs!$D$47*Inputs!$D$46+D13*Inputs!$D$49*Inputs!$D$48 -> 171 | G40: =F13*Inputs!$D$47*Inputs!$D$46+E13*Inputs!$D$49*Inputs!$D$48 -> 699.75 | H40: =SUM(C40:G40) -> 888.75
...

Sheet FM_Base
A1: 5-Year Bottom-up Model — Base (만원)
A2: 모든 입력은 Inputs / Inputs_Yearly의 Base 열·행을 참조 (녹색). 영업이익은 이자·세금 제외 근사.
A3: 항목 | B3: 단위 | C3: Y1 | D3: Y2 | E3: Y3 | F3: Y4 | G3: Y5 | H3: 5Y 합계
A4: VOLUME
A5: 구축 직접판매 Kitchen | B5: 세대 | C5: =Inputs_Yearly!$E$29 -> 0 | D5: =Inputs_Yearly!$F$29 -> 3 | E5: =Inputs_Yearly!$G$29 -> 30 | F5: =Inputs_Yearly!$H$29 -> 50 | G5: =Inputs_Yearly!$I$29 -> 60 | H5: =SUM(C5:G5) -> 143
A6: 구축 Partner 경유 Kitchen | B6: 세대 | C6: =Inputs_Yearly!$E$33 -> 0 | D6: =Inputs_Yearly!$F$33 -> 0 | E6: =Inputs_Yearly!$G$33 -> 20 | F6: =Inputs_Yearly!$H$33 -> 130 | G6: =Inputs_Yearly!$I$33 -> 340 | H6: =SUM(C6:G6) -> 490
A7: 신축 Robot-ready 설치 (계약 2년 후) | B7: 세대 | C7: =0 -> 0 | D7: =0 -> 0 | E7: =Inputs_Yearly!$E$49*Inputs!$E$73*Inputs!$E$74 -> 0 | F7: =Inputs_Yearly!$F$49*Inputs!$E$73*Inputs!$E$74 -> 0 | G7: =Inputs_Yearly!$G$49*Inputs!$E$73*Inputs!$E$74 -> 80 | H7: =SUM(C7:G7) -> 80
A8: Kitchen 설치 합계 | B8: 세대 | C8: =C5+C6+C7 -> 0 | D8: =D5+D6+D7 -> 3 | E8: =E5+E6+E7 -> 50 | F8: =F5+F6+F7 -> 180 | G8: =G5+G6+G7 -> 480 | H8: =SUM(C8:G8) -> 713
A9: Robot Attach Rate (구축) | B9: % | C9: =Inputs_Yearly!$E$37 -> 1 | D9: =Inputs_Yearly!$F$37 -> 1 | E9: =Inputs_Yearly!$G$37 -> 0.85 | F9: =Inputs_Yearly!$H$37 -> 0.85 | G9: =Inputs_Yearly!$I$37 -> 0.85
A10: Robot-ready Only 세대 후속 Attach | B10: 대 | C10: =0*Inputs!$E$72 -> 0 | D10: =C20*Inputs!$E$72 -> 0 | E10: =D20*Inputs!$E$72 -> 0 | F10: =E20*Inputs!$E$72 -> 0.75 | G10: =F20*Inputs!$E$72 -> 3.375 | H10: =SUM(C10:G10) -> 4.125
A11: Robot 설치 — 구축 | B11: 대 | C11: =(C5+C6)*C9 -> 0 | D11: =(D5+D6)*D9 -> 3 | E11: =(E5+E6)*E9 -> 42.5 | F11: =(F5+F6)*F9 -> 153 | G11: =(G5+G6)*G9 -> 340 | H11: =SUM(C11:G11) -> 538.5
A12: Robot 설치 — 신축 입주 | B12: 대 | C12: =C7*Inputs!$E$75 -> 0 | D12: =D7*Inputs!$E$75 -> 0 | E12: =E7*Inputs!$E$75 -> 0 | F12: =F7*Inputs!$E$75 -> 0 | G12: =G7*Inputs!$E$75 -> 20 | H12: =SUM(C12:G12) -> 20
A13: Robot 설치 합계 | B13: 대 | C13: =C11+C12+C10 -> 0 | D13: =D11+D12+D10 -> 3 | E13: =E11+E12+E10 -> 42.5 | F13: =F11+F12+F10 -> 153.75 | G13: =G11+G12+G10 -> 363.375 | H13: =SUM(C13:G13) -> 562.625
A14: Rental 비중 | B14: % | C14: =Inputs_Yearly!$E$41 -> 0 | D14: =Inputs_Yearly!$F$41 -> 0.3 | E14: =Inputs_Yearly!$G$41 -> 0.3 | F14: =Inputs_Yearly!$H$41 -> 0.4 | G14: =Inputs_Yearly!$I$41 -> 0.4
A15: Rental Partner 보유 Flag | B15: flag | C15: =Inputs_Yearly!$E$45 -> 0 | D15: =Inputs_Yearly!$F$45 -> 0 | E15: =Inputs_Yearly!$G$45 -> 0 | F15: =Inputs_Yearly!$H$45 -> 1 | G15: =Inputs_Yearly!$I$45 -> 1
A16: Rental 설치 | B16: 대 | C16: =C13*C14 -> 0 | D16: =D13*D14 -> 0.9 | E16: =E13*E14 -> 12.75 | F16: =F13*F14 -> 61.5 | G16: =G13*G14 -> 145.35 | H16: =SUM(C16:G16) -> 220.5
A17: 구매 설치 | B17: 대 | C17: =C13-C16 -> 0 | D17: =D13-D16 -> 2.1 | E17: =E13-E16 -> 29.75 | F17: =F13-F16 -> 92.25 | G17: =G13-G16 -> 218.025 | H17: =SUM(C17:G17) -> 342.125
A18: Rental — ARKI 보유 (Pilot) | B18: 대 | C18: =C16*(1-C15) -> 0 | D18: =D16*(1-D15) -> 0.9 | E18: =E16*(1-E15) -> 12.75 | F18: =F16*(1-F15) -> 0 | G18: =G16*(1-G15) -> 0 | H18: =SUM(C18:G18) -> 13.65
A19: Rental — Partner 보유 | B19: 대 | C19: =C16*C15 -> 0 | D19: =D16*D15 -> 0 | E19: =E16*E15 -> 0 | F19: =F16*F15 -> 61.5 | G19: =G16*G15 -> 145.35 | H19: =SUM(C19:G19) -> 206.85
A20: Robot-ready Only 누적 (기말) | B20: 세대 | C20: =0+(C5+C6)*(1-C9)+C7*(1-Inputs!$E$75)-C10 -> 0 | D20: =C20+(D5+D6)*(1-D9)+D7*(1-Inputs!$E$75)-D10 -> 0 | E20: =D20+(E5+E6)*(1-E9)+E7*(1-Inputs!$E$75)-E10 -> 7.5 | F20: =E20+(F5+F6)*(1-F9)+F7*(1-Inputs!$E$75)-F10 -> 33.75 | G20: =F20+(G5+G6)*(1-G9)+G7*(1-Inputs!$E$75)-G10 -> 150.375
A21: 구매 Robot 누적 (기말) | B21: 대 | C21: =0+C17 -> 0 | D21: =C21+D17 -> 2.1 | E21: =D21+E17 -> 31.85 | F21: =E21+F17 -> 124.1 | G21: =F21+G17 -> 342.125
A22: 구매 Robot 평균 가동 | B22: 대 | C22: =0+C17/2 -> 0 | D22: =C21+D17/2 -> 1.05 | E22: =D21+E17/2 -> 16.975 | F22: =E21+F17/2 -> 77.975 | G22: =F21+G17/2 -> 233.1125
A23: ARKI Rental 누적 (기말) | B23: 대 | C23: =0+C18 -> 0 | D23: =C23+D18 -> 0.9 | E23: =D23+E18 -> 13.65 | F23: =E23+F18 -> 13.65 | G23: =F23+G18 -> 13.65
A24: ARKI Rental 평균 가동 | B24: 대 | C24: =0+C18/2 -> 0 | D24: =C23+D18/2 -> 0.45 | E24: =D23+E18/2 -> 7.275 | F24: =E23+F18/2 -> 13.65 | G24: =F23+G18/2 -> 13.65
A25: Partner Rental 누적 (기말) | B25: 대 | C25: =0+C19 -> 0 | D25: =C25+D19 -> 0 | E25: =D25+E19 -> 0 | F25: =E25+F19 -> 61.5 | G25: =F25+G19 -> 206.85
A26: Partner Rental 평균 가동 | B26: 대 | C26: =0+C19/2 -> 0 | D26: =C25+D19/2 -> 0 | E26: =D25+E19/2 -> 0 | F26: =E25+F19/2 -> 30.75 | G26: =F25+G19/2 -> 134.175
A27: Installed Robot (기말) | B27: 대 | C27: =C21+C23+C25 -> 0 | D27: =D21+D23+D25 -> 3 | E27: =E21+E23+E25 -> 45.5 | F27: =F21+F23+F25 -> 199.25 | G27: =G21+G23+G25 -> 562.625
A28: 신축 계약 Backlog (미설치 세대) | B28: 세대 | C28: =Inputs_Yearly!$E$49*Inputs!$E$73*Inputs!$E$74 -> 0 | D28: =(Inputs_Yearly!$F$49+Inputs_Yearly!$E$49)*Inputs!$E$73*Inputs!$E$74 -> 0 | E28: =(Inputs_Yearly!$G$49+Inputs_Yearly!$F$49)*Inputs!$E$73*Inputs!$E$74 -> 80 | F28: =(Inputs_Yearly!$H$49+Inputs_Yearly!$G$49)*Inputs!$E$73*Inputs!$E$74 -> 240 | G28: =(Inputs_Yearly!$I$49+Inputs_Yearly!$H$49)*Inputs!$E$73*Inputs!$E$74 -> 400
A29: REVENUE (만원)
A30: 가격 실현율 | B30: % | C30: =Inputs_Yearly!$E$5 -> 1 | D30: =Inputs_Yearly!$F$5 -> 0.5 | E30: =Inputs_Yearly!$G$5 -> 1 | F30: =Inputs_Yearly!$H$5 -> 1 | G30: =Inputs_Yearly!$I$5 -> 1
A31: Consumables 연 List (구매 고객) | B31: 만원/대 | C31: =Inputs!$E$38*Inputs!$E$39+Inputs!$E$40*Inputs!$E$41+Inputs!$E$42*Inputs!$E$43 -> 36 | D31: =Inputs!$E$38*Inputs!$E$39+Inputs!$E$40*Inputs!$E$41+Inputs!$E$42*Inputs!$E$43 -> 36 | E31: =Inputs!$E$38*Inputs!$E$39+Inputs!$E$40*Inputs!$E$41+Inputs!$E$42*Inputs!$E$43 -> 36 | F31: =Inputs!$E$38*Inputs!$E$39+Inputs!$E$40*Inputs!$E$41+Inputs!$E$42*Inputs!$E$43 -> 36 | G31: =Inputs!$E$38*Inputs!$E$39+Inputs!$E$40*Inputs!$E$41+Inputs!$E$42*Inputs!$E$43 -> 36
A32: Consumables 연 List (Rental, Grip 제외) | B32: 만원/대 | C32: =Inputs!$E$40*Inputs!$E$41+Inputs!$E$42*Inputs!$E$43 -> 18 | D32: =Inputs!$E$40*Inputs!$E$41+Inputs!$E$42*Inputs!$E$43 -> 18 | E32: =Inputs!$E$40*Inputs!$E$41+Inputs!$E$42*Inputs!$E$43 -> 18 | F32: =Inputs!$E$40*Inputs!$E$41+Inputs!$E$42*Inputs!$E$43 -> 18 | G32: =Inputs!$E$40*Inputs!$E$41+Inputs!$E$42*Inputs!$E$43 -> 18
A33: Grip Kit 연 List | B33: 만원/대 | C33: =Inputs!$E$38*Inputs!$E$39 -> 18 | D33: =Inputs!$E$38*Inputs!$E$39 -> 18 | E33: =Inputs!$E$38*Inputs!$E$39 -> 18 | F33: =Inputs!$E$38*Inputs!$E$39 -> 18 | G33: =Inputs!$E$38*Inputs!$E$39 -> 18
A34: A. Kitchen Build (Robot-ready) | B34: 만원 | C34: =(C5+C6)*Inputs!$E$30*C30+C7*Inputs!$E$31 -> 0 | D34: =(D5+D6)*Inputs!$E$30*D30+D7*Inputs!$E$31 -> 675 | E34: =(E5+E6)*Inputs!$E$30*E30+E7*Inputs!$E$31 -> 22500 | F34: =(F5+F6)*Inputs!$E$30*F30+F7*Inputs!$E$31 -> 81000 | G34: =(G5+G6)*Inputs!$E$30*G30+G7*Inputs!$E$31 -> 197600 | H34: =SUM(C34:G34) -> 301775
A35: A. 설치·Calibration | B35: 만원 | C35: =C13*Inputs!$E$33*C30 -> 0 | D35: =D13*Inputs!$E$33*D30 -> 120 | E35: =E13*Inputs!$E$33*E30 -> 3400 | F35: =F13*Inputs!$E$33*F30 -> 12300 | G35: =G13*Inputs!$E$33*G30 -> 29070 | H35: =SUM(C35:G35) -> 44890
A36: A. Robot Hardware (구매 + Rental Partner 공급) | B36: 만원 | C36: =C17*Inputs!$E$32*C30+C19*Inputs!$E$32*Inputs!$E$50 -> 0 | D36: =D17*Inputs!$E$32*D30+D19*Inputs!$E$32*Inputs!$E$50 -> 1564.5 | E36: =E17*Inputs!$E$32*E30+E19*Inputs!$E$32*Inputs!$E$50 -> 44327.5 | F36: =F17*Inputs!$E$32*F30+F19*Inputs!$E$32*Inputs!$E$50 -> 218091.3 | G36: =G17*Inputs!$E$32*G30+G19*Inputs!$E$32*Inputs!$E$50 -> 515440.17 | H36: =SUM(C36:G36) -> 779423.47
A37: B. Rental (ARKI 보유) | B37: 만원 | C37: =C24*Inputs!$E$34*12 -> 0 | D37: =D24*Inputs!$E$34*12 -> 178.2 | E37: =E24*Inputs!$E$34*12 -> 2880.9 | F37: =F24*Inputs!$E$34*12 -> 5405.4 | G37: =G24*Inputs!$E$34*12 -> 5405.4 | H37: =SUM(C37:G37) -> 13869.9
A38: B. Care (구매 고객 + Partner 서비스료) | B38: 만원 | C38: =C22*Inputs!$E$45*Inputs!$E$36+C26*Inputs!$E$51*12 -> 0 | D38: =D22*Inputs!$E$45*Inputs!$E$36+D26*Inputs!$E$51*12 -> 35.28 | E38: =E22*Inputs!$E$45*Inputs!$E$36+E26*Inputs!$E$51*12 -> 570.36 | F38: =F22*Inputs!$E$45*Inputs!$E$36+F26*Inputs!$E$51*12 -> 4833.96 | G38: =G22*Inputs!$E$45*Inputs!$E$36+G26*Inputs!$E$51*12 -> 17493.18 | H38: =SUM(C38:G38) -> 22932.78
A39: B. Consumables | B39: 만원 | C39: =C22*Inputs!$E$44*C31+(C24+C26)*Inputs!$E$44*C32 -> 0 | D39: =D22*Inputs!$E$44*D31+(D24+D26)*Inputs!$E$44*D32 -> 32.13 | E39: =E22*Inputs!$E$44*E31+(E24+E26)*Inputs!$E$44*E32 -> 519.435 | F39: =F22*Inputs!$E$44*F31+(F24+F26)*Inputs!$E$44*F32 -> 2524.41 | G39: =G22*Inputs!$E$44*G31+(G24+G26)*Inputs!$E$44*G32 -> 7737.03 | H39: =SUM(C39:G39) -> 10813.005
A40: C. Upgrade (Software Skill + Tool) | B40: 만원 | C40: =0*Inputs!$E$47*Inputs!$E$46+0*Inputs!$E$49*Inputs!$E$48 -> 0 | D40: =C13*Inputs!$E$47*Inputs!$E$46+0*Inputs!$E$49*Inputs!$E$48 -> 0 | E40: =D13*Inputs!$E$47*Inputs!$E$46+C13*Inputs!$E$49*Inputs!$E$48 -> 36 | F40: =E13*Inputs!$E$47*Inputs!$E$46+D13*Inputs!$E$49*Inputs!$E$48 -> 570 | G40: =F13*Inputs!$E$47*Inputs!$E$46+E13*Inputs!$E$49*Inputs!$E$48 -> 2695 | H40: =SUM(C40:G40) -> 3301
...

Sheet FM_Upside
A1: 5-Year Bottom-up Model — Upside (만원)
A2: 모든 입력은 Inputs / Inputs_Yearly의 Upside 열·행을 참조 (녹색). 영업이익은 이자·세금 제외 근사.
A3: 항목 | B3: 단위 | C3: Y1 | D3: Y2 | E3: Y3 | F3: Y4 | G3: Y5 | H3: 5Y 합계
A4: VOLUME
A5: 구축 직접판매 Kitchen | B5: 세대 | C5: =Inputs_Yearly!$E$30 -> 0 | D5: =Inputs_Yearly!$F$30 -> 3 | E5: =Inputs_Yearly!$G$30 -> 35 | F5: =Inputs_Yearly!$H$30 -> 60 | G5: =Inputs_Yearly!$I$30 -> 70 | H5: =SUM(C5:G5) -> 168
A6: 구축 Partner 경유 Kitchen | B6: 세대 | C6: =Inputs_Yearly!$E$34 -> 0 | D6: =Inputs_Yearly!$F$34 -> 0 | E6: =Inputs_Yearly!$G$34 -> 30 | F6: =Inputs_Yearly!$H$34 -> 220 | G6: =Inputs_Yearly!$I$34 -> 600 | H6: =SUM(C6:G6) -> 850
A7: 신축 Robot-ready 설치 (계약 2년 후) | B7: 세대 | C7: =0 -> 0 | D7: =0 -> 0 | E7: =Inputs_Yearly!$E$50*Inputs!$F$73*Inputs!$F$74 -> 0 | F7: =Inputs_Yearly!$F$50*Inputs!$F$73*Inputs!$F$74 -> 0 | G7: =Inputs_Yearly!$G$50*Inputs!$F$73*Inputs!$F$74 -> 192 | H7: =SUM(C7:G7) -> 192
A8: Kitchen 설치 합계 | B8: 세대 | C8: =C5+C6+C7 -> 0 | D8: =D5+D6+D7 -> 3 | E8: =E5+E6+E7 -> 65 | F8: =F5+F6+F7 -> 280 | G8: =G5+G6+G7 -> 862 | H8: =SUM(C8:G8) -> 1210
A9: Robot Attach Rate (구축) | B9: % | C9: =Inputs_Yearly!$E$38 -> 1 | D9: =Inputs_Yearly!$F$38 -> 1 | E9: =Inputs_Yearly!$G$38 -> 0.85 | F9: =Inputs_Yearly!$H$38 -> 0.85 | G9: =Inputs_Yearly!$I$38 -> 0.85
A10: Robot-ready Only 세대 후속 Attach | B10: 대 | C10: =0*Inputs!$F$72 -> 0 | D10: =C20*Inputs!$F$72 -> 0 | E10: =D20*Inputs!$F$72 -> 0 | F10: =E20*Inputs!$F$72 -> 1.17 | G10: =F20*Inputs!$F$72 -> 6.0696 | H10: =SUM(C10:G10) -> 7.2396
A11: Robot 설치 — 구축 | B11: 대 | C11: =(C5+C6)*C9 -> 0 | D11: =(D5+D6)*D9 -> 3 | E11: =(E5+E6)*E9 -> 55.25 | F11: =(F5+F6)*F9 -> 238 | G11: =(G5+G6)*G9 -> 569.5 | H11: =SUM(C11:G11) -> 865.75
A12: Robot 설치 — 신축 입주 | B12: 대 | C12: =C7*Inputs!$F$75 -> 0 | D12: =D7*Inputs!$F$75 -> 0 | E12: =E7*Inputs!$F$75 -> 0 | F12: =F7*Inputs!$F$75 -> 0 | G12: =G7*Inputs!$F$75 -> 57.6 | H12: =SUM(C12:G12) -> 57.6
A13: Robot 설치 합계 | B13: 대 | C13: =C11+C12+C10 -> 0 | D13: =D11+D12+D10 -> 3 | E13: =E11+E12+E10 -> 55.25 | F13: =F11+F12+F10 -> 239.17 | G13: =G11+G12+G10 -> 633.1696 | H13: =SUM(C13:G13) -> 930.5896
A14: Rental 비중 | B14: % | C14: =Inputs_Yearly!$E$42 -> 0 | D14: =Inputs_Yearly!$F$42 -> 0.3 | E14: =Inputs_Yearly!$G$42 -> 0.3 | F14: =Inputs_Yearly!$H$42 -> 0.45 | G14: =Inputs_Yearly!$I$42 -> 0.45
A15: Rental Partner 보유 Flag | B15: flag | C15: =Inputs_Yearly!$E$46 -> 0 | D15: =Inputs_Yearly!$F$46 -> 0 | E15: =Inputs_Yearly!$G$46 -> 0 | F15: =Inputs_Yearly!$H$46 -> 1 | G15: =Inputs_Yearly!$I$46 -> 1
A16: Rental 설치 | B16: 대 | C16: =C13*C14 -> 0 | D16: =D13*D14 -> 0.9 | E16: =E13*E14 -> 16.575 | F16: =F13*F14 -> 107.6265 | G16: =G13*G14 -> 284.92632 | H16: =SUM(C16:G16) -> 410.02782
A17: 구매 설치 | B17: 대 | C17: =C13-C16 -> 0 | D17: =D13-D16 -> 2.1 | E17: =E13-E16 -> 38.675 | F17: =F13-F16 -> 131.5435 | G17: =G13-G16 -> 348.24328 | H17: =SUM(C17:G17) -> 520.56178
A18: Rental — ARKI 보유 (Pilot) | B18: 대 | C18: =C16*(1-C15) -> 0 | D18: =D16*(1-D15) -> 0.9 | E18: =E16*(1-E15) -> 16.575 | F18: =F16*(1-F15) -> 0 | G18: =G16*(1-G15) -> 0 | H18: =SUM(C18:G18) -> 17.475
A19: Rental — Partner 보유 | B19: 대 | C19: =C16*C15 -> 0 | D19: =D16*D15 -> 0 | E19: =E16*E15 -> 0 | F19: =F16*F15 -> 107.6265 | G19: =G16*G15 -> 284.92632 | H19: =SUM(C19:G19) -> 392.55282
A20: Robot-ready Only 누적 (기말) | B20: 세대 | C20: =0+(C5+C6)*(1-C9)+C7*(1-Inputs!$F$75)-C10 -> 0 | D20: =C20+(D5+D6)*(1-D9)+D7*(1-Inputs!$F$75)-D10 -> 0 | E20: =D20+(E5+E6)*(1-E9)+E7*(1-Inputs!$F$75)-E10 -> 9.75 | F20: =E20+(F5+F6)*(1-F9)+F7*(1-Inputs!$F$75)-F10 -> 50.58 | G20: =F20+(G5+G6)*(1-G9)+G7*(1-Inputs!$F$75)-G10 -> 279.4104
A21: 구매 Robot 누적 (기말) | B21: 대 | C21: =0+C17 -> 0 | D21: =C21+D17 -> 2.1 | E21: =D21+E17 -> 40.775 | F21: =E21+F17 -> 172.3185 | G21: =F21+G17 -> 520.56178
A22: 구매 Robot 평균 가동 | B22: 대 | C22: =0+C17/2 -> 0 | D22: =C21+D17/2 -> 1.05 | E22: =D21+E17/2 -> 21.4375 | F22: =E21+F17/2 -> 106.54675 | G22: =F21+G17/2 -> 346.44014
A23: ARKI Rental 누적 (기말) | B23: 대 | C23: =0+C18 -> 0 | D23: =C23+D18 -> 0.9 | E23: =D23+E18 -> 17.475 | F23: =E23+F18 -> 17.475 | G23: =F23+G18 -> 17.475
A24: ARKI Rental 평균 가동 | B24: 대 | C24: =0+C18/2 -> 0 | D24: =C23+D18/2 -> 0.45 | E24: =D23+E18/2 -> 9.1875 | F24: =E23+F18/2 -> 17.475 | G24: =F23+G18/2 -> 17.475
A25: Partner Rental 누적 (기말) | B25: 대 | C25: =0+C19 -> 0 | D25: =C25+D19 -> 0 | E25: =D25+E19 -> 0 | F25: =E25+F19 -> 107.6265 | G25: =F25+G19 -> 392.55282
A26: Partner Rental 평균 가동 | B26: 대 | C26: =0+C19/2 -> 0 | D26: =C25+D19/2 -> 0 | E26: =D25+E19/2 -> 0 | F26: =E25+F19/2 -> 53.81325 | G26: =F25+G19/2 -> 250.08966
A27: Installed Robot (기말) | B27: 대 | C27: =C21+C23+C25 -> 0 | D27: =D21+D23+D25 -> 3 | E27: =E21+E23+E25 -> 58.25 | F27: =F21+F23+F25 -> 297.42 | G27: =G21+G23+G25 -> 930.5896
A28: 신축 계약 Backlog (미설치 세대) | B28: 세대 | C28: =Inputs_Yearly!$E$50*Inputs!$F$73*Inputs!$F$74 -> 0 | D28: =(Inputs_Yearly!$F$50+Inputs_Yearly!$E$50)*Inputs!$F$73*Inputs!$F$74 -> 0 | E28: =(Inputs_Yearly!$G$50+Inputs_Yearly!$F$50)*Inputs!$F$73*Inputs!$F$74 -> 192 | F28: =(Inputs_Yearly!$H$50+Inputs_Yearly!$G$50)*Inputs!$F$73*Inputs!$F$74 -> 480 | G28: =(Inputs_Yearly!$I$50+Inputs_Yearly!$H$50)*Inputs!$F$73*Inputs!$F$74 -> 672
A29: REVENUE (만원)
A30: 가격 실현율 | B30: % | C30: =Inputs_Yearly!$E$6 -> 1 | D30: =Inputs_Yearly!$F$6 -> 0.6 | E30: =Inputs_Yearly!$G$6 -> 1 | F30: =Inputs_Yearly!$H$6 -> 1 | G30: =Inputs_Yearly!$I$6 -> 1
A31: Consumables 연 List (구매 고객) | B31: 만원/대 | C31: =Inputs!$F$38*Inputs!$F$39+Inputs!$F$40*Inputs!$F$41+Inputs!$F$42*Inputs!$F$43 -> 36 | D31: =Inputs!$F$38*Inputs!$F$39+Inputs!$F$40*Inputs!$F$41+Inputs!$F$42*Inputs!$F$43 -> 36 | E31: =Inputs!$F$38*Inputs!$F$39+Inputs!$F$40*Inputs!$F$41+Inputs!$F$42*Inputs!$F$43 -> 36 | F31: =Inputs!$F$38*Inputs!$F$39+Inputs!$F$40*Inputs!$F$41+Inputs!$F$42*Inputs!$F$43 -> 36 | G31: =Inputs!$F$38*Inputs!$F$39+Inputs!$F$40*Inputs!$F$41+Inputs!$F$42*Inputs!$F$43 -> 36
A32: Consumables 연 List (Rental, Grip 제외) | B32: 만원/대 | C32: =Inputs!$F$40*Inputs!$F$41+Inputs!$F$42*Inputs!$F$43 -> 18 | D32: =Inputs!$F$40*Inputs!$F$41+Inputs!$F$42*Inputs!$F$43 -> 18 | E32: =Inputs!$F$40*Inputs!$F$41+Inputs!$F$42*Inputs!$F$43 -> 18 | F32: =Inputs!$F$40*Inputs!$F$41+Inputs!$F$42*Inputs!$F$43 -> 18 | G32: =Inputs!$F$40*Inputs!$F$41+Inputs!$F$42*Inputs!$F$43 -> 18
A33: Grip Kit 연 List | B33: 만원/대 | C33: =Inputs!$F$38*Inputs!$F$39 -> 18 | D33: =Inputs!$F$38*Inputs!$F$39 -> 18 | E33: =Inputs!$F$38*Inputs!$F$39 -> 18 | F33: =Inputs!$F$38*Inputs!$F$39 -> 18 | G33: =Inputs!$F$38*Inputs!$F$39 -> 18
A34: A. Kitchen Build (Robot-ready) | B34: 만원 | C34: =(C5+C6)*Inputs!$F$30*C30+C7*Inputs!$F$31 -> 0 | D34: =(D5+D6)*Inputs!$F$30*D30+D7*Inputs!$F$31 -> 810 | E34: =(E5+E6)*Inputs!$F$30*E30+E7*Inputs!$F$31 -> 29250 | F34: =(F5+F6)*Inputs!$F$30*F30+F7*Inputs!$F$31 -> 126000 | G34: =(G5+G6)*Inputs!$F$30*G30+G7*Inputs!$F$31 -> 343740 | H34: =SUM(C34:G34) -> 499800
A35: A. 설치·Calibration | B35: 만원 | C35: =C13*Inputs!$F$33*C30 -> 0 | D35: =D13*Inputs!$F$33*D30 -> 144 | E35: =E13*Inputs!$F$33*E30 -> 4420 | F35: =F13*Inputs!$F$33*F30 -> 19133.6 | G35: =G13*Inputs!$F$33*G30 -> 50653.568 | H35: =SUM(C35:G35) -> 74351.168
A36: A. Robot Hardware (구매 + Rental Partner 공급) | B36: 만원 | C36: =C17*Inputs!$F$32*C30+C19*Inputs!$F$32*Inputs!$F$50 -> 0 | D36: =D17*Inputs!$F$32*D30+D19*Inputs!$F$32*Inputs!$F$50 -> 1877.4 | E36: =E17*Inputs!$F$32*E30+E19*Inputs!$F$32*Inputs!$F$50 -> 57625.75 | F36: =F17*Inputs!$F$32*F30+F19*Inputs!$F$32*Inputs!$F$50 -> 337119.68 | G36: =G17*Inputs!$F$32*G30+G19*Inputs!$F$32*Inputs!$F$50 -> 892477.88 | H36: =SUM(C36:G36) -> 1289100.7
A37: B. Rental (ARKI 보유) | B37: 만원 | C37: =C24*Inputs!$F$34*12 -> 0 | D37: =D24*Inputs!$F$34*12 -> 178.2 | E37: =E24*Inputs!$F$34*12 -> 3638.25 | F37: =F24*Inputs!$F$34*12 -> 6920.1 | G37: =G24*Inputs!$F$34*12 -> 6920.1 | H37: =SUM(C37:G37) -> 17656.65
A38: B. Care (구매 고객 + Partner 서비스료) | B38: 만원 | C38: =C22*Inputs!$F$45*Inputs!$F$36+C26*Inputs!$F$51*12 -> 0 | D38: =D22*Inputs!$F$45*Inputs!$F$36+D26*Inputs!$F$51*12 -> 35.28 | E38: =E22*Inputs!$F$45*Inputs!$F$36+E26*Inputs!$F$51*12 -> 720.3 | F38: =F22*Inputs!$F$45*Inputs!$F$36+F26*Inputs!$F$51*12 -> 7454.5248 | G38: =G22*Inputs!$F$45*Inputs!$F$36+G26*Inputs!$F$51*12 -> 29646.844 | H38: =SUM(C38:G38) -> 37856.949
A39: B. Consumables | B39: 만원 | C39: =C22*Inputs!$F$44*C31+(C24+C26)*Inputs!$F$44*C32 -> 0 | D39: =D22*Inputs!$F$44*D31+(D24+D26)*Inputs!$F$44*D32 -> 32.13 | E39: =E22*Inputs!$F$44*E31+(E24+E26)*Inputs!$F$44*E32 -> 655.9875 | F39: =F22*Inputs!$F$44*F31+(F24+F26)*Inputs!$F$44*F32 -> 3583.2101 | G39: =G22*Inputs!$F$44*G31+(G24+G26)*Inputs!$F$44*G32 -> 12101.606 | H39: =SUM(C39:G39) -> 16372.934
A40: C. Upgrade (Software Skill + Tool) | B40: 만원 | C40: =0*Inputs!$F$47*Inputs!$F$46+0*Inputs!$F$49*Inputs!$F$48 -> 0 | D40: =C13*Inputs!$F$47*Inputs!$F$46+0*Inputs!$F$49*Inputs!$F$48 -> 0 | E40: =D13*Inputs!$F$47*Inputs!$F$46+C13*Inputs!$F$49*Inputs!$F$48 -> 36 | F40: =E13*Inputs!$F$47*Inputs!$F$46+D13*Inputs!$F$49*Inputs!$F$48 -> 723 | G40: =F13*Inputs!$F$47*Inputs!$F$46+E13*Inputs!$F$49*Inputs!$F$48 -> 3975.04 | H40: =SUM(C40:G40) -> 4734.04
...

Sheet Household
A1: Household Economics — 구축 Premium 1세대, 5년, 직접판매, Base (만원)
A2: 기대값 기준 (Software·Tool은 구매율 반영). 구매 모델은 Care 가입 세대 기준. Y3 / Y5 = 해당 연도의 원가 수준을 5년간 적용.
A4: 항목 | B4: 구매 · Y3 원가 | C4: 구매 · Y5 원가 | D4: Rental · Y3 원가 | E4: Rental · Y5 원가 | F4: 산식
A5: REVENUE
A6: Robot-ready Kitchen 증분 | B6: =Inputs!$E$30 -> 450 | C6: =Inputs!$E$30 -> 450 | D6: =Inputs!$E$30 -> 450 | E6: =Inputs!$E$30 -> 450 | F6: Year 0
A7: 설치·Calibration | B7: =Inputs!$E$33 -> 80 | C7: =Inputs!$E$33 -> 80 | D7: =Inputs!$E$33 -> 80 | E7: =Inputs!$E$33 -> 80 | F7: Year 0
A8: Robot Module (구매) | B8: =Inputs!$E$32 -> 1490 | C8: =Inputs!$E$32 -> 1490 | D8: =0 -> 0 | E8: =0 -> 0 | F8: Year 0
A9: Rental (60개월) | B9: =0 -> 0 | C9: =0 -> 0 | D9: =Inputs!$E$34*Inputs!$E$35 -> 1980 | E9: =Inputs!$E$34*Inputs!$E$35 -> 1980 | F9: 월 요금 × 60
A10: Care Basic (5년) | B10: =5*Inputs!$E$36 -> 240 | C10: =5*Inputs!$E$36 -> 240 | D10: =0 -> 0 | E10: =0 -> 0 | F10: Rental은 요금에 포함
A11: Consumables (5년, 구매율 반영) | B11: =5*Inputs!$E$44*(Inputs!$E$38*Inputs!$E$39+Inputs!$E$40*Inputs!$E$41+Inputs!$E$42*Inputs!$E$43) -> 126 | C11: =5*Inputs!$E$44*(Inputs!$E$38*Inputs!$E$39+Inputs!$E$40*Inputs!$E$41+Inputs!$E$42*Inputs!$E$43) -> 126 | D11: =5*Inputs!$E$44*(Inputs!$E$40*Inputs!$E$41+Inputs!$E$42*Inputs!$E$43) -> 63 | E11: =5*Inputs!$E$44*(Inputs!$E$40*Inputs!$E$41+Inputs!$E$42*Inputs!$E$43) -> 63 | F11: Rental은 Grip Kit 포함
A12: Software Skill (기대값) | B12: =Inputs!$E$47*Inputs!$E$46 -> 12 | C12: =Inputs!$E$47*Inputs!$E$46 -> 12 | D12: =Inputs!$E$47*Inputs!$E$46 -> 12 | E12: =Inputs!$E$47*Inputs!$E$46 -> 12
A13: Tool / End-effector (기대값) | B13: =Inputs!$E$49*Inputs!$E$48 -> 20 | C13: =Inputs!$E$49*Inputs!$E$48 -> 20 | D13: =Inputs!$E$49*Inputs!$E$48 -> 20 | E13: =Inputs!$E$49*Inputs!$E$48 -> 20
A14: 5년 매출 | B14: =B6+B7+B8+B9+B10+B11+B12+B13 -> 2418 | C14: =C6+C7+C8+C9+C10+C11+C12+C13 -> 2418 | D14: =D6+D7+D8+D9+D10+D11+D12+D13 -> 2605 | E14: =E6+E7+E8+E9+E10+E11+E12+E13 -> 2605
A15: COST
A16: Kitchen Module 원가 | B16: =Inputs!$E$53*(Inputs_Yearly!$G$9+Inputs!$E$54*(1-Inputs_Yearly!$G$9))+Inputs!$E$55*(1-Inputs_Yearly!$G$9) -> 277 | C16: =Inputs!$E$53*(Inputs_Yearly!$I$9+Inputs!$E$54*(1-Inputs_Yearly!$I$9))+Inputs!$E$55*(1-Inputs_Yearly!$I$9) -> 244 | D16: =Inputs!$E$53*(Inputs_Yearly!$G$9+Inputs!$E$54*(1-Inputs_Yearly!$G$9))+Inputs!$E$55*(1-Inputs_Yearly!$G$9) -> 277 | E16: =Inputs!$E$53*(Inputs_Yearly!$I$9+Inputs!$E$54*(1-Inputs_Yearly!$I$9))+Inputs!$E$55*(1-Inputs_Yearly!$I$9) -> 244 | F16: Standard Module 사용률 연동
A17: 설치·Calibration 원가 | B17: =Inputs_Yearly!$G$17 -> 60 | C17: =Inputs_Yearly!$I$17 -> 38 | D17: =Inputs_Yearly!$G$17 -> 60 | E17: =Inputs_Yearly!$I$17 -> 38
A18: 물류 | B18: =Inputs!$E$57 -> 25 | C18: =Inputs!$E$57 -> 25 | D18: =Inputs!$E$57 -> 25 | E18: =Inputs!$E$57 -> 25
A19: Robot BOM (Rental은 잔존가치 차감) | B19: =Inputs_Yearly!$G$13 -> 1150 | C19: =Inputs_Yearly!$I$13 -> 900 | D19: =Inputs_Yearly!$G$13*(1-Inputs!$E$68) -> 977.5 | E19: =Inputs_Yearly!$I$13*(1-Inputs!$E$68) -> 765
A20: Rental 금융비용 (5년) | B20: =0 -> 0 | C20: =0 -> 0 | D20: =Inputs_Yearly!$G$13*(1+Inputs!$E$68)/2*Inputs!$E$69*5 -> 264.5 | E20: =Inputs_Yearly!$I$13*(1+Inputs!$E$68)/2*Inputs!$E$69*5 -> 207 | F20: 평균잔액 × 금리
A21: Warranty Reserve | B21: =Inputs!$E$58*Inputs!$E$32 -> 59.6 | C21: =Inputs!$E$58*Inputs!$E$32 -> 59.6 | D21: =Inputs!$E$58*Inputs_Yearly!$G$13 -> 46 | E21: =Inputs!$E$58*Inputs_Yearly!$I$13 -> 36
A22: Care Service 원가 (5년) | B22: =5*(Inputs_Yearly!$G$21*Inputs_Yearly!$G$25+Inputs!$E$59*Inputs!$E$60+Inputs!$E$61) -> 184 | C22: =5*(Inputs_Yearly!$I$21*Inputs_Yearly!$I$25+Inputs!$E$59*Inputs!$E$60+Inputs!$E$61) -> 134 | D22: =5*(Inputs_Yearly!$G$21*Inputs_Yearly!$G$25+Inputs!$E$59*Inputs!$E$60+Inputs!$E$61) -> 184 | E22: =5*(Inputs_Yearly!$I$21*Inputs_Yearly!$I$25+Inputs!$E$59*Inputs!$E$60+Inputs!$E$61) -> 134
A23: Consumables 원가 | B23: =B11*Inputs!$E$62 -> 44.1 | C23: =C11*Inputs!$E$62 -> 44.1 | D23: =(D11+5*Inputs!$E$38*Inputs!$E$39)*Inputs!$E$62 -> 53.55 | E23: =(E11+5*Inputs!$E$38*Inputs!$E$39)*Inputs!$E$62 -> 53.55
A24: Upgrade 원가 | B24: =Inputs!$E$47*Inputs!$E$46*Inputs!$E$63+Inputs!$E$49*Inputs!$E$48*Inputs!$E$64 -> 10.2 | C24: =Inputs!$E$47*Inputs!$E$46*Inputs!$E$63+Inputs!$E$49*Inputs!$E$48*Inputs!$E$64 -> 10.2 | D24: =Inputs!$E$47*Inputs!$E$46*Inputs!$E$63+Inputs!$E$49*Inputs!$E$48*Inputs!$E$64 -> 10.2 | E24: =Inputs!$E$47*Inputs!$E$46*Inputs!$E$63+Inputs!$E$49*Inputs!$E$48*Inputs!$E$64 -> 10.2
A25: 직접판매 획득비용 | B25: =Inputs!$E$66 -> 150 | C25: =Inputs!$E$66 -> 150 | D25: =Inputs!$E$66 -> 150 | E25: =Inputs!$E$66 -> 150
A26: 5년 비용 | B26: =B16+B17+B18+B19+B20+B21+B22+B23+B24+B25 -> 1959.9 | C26: =C16+C17+C18+C19+C20+C21+C22+C23+C24+C25 -> 1604.9 | D26: =D16+D17+D18+D19+D20+D21+D22+D23+D24+D25 -> 2047.75 | E26: =E16+E17+E18+E19+E20+E21+E22+E23+E24+E25 -> 1662.75
A27: RESULT
A28: Year 0 매출 | B28: =B6+B7+B8 -> 2020 | C28: =C6+C7+C8 -> 2020 | D28: =D6+D7 -> 530 | E28: =E6+E7 -> 530
A29: 5년 매출총이익 (획득비용 전) | B29: =B14-(B26-B25) -> 608.1 | C29: =C14-(C26-C25) -> 963.1 | D29: =D14-(D26-D25) -> 707.25 | E29: =E14-(E26-E25) -> 1092.25
A30: 5년 Lifetime Contribution | B30: =B14-B26 -> 458.1 | C30: =C14-C26 -> 813.1 | D30: =D14-D26 -> 557.25 | E30: =E14-E26 -> 942.25
A31: Contribution Margin | B31: =IF(B14=0,0,B30/B14) -> 0.18945409 | C31: =IF(C14=0,0,C30/C14) -> 0.33626964 | D31: =IF(D14=0,0,D30/D14) -> 0.21391555 | E31: =IF(E14=0,0,E30/E14) -> 0.36170825
A32: Recurring 매출 (Rental·Care·Consumables) | B32: =B10+B11 -> 366 | C32: =C10+C11 -> 366 | D32: =D9+D11 -> 2043 | E32: =E9+E11 -> 2043

Sheet Unit_Economics
A1: Unit Economics — Base (만원)
A3: Rental 월 원가 Build-up (Robot 1대, ARKI 보유 가정) | B3: Y3 원가 | C3: Y5 원가 | D3: 산식
A4: Robot BOM | B4: =Inputs_Yearly!$G$13 -> 1150 | C4: =Inputs_Yearly!$I$13 -> 900
A5: 감가 (잔존가치 차감, 60개월) | B5: =B4*(1-Inputs!$E$68)/Inputs!$E$35 -> 16.291667 | C5: =C4*(1-Inputs!$E$68)/Inputs!$E$35 -> 12.75
A6: 금융비용 (평균잔액 × 금리 / 12) | B6: =B4*(1+Inputs!$E$68)/2*Inputs!$E$69/12 -> 4.4083333 | C6: =C4*(1+Inputs!$E$68)/2*Inputs!$E$69/12 -> 3.45
A7: Care 원가 / 12 | B7: =(Inputs_Yearly!$G$21*Inputs_Yearly!$G$25+Inputs!$E$59*Inputs!$E$60+Inputs!$E$61)/12 -> 3.0666667 | C7: =(Inputs_Yearly!$I$21*Inputs_Yearly!$I$25+Inputs!$E$59*Inputs!$E$60+Inputs!$E$61)/12 -> 2.2333333
A8: Grip Kit 원가 / 12 | B8: =Inputs!$E$38*Inputs!$E$39*Inputs!$E$62/12 -> 0.525 | C8: =Inputs!$E$38*Inputs!$E$39*Inputs!$E$62/12 -> 0.525
A9: Failure Reserve | B9: =Inputs!$E$58*B4/Inputs!$E$35 -> 0.76666667 | C9: =Inputs!$E$58*C4/Inputs!$E$35 -> 0.6
A10: 월 원가 합계 | B10: =B5+B6+B7+B8+B9 -> 25.058333 | C10: =C5+C6+C7+C8+C9 -> 19.558333
A11: 월 Rental 요금 (가정) | B11: =Inputs!$E$34 -> 33 | C11: =Inputs!$E$34 -> 33
A12: 월 Contribution | B12: =B11-B10 -> 7.9416667 | C12: =C11-C10 -> 13.441667
A13: Contribution Margin | B13: =B12/B11 -> 0.24065657 | C13: =C12/C11 -> 0.40732323
A14: 마진 20% 확보 요금 | B14: =B10/0.8 -> 31.322917 | C14: =C10/0.8 -> 24.447917
A15: Payback (BOM ÷ (요금 − Care − Grip), 개월) | B15: =B4/(B11-B7-B8) -> 39.104562 | C15: =C4/(C11-C7-C8) -> 29.760265 | D15: 금융비용 제외 현금 회수
A16: Payback 허들 충족 최대 BOM | B16: =Inputs!$E$70*(B11-B7-B8) -> 1058.7 | C16: =Inputs!$E$70*(C11-C7-C8) -> 1088.7 | D16: Rental Partner 요구 Payback 기준
A18: Care Basic (Robot 1대·년) | B18: Y3 원가 | C18: Y5 원가 | D18: 산식
A19: Care 연 요금 | B19: =Inputs!$E$36 -> 48 | C19: =Inputs!$E$36 -> 48
A20: 정기 방문 원가 | B20: =Inputs_Yearly!$G$21*Inputs_Yearly!$G$25 -> 22 | C20: =Inputs_Yearly!$I$21*Inputs_Yearly!$I$25 -> 12
A21: 고장 방문 원가 | B21: =Inputs!$E$59*Inputs!$E$60 -> 10.8 | C21: =Inputs!$E$59*Inputs!$E$60 -> 10.8
A22: Cloud·Software | B22: =Inputs!$E$61 -> 4 | C22: =Inputs!$E$61 -> 4
A23: Care 원가 합계 | B23: =SUM(B20:B22) -> 36.8 | C23: =SUM(C20:C22) -> 26.8
A24: Care Contribution | B24: =B19-B23 -> 11.2 | C24: =C19-C23 -> 21.2
A25: Care Margin | B25: =B24/B19 -> 0.23333333 | C25: =C24/C19 -> 0.44166667
A27: Consumables (Robot 1대·년, 구매 고객) | B27: 연 매출 | C27: 원가 | D27: Contribution
A28: Grip Kit (List × 구매율) | B28: =Inputs!$E$38*Inputs!$E$39*Inputs!$E$44 -> 12.6 | C28: =B28*Inputs!$E$62 -> 4.41 | D28: =B28-C28 -> 8.19
A29: Cleaning Kit (List × 구매율) | B29: =Inputs!$E$40*Inputs!$E$41*Inputs!$E$44 -> 7 | C29: =B29*Inputs!$E$62 -> 2.45 | D29: =B29-C29 -> 4.55
A30: Protection Kit (List × 구매율) | B30: =Inputs!$E$42*Inputs!$E$43*Inputs!$E$44 -> 5.6 | C30: =B30*Inputs!$E$62 -> 1.96 | D30: =B30-C30 -> 3.64
A31: 합계 | B31: =SUM(B28:B30) -> 25.2 | C31: =SUM(C28:C30) -> 8.82 | D31: =SUM(D28:D30) -> 16.38
A33: Rental Partner 경제성 (Base, Y4~) | B33: 값 | D33: 산식
A34: Robot 매입가 (ASP × 공급가율) | B34: =Inputs!$E$32*Inputs!$E$50 -> 1311.2
A35: 월 순유입 (요금 − ARKI 서비스료) | B35: =Inputs!$E$34-Inputs!$E$51 -> 27
A36: 잔존가치 (매입가 × 잔존율) | B36: =B34*Inputs!$E$68 -> 196.68
A37: 월 IRR | B37: =RATE(Inputs!$E$35,B35,-B34,B36) -> 0.010276112 | D37: RATE(기간, 월 유입, −매입가, 잔존가치)
A38: 연 IRR (연체·해지 미반영) | B38: =(1+B37)^12-1 -> 0.13052719
A40: Robot BOM 구성 (ASSUMPTION, 만원/대) | B40: Pilot (Y1) | C40: Y3 | D40: Y5
A41: 6축 Arm (가반 3~5kg, Controller 포함) | B41: 950 | C41: 600 | D41: 450 | E41: FAIRINO FR5 $6,999 · xArm 6 $8,399 공개가 → OEM·국산 Partner·전용 Arm
A42: Linear Rail · Carriage · Servo (2.4~3.6m) | B42: 180 | C42: 150 | D42: 120 | E42: Belt 구동 7축 Rail. 소형 KK Module $73~245는 참고만
A43: End-effector Set (Gripper + Suction + Tool Changer) | B43: 120 | C43: 90 | D43: 70 | E43: Robotiq 2F-85 $4,999 대비 저가 전동 Gripper + 자체 Finger
A44: Vision (Depth Camera 2대 + Mount) | B44: 110 | C44: 80 | D44: 60 | E44: Orbbec Gemini 335 $384~400 · RealSense D405 $514
A45: Compute (Edge GPU) | B45: 100 | C45: 80 | D45: 70 | E45: Edge AI Module 가정
...

Sheet Market
A1: Market Sizing — Bottom-up (Base)
A3: 항목 | B3: 값 | C3: 단위 | D3: Tag | E3: 산식 / 출처
A4: 총주택 (2025) | B4: =Inputs!$E$5 -> 20181 | C4: 천호 | D4: FACT | E4: 국가데이터처 2025 인구주택총조사
A5: 아파트 비중 | B5: =Inputs!$E$6 -> 0.658 | C5: % | D5: FACT
A6: 아파트 수 (2025) | B6: =B4*B5 -> 13279.098 | C6: 천호 | D6: DERIVED | E6: 총주택 × 비중
A7: 교차검증 ①: 20년+ 아파트(2023) ÷ 교체주기 | B7: =Inputs!$E$10/Inputs!$E$15 -> 290.45455 | C7: 천/년 | D7: DERIVED
A8: 교차검증 ②: 매매거래 × 아파트 비중 × 교체율 + 비거래 교체 | B8: =Inputs!$E$11*Inputs!$E$16*Inputs!$E$17+Inputs!$E$18 -> 303.28 | C8: 천/년 | D8: DERIVED
A9: 연간 Kitchen 교체 세대 (설정) | B9: =Inputs!$E$19 -> 300 | C9: 천/년 | D9: ASSUMPTION | E9: ①·② 교차검증 후 설정
A10: Premium 비중 | B10: =Inputs!$E$20 -> 0.1 | C10: % | D10: ASSUMPTION
A11: Premium Kitchen 교체 세대 | B11: =B9*B10 -> 30 | C11: 천/년 | D11: DERIVED
A12: Robot-ready 적용 가능률 | B12: =Inputs!$E$21 -> 0.6 | C12: % | D12: ASSUMPTION
A13: 구축 SAM 세대 | B13: =B11*B12 -> 18 | C13: 천/년 | D13: DERIVED
A14: 구축 패키지 기대 매출/세대 | B14: =Inputs!$E$30+Inputs_Yearly!$I$37*(Inputs!$E$32+Inputs!$E$33) -> 1784.5 | C14: 만원 | D14: DERIVED | E14: Robot-ready + Attach × (Robot + 설치)
A15: 연간 신규 아파트 입주 | B15: =Inputs!$E$22 -> 200 | C15: 천/년 | D15: DERIVED | E15: 2025 23.6만 · 2026E 18.3만
A16: Premium 단지 비중 | B16: =Inputs!$E$23 -> 0.15 | C16: % | D16: ASSUMPTION
A17: 신축 Premium 세대 | B17: =B15*B16 -> 30 | C17: 천/년 | D17: DERIVED
A18: Robot-ready Option 선택률 | B18: =Inputs!$E$74 -> 0.1 | C18: % | D18: ASSUMPTION
A19: 신축 SAM 세대 | B19: =B17*B18 -> 3 | C19: 천/년 | D19: DERIVED
A20: 신축 패키지 기대 매출/세대 | B20: =Inputs!$E$31+Inputs!$E$75*(Inputs!$E$32+Inputs!$E$33) -> 612.5 | C20: 만원 | D20: DERIVED
A21: 전체 패키지 단가 (Robot-ready + Robot + 설치) | B21: =Inputs!$E$30+Inputs!$E$32+Inputs!$E$33 -> 2020 | C21: 만원 | D21: ASSUMPTION
A22: TAM: Premium 세대 (구축+신축) × 전체 패키지 | B22: =(B11+B17)*B21/10 -> 12120 | C22: 억원/년 | D22: DERIVED | E22: 천세대 × 만원 ÷ 10 = 억원
A23: SAM 구축 | B23: =B13*B14/10 -> 3212.1 | C23: 억원/년 | D23: DERIVED
A24: SAM 신축 | B24: =B19*B20/10 -> 183.75 | C24: 억원/년 | D24: DERIVED
A25: SAM 합계 | B25: =B23+B24 -> 3395.85 | C25: 억원/년 | D25: DERIVED
A26: SOM: Y5 매출 (Base Plan) | B26: =FM_Base!$G$41/10000 -> 77.544078 | C26: 억원/년 | D26: TARGET | E26: FM_Base Y5
A27: SOM 세대 / SAM 세대 | B27: =FM_Base!$G$8/((B13+B19)*1000) -> 0.022857143 | C27: % | D27: DERIVED

Sheet Sensitivity
A1: Sensitivity — 구축 구매 1세대 5년 Contribution (Base, Y3 원가, 직접판매)
A2: 각 행은 한 변수만 바꾼 파라미터 세트 (파란 글자 = 변경값). Contribution 수식은 Household 시트와 동일 구조.
A4: Case | B4: p_robot | C4: bom | D4: p_rr | E4: cac | F4: p_care | G4: visit_cost | H4: smr | I4: comm_cost | J4: corrective | K4: warranty | L4: cons_attach | M4: Contribution | N4: Δ vs Base
